Workbook

Sheet 회원명단 및 기준에버
B3: 기준 에버
B4: 순번 | C4: 이름 | D4: 1분기 | E4: 2분기 | F4: 3분기 | G4: 4분기
B5: 1 | C5: 최 현 수 | D5: 200 | E5: 200
B6: 2 | C6: 임 승 기 | D6: 200 | E6: 200
B7: 3 | C7: 이 범 수 | D7: 193 | E7: 200
B8: 4 | C8: 강 희 태 | D8: 200 | E8: 200
B9: 5 | C9: 박 시 진 | D9: 196 | E9: 200
B10: 6 | C10: 김 남 주 | D10: 195 | E10: 200
B11: 7 | C11: 장 영 민 | D11: 200 | E11: 200
B12: 8 | C12: 변 상 필 | D12: 200 | E12: 200
B13: 9 | C13: 임 연 진 | D13: 194 | E13: 200
B14: 10 | C14: 송 정 현 | D14: 187 | E14: 200
B15: 11 | C15: 김 정 희 | D15: 200 | E15: 200
B16: 12 | C16: 이 대 용 | D16: 200 | E16: 200
... B39: 35 | C39: 손 은 주 | D39: 151 | E39: 144
B40: 36
B41: 37
B42: 38
B43: 39

Sheet 00회번개 6인팀
A1: 2026 아르케 존 00회 정기 번개 점수
L2: 날짜 | N2: 46113 | U2: 팀전에버기준 | V2: 0 | W2: 순위에버오차기준 | X2: 1
B3: 이 름 | C3: 1 G | D3: 2 G | E3: 3 G | F3: 4G | G3: 합 계 | H3: 에 버 | I3: 기본에버 | J3: 1 G | K3: 2 G | L3: 3 G | M3: 4G | N3: 합 계 | O3: 오 차 | U3: 수식입력부분 삭제하지마세요~
A4: 1 | G4: =F4+E4+D4+C4 -> 0 | H4: =G4/4 -> 0 | I4: =IF(B4="","",IFERROR(INDEX('회원명단 및 기준에버'!D:G,MATCH(B4,'회원명단 및 기준에버'!$C:$C,0),CHOOSE(INT((MONTH($N$2)-1)/3)+1,1,2,3,4)),"")) | J4: =IFERROR(C4+-I4,0) -> 0 | K4: =IFERROR(D4+-I4,0) -> 0 | L4: =IFERROR(E4+-I4,0) -> 0 | M4: =IFERROR(F4+-I4,0) -> 0 | N4: =SUM(J4:M4) -> 0 | O4: =IFERROR(H4+-I4,0) -> 0 | U4: =MAX(C4:F4)-MIN(C4:F4) -> 0 | V4: =IF($X$2=0,(G4*1000000+U4*1000+A4),(O4*1000000+U4*1000+A4)) -> 1 | W4: =_xlfn.RANK.EQ(V4,$V$4:$V$33,0) -> 30
A5: 2 | G5: =F5+E5+D5+C5 -> 0 | H5: =G5/4 -> 0 | I5: =IF(B5="","",IFERROR(INDEX('회원명단 및 기준에버'!D:G,MATCH(B5,'회원명단 및 기준에버'!$C:$C,0),CHOOSE(INT((MONTH($N$2)-1)/3)+1,1,2,3,4)),"")) | J5: =IFERROR(C5+-I5,0) -> 0 | K5: =IFERROR(D5+-I5,0) -> 0 | L5: =IFERROR(E5+-I5,0) -> 0 | M5: =IFERROR(F5+-I5,0) -> 0 | N5: =SUM(J5:M5) -> 0 | O5: =IFERROR(H5+-I5,0) -> 0 | U5: =MAX(C5:F5)-MIN(C5:F5) -> 0 | V5: =IF($X$2=0,(G5*1000000+U5*1000+A5),(O5*1000000+U5*1000+A5)) -> 2 | W5: =_xlfn.RANK.EQ(V5,$V$4:$V$33,0) -> 29
A6: 3 | G6: =F6+E6+D6+C6 -> 0 | H6: =G6/4 -> 0 | I6: =IF(B6="","",IFERROR(INDEX('회원명단 및 기준에버'!D:G,MATCH(B6,'회원명단 및 기준에버'!$C:$C,0),CHOOSE(INT((MONTH($N$2)-1)/3)+1,1,2,3,4)),"")) | J6: =IFERROR(C6+-I6,0) -> 0 | K6: =IFERROR(D6+-I6,0) -> 0 | L6: =IFERROR(E6+-I6,0) -> 0 | M6: =IFERROR(F6+-I6,0) -> 0 | N6: =SUM(J6:M6) -> 0 | O6: =IFERROR(H6+-I6,0) -> 0 | U6: =MAX(C6:F6)-MIN(C6:F6) -> 0 | V6: =IF($X$2=0,(G6*1000000+U6*1000+A6),(O6*1000000+U6*1000+A6)) -> 3 | W6: =_xlfn.RANK.EQ(V6,$V$4:$V$33,0) -> 28
A7: 4 | G7: =F7+E7+D7+C7 -> 0 | H7: =G7/4 -> 0 | I7: =IF(B7="","",IFERROR(INDEX('회원명단 및 기준에버'!D:G,MATCH(B7,'회원명단 및 기준에버'!$C:$C,0),CHOOSE(INT((MONTH($N$2)-1)/3)+1,1,2,3,4)),"")) | J7: =IFERROR(C7+-I7,0) -> 0 | K7: =IFERROR(D7+-I7,0) -> 0 | L7: =IFERROR(E7+-I7,0) -> 0 | M7: =IFERROR(F7+-I7,0) -> 0 | N7: =SUM(J7:M7) -> 0 | O7: =IFERROR(H7+-I7,0) -> 0 | U7: =MAX(C7:F7)-MIN(C7:F7) -> 0 | V7: =IF($X$2=0,(G7*1000000+U7*1000+A7),(O7*1000000+U7*1000+A7)) -> 4 | W7: =_xlfn.RANK.EQ(V7,$V$4:$V$33,0) -> 27
A8: 5 | G8: =F8+E8+D8+C8 -> 0 | H8: =G8/4 -> 0 | I8: =IF(B8="","",IFERROR(INDEX('회원명단 및 기준에버'!D:G,MATCH(B8,'회원명단 및 기준에버'!$C:$C,0),CHOOSE(INT((MONTH($N$2)-1)/3)+1,1,2,3,4)),"")) | J8: =IFERROR(C8+-I8,0) -> 0 | K8: =IFERROR(D8+-I8,0) -> 0 | L8: =IFERROR(E8+-I8,0) -> 0 | M8: =IFERROR(F8+-I8,0) -> 0 | N8: =SUM(J8:M8) -> 0 | O8: =IFERROR(H8+-I8,0) -> 0 | U8: =MAX(C8:F8)-MIN(C8:F8) -> 0 | V8: =IF($X$2=0,(G8*1000000+U8*1000+A8),(O8*1000000+U8*1000+A8)) -> 5 | W8: =_xlfn.RANK.EQ(V8,$V$4:$V$33,0) -> 26
A9: 6 | G9: =F9+E9+D9+C9 -> 0 | H9: =G9/4 -> 0 | I9: =IF(B9="","",IFERROR(INDEX('회원명단 및 기준에버'!D:G,MATCH(B9,'회원명단 및 기준에버'!$C:$C,0),CHOOSE(INT((MONTH($N$2)-1)/3)+1,1,2,3,4)),"")) | J9: =IFERROR(C9+-I9,0) -> 0 | K9: =IFERROR(D9+-I9,0) -> 0 | L9: =IFERROR(E9+-I9,0) -> 0 | M9: =IFERROR(F9+-I9,0) -> 0 | N9: =SUM(J9:M9) -> 0 | O9: =IFERROR(H9+-I9,0) -> 0 | U9: =MAX(C9:F9)-MIN(C9:F9) -> 0 | V9: =IF($X$2=0,(G9*1000000+U9*1000+A9),(O9*1000000+U9*1000+A9)) -> 6 | W9: =_xlfn.RANK.EQ(V9,$V$4:$V$33,0) -> 25
A10: 7 | G10: =F10+E10+D10+C10 -> 0 | H10: =G10/4 -> 0 | I10: =IF(B10="","",IFERROR(INDEX('회원명단 및 기준에버'!D:G,MATCH(B10,'회원명단 및 기준에버'!$C:$C,0),CHOOSE(INT((MONTH($N$2)-1)/3)+1,1,2,3,4)),"")) | J10: =IFERROR(C10+-I10,0) -> 0 | K10: =IFERROR(D10+-I10,0) -> 0 | L10: =IFERROR(E10+-I10,0) -> 0 | M10: =IFERROR(F10+-I10,0) -> 0 | N10: =SUM(J10:M10) -> 0 | O10: =IFERROR(H10+-I10,0) -> 0 | U10: =MAX(C10:F10)-MIN(C10:F10) -> 0 | V10: =IF($X$2=0,(G10*1000000+U10*1000+A10),(O10*1000000+U10*1000+A10)) -> 7 | W10: =_xlfn.RANK.EQ(V10,$V$4:$V$33,0) -> 24
A11: 8 | G11: =F11+E11+D11+C11 -> 0 | H11: =G11/4 -> 0 | I11: =IF(B11="","",IFERROR(INDEX('회원명단 및 기준에버'!D:G,MATCH(B11,'회원명단 및 기준에버'!$C:$C,0),CHOOSE(INT((MONTH($N$2)-1)/3)+1,1,2,3,4)),"")) | J11: =IFERROR(C11+-I11,0) -> 0 | K11: =IFERROR(D11+-I11,0) -> 0 | L11: =IFERROR(E11+-I11,0) -> 0 | M11: =IFERROR(F11+-I11,0) -> 0 | N11: =SUM(J11:M11) -> 0 | O11: =IFERROR(H11+-I11,0) -> 0 | U11: =MAX(C11:F11)-MIN(C11:F11) -> 0 | V11: =IF($X$2=0,(G11*1000000+U11*1000+A11),(O11*1000000+U11*1000+A11)) -> 8 | W11: =_xlfn.RANK.EQ(V11,$V$4:$V$33,0) -> 23
A12: 9 | G12: =F12+E12+D12+C12 -> 0 | H12: =G12/4 -> 0 | I12: =IF(B12="","",IFERROR(INDEX('회원명단 및 기준에버'!D:G,MATCH(B12,'회원명단 및 기준에버'!$C:$C,0),CHOOSE(INT((MONTH($N$2)-1)/3)+1,1,2,3,4)),"")) | J12: =IFERROR(C12+-I12,0) -> 0 | K12: =IFERROR(D12+-I12,0) -> 0 | L12: =IFERROR(E12+-I12,0) -> 0 | M12: =IFERROR(F12+-I12,0) -> 0 | N12: =SUM(J12:M12) -> 0 | O12: =IFERROR(H12+-I12,0) -> 0 | U12: =MAX(C12:F12)-MIN(C12:F12) -> 0 | V12: =IF($X$2=0,(G12*1000000+U12*1000+A12),(O12*1000000+U12*1000+A12)) -> 9 | W12: =_xlfn.RANK.EQ(V12,$V$4:$V$33,0) -> 22
A13: 10 | G13: =F13+E13+D13+C13 -> 0 | H13: =G13/4 -> 0 | I13: =IF(B13="","",IFERROR(INDEX('회원명단 및 기준에버'!D:G,MATCH(B13,'회원명단 및 기준에버'!$C:$C,0),CHOOSE(INT((MONTH($N$2)-1)/3)+1,1,2,3,4)),"")) | J13: =IFERROR(C13+-I13,0) -> 0 | K13: =IFERROR(D13+-I13,0) -> 0 | L13: =IFERROR(E13+-I13,0) -> 0 | M13: =IFERROR(F13+-I13,0) -> 0 | N13: =SUM(J13:M13) -> 0 | O13: =IFERROR(H13+-I13,0) -> 0 | U13: =MAX(C13:F13)-MIN(C13:F13) -> 0 | V13: =IF($X$2=0,(G13*1000000+U13*1000+A13),(O13*1000000+U13*1000+A13)) -> 10 | W13: =_xlfn.RANK.EQ(V13,$V$4:$V$33,0) -> 21
A14: 11 | G14: =F14+E14+D14+C14 -> 0 | H14: =G14/4 -> 0 | I14: =IF(B14="","",IFERROR(INDEX('회원명단 및 기준에버'!D:G,MATCH(B14,'회원명단 및 기준에버'!$C:$C,0),CHOOSE(INT((MONTH($N$2)-1)/3)+1,1,2,3,4)),"")) | J14: =IFERROR(C14+-I14,0) -> 0 | K14: =IFERROR(D14+-I14,0) -> 0 | L14: =IFERROR(E14+-I14,0) -> 0 | M14: =IFERROR(F14+-I14,0) -> 0 | N14: =SUM(J14:M14) -> 0 | O14: =IFERROR(H14+-I14,0) -> 0 | U14: =MAX(C14:F14)-MIN(C14:F14) -> 0 | V14: =IF($X$2=0,(G14*1000000+U14*1000+A14),(O14*1000000+U14*1000+A14)) -> 11 | W14: =_xlfn.RANK.EQ(V14,$V$4:$V$33,0) -> 20
A15: 12 | G15: =F15+E15+D15+C15 -> 0 | H15: =G15/4 -> 0 | I15: =IF(B15="","",IFERROR(INDEX('회원명단 및 기준에버'!D:G,MATCH(B15,'회원명단 및 기준에버'!$C:$C,0),CHOOSE(INT((MONTH($N$2)-1)/3)+1,1,2,3,4)),"")) | J15: =IFERROR(C15+-I15,0) -> 0 | K15: =IFERROR(D15+-I15,0) -> 0 | L15: =IFERROR(E15+-I15,0) -> 0 | M15: =IFERROR(F15+-I15,0) -> 0 | N15: =SUM(J15:M15) -> 0 | O15: =IFERROR(H15+-I15,0) -> 0 | U15: =MAX(C15:F15)-MIN(C15:F15) -> 0 | V15: =IF($X$2=0,(G15*1000000+U15*1000+A15),(O15*1000000+U15*1000+A15)) -> 12 | W15: =_xlfn.RANK.EQ(V15,$V$4:$V$33,0) -> 19
... A33: 30 | G33: =F33+E33+D33+C33 -> 0 | H33: =G33/4 -> 0 | I33: =IF(B33="","",IFERROR(INDEX('회원명단 및 기준에버'!D:G,MATCH(B33,'회원명단 및 기준에버'!$C:$C,0),CHOOSE(INT((MONTH($N$2)-1)/3)+1,1,2,3,4)),"")) | J33: =IFERROR(C33+-I33,0) -> 0 | K33: =IFERROR(D33+-I33,0) -> 0 | L33: =IFERROR(E33+-I33,0) -> 0 | M33: =IFERROR(F33+-I33,0) -> 0 | N33: =SUM(J33:M33) -> 0 | O33: =IFERROR(H33+-I33,0) -> 0 | U33: =MAX(C33:F33)-MIN(C33:F33) -> 0 | V33: =IF($X$2=0,(G33*1000000+U33*1000+A33),(O33*1000000+U33*1000+A33)) -> 30 | W33: =_xlfn.RANK.EQ(V33,$V$4:$V$33,0) -> 1
B34: 팀 전
B35: =$B4 -> 0 | C35: =IF($V$2=0,$C4,$J4) -> 0 | D35: =IF($V$2=0,$D4,$K4) -> 0 | E35: =IF($V$2=0,$E4,$L4) -> 0 | F35: =IF($V$2=0,$F4,$M4) -> 0 | G35: =E41+D41+C41+F41 -> 0 | I35: =$B10 -> 0 | J35: =IF($V$2=0,$C10,$J10) -> 0 | K35: =IF($V$2=0,$D10,$K10) -> 0 | L35: =IF($V$2=0,$E10,$L10) -> 0 | M35: =IF($V$2=0,$F10,$M10) -> 0 | N35: =L41+K41+J41+M41 -> 0
B36: =$B5 -> 0 | C36: =IF($V$2=0,$C5,$J5) -> 0 | D36: =IF($V$2=0,$D5,$K5) -> 0 | E36: =IF($V$2=0,$E5,$L5) -> 0 | F36: =IF($V$2=0,$F5,$M5) -> 0 | I36: =$B11 -> 0 | J36: =IF($V$2=0,$C11,$J11) -> 0 | K36: =IF($V$2=0,$D11,$K11) -> 0 | L36: =IF($V$2=0,$E11,$L11) -> 0 | M36: =IF($V$2=0,$F11,$M11) -> 0
B37: =$B6 -> 0 | C37: =IF($V$2=0,$C6,$J6) -> 0 | D37: =IF($V$2=0,$D6,$K6) -> 0 | E37: =IF($V$2=0,$E6,$L6) -> 0 | F37: =IF($V$2=0,$F6,$M6) -> 0 | I37: =$B12 -> 0 | J37: =IF($V$2=0,$C12,$J12) -> 0 | K37: =IF($V$2=0,$D12,$K12) -> 0 | L37: =IF($V$2=0,$E12,$L12) -> 0 | M37: =IF($V$2=0,$F12,$M12) -> 0
B38: =$B7 -> 0 | C38: =IF($V$2=0,$C7,$J7) -> 0 | D38: =IF($V$2=0,$D7,$K7) -> 0 | E38: =IF($V$2=0,$E7,$L7) -> 0 | F38: =IF($V$2=0,$F7,$M7) -> 0 | I38: =$B13 -> 0 | J38: =IF($V$2=0,$C13,$J13) -> 0 | K38: =IF($V$2=0,$D13,$K13) -> 0 | L38: =IF($V$2=0,$E13,$L13) -> 0 | M38: =IF($V$2=0,$F13,$M13) -> 0
B39: =$B8 -> 0 | C39: =IF($V$2=0,$C8,$J8) -> 0 | D39: =IF($V$2=0,$D8,$K8) -> 0 | E39: =IF($V$2=0,$E8,$L8) -> 0 | F39: =IF($V$2=0,$F8,$M8) -> 0 | I39: =$B14 -> 0 | J39: =IF($V$2=0,$C14,$J14) -> 0 | K39: =IF($V$2=0,$D14,$K14) -> 0 | L39: =IF($V$2=0,$E14,$L14) -> 0 | M39: =IF($V$2=0,$F14,$M14) -> 0
B40: =$B9 -> 0 | C40: =IF($V$2=0,$C9,$J9) -> 0 | D40: =IF($V$2=0,$D9,$K9) -> 0 | E40: =IF($V$2=0,$E9,$L9) -> 0 | F40: =IF($V$2=0,$F9,$M9) -> 0 | I40: =$B15 -> 0 | J40: =IF($V$2=0,$C15,$J15) -> 0 | K40: =IF($V$2=0,$D15,$K15) -> 0 | L40: =IF($V$2=0,$E15,$L15) -> 0 | M40: =IF($V$2=0,$F15,$M15) -> 0
C41: =SUM(C35:C40) -> 0 | D41: =SUM(D35:D40) -> 0 | E41: =SUM(E35:E40) -> 0 | F41: =SUM(F35:F40) -> 0 | J41: =SUM(J35:J40) -> 0 | K41: =SUM(K35:K40) -> 0 | L41: =SUM(L35:L40) -> 0 | M41: =SUM(M35:M40) -> 0
B43: =$B16 -> 0 | C43: =IF($V$2=0,$C16,$J16) -> 0 | D43: =IF($V$2=0,$D16,$K16) -> 0 | E43: =IF($V$2=0,$E16,$L16) -> 0 | F43: =IF($V$2=0,$F16,$M16) -> 0 | G43: =E49+D49+C49+F49 -> 0 | I43: =$B22 -> 0 | J43: =IF($V$2=0,$C22,$J22) -> 0 | K43: =IF($V$2=0,$D22,$K22) -> 0 | L43: =IF($V$2=0,$E22,$L22) -> 0 | M43: =IF($V$2=0,$F22,$M22) -> 0 | N43: =L49+K49+J49+M49 -> 0
B44: =$B17 -> 0 | C44: =IF($V$2=0,$C17,$J17) -> 0 | D44: =IF($V$2=0,$D17,$K17) -> 0 | E44: =IF($V$2=0,$E17,$L17) -> 0 | F44: =IF($V$2=0,$F17,$M17) -> 0 | I44: =$B23 -> 0 | J44: =IF($V$2=0,$C23,$J23) -> 0 | K44: =IF($V$2=0,$D23,$K23) -> 0 | L44: =IF($V$2=0,$E23,$L23) -> 0 | M44: =IF($V$2=0,$F23,$M23) -> 0
B45: =$B18 -> 0 | C45: =IF($V$2=0,$C18,$J18) -> 0 | D45: =IF($V$2=0,$D18,$K18) -> 0 | E45: =IF($V$2=0,$E18,$L18) -> 0 | F45: =IF($V$2=0,$F18,$M18) -> 0 | I45: =$B24 -> 0 | J45: =IF($V$2=0,$C24,$J24) -> 0 | K45: =IF($V$2=0,$D24,$K24) -> 0 | L45: =IF($V$2=0,$E24,$L24) -> 0 | M45: =IF($V$2=0,$F24,$M24) -> 0
B46: =$B19 -> 0 | C46: =IF($V$2=0,$C19,$J19) -> 0 | D46: =IF($V$2=0,$D19,$K19) -> 0 | E46: =IF($V$2=0,$E19,$L19) -> 0 | F46: =IF($V$2=0,$F19,$M19) -> 0 | I46: =$B25 -> 0 | J46: =IF($V$2=0,$C25,$J25) -> 0 | K46: =IF($V$2=0,$D25,$K25) -> 0 | L46: =IF($V$2=0,$E25,$L25) -> 0 | M46: =IF($V$2=0,$F25,$M25) -> 0
B47: =$B20 -> 0 | C47: =IF($V$2=0,$C20,$J20) -> 0 | D47: =IF($V$2=0,$D20,$K20) -> 0 | E47: =IF($V$2=0,$E20,$L20) -> 0 | F47: =IF($V$2=0,$F20,$M20) -> 0 | I47: =$B26 -> 0 | J47: =IF($V$2=0,$C26,$J26) -> 0 | K47: =IF($V$2=0,$D26,$K26) -> 0 | L47: =IF($V$2=0,$E26,$L26) -> 0 | M47: =IF($V$2=0,$F26,$M26) -> 0
B48: =$B21 -> 0 | C48: =IF($V$2=0,$C21,$J21) -> 0 | D48: =IF($V$2=0,$D21,$K21) -> 0 | E48: =IF($V$2=0,$E21,$L21) -> 0 | F48: =IF($V$2=0,$F21,$M21) -> 0 | I48: =$B27 -> 0 | J48: =IF($V$2=0,$C27,$J27) -> 0 | K48: =IF($V$2=0,$D27,$K27) -> 0 | L48: =IF($V$2=0,$E27,$L27) -> 0 | M48: =IF($V$2=0,$F27,$M27) -> 0
C49: =SUM(C43:C48) -> 0 | D49: =SUM(D43:D48) -> 0 | E49: =SUM(E43:E48) -> 0 | F49: =SUM(F43:F48) -> 0 | J49: =SUM(J43:J48) -> 0 | K49: =SUM(K43:K48) -> 0 | L49: =SUM(L43:L48) -> 0 | M49: =SUM(M43:M48) -> 0
B51: =$B28 -> 0 | C51: =IF($V$2=0,$C28,$J28) -> 0 | D51: =IF($V$2=0,$D28,$K28) -> 0 | E51: =IF($V$2=0,$E28,$L28) -> 0 | F51: =IF($V$2=0,$F28,M28) -> 0 | G51: =E57+D57+C57+F57 -> 0
B52: =$B29 -> 0 | C52: =IF($V$2=0,$C29,$J29) -> 0 | D52: =IF($V$2=0,$D29,$K29) -> 0 | E52: =IF($V$2=0,$E29,$L29) -> 0 | F52: =IF($V$2=0,$F29,M29) -> 0
B53: =$B30 -> 0 | C53: =IF($V$2=0,$C30,$J30) -> 0 | D53: =IF($V$2=0,$D30,$K30) -> 0 | E53: =IF($V$2=0,$E30,$L30) -> 0 | F53: =IF($V$2=0,$F30,M30) -> 0
B54: =$B31 -> 0 | C54: =IF($V$2=0,$C31,$J31) -> 0 | D54: =IF($V$2=0,$D31,$K31) -> 0 | E54: =IF($V$2=0,$E31,$L31) -> 0 | F54: =IF($V$2=0,$F31,M31) -> 0
B55: =$B32 -> 0 | C55: =IF($V$2=0,$C32,$J32) -> 0 | D55: =IF($V$2=0,$D32,$K32) -> 0 | E55: =IF($V$2=0,$E32,$L32) -> 0 | F55: =IF($V$2=0,$F32,M32) -> 0
B56: =$B33 -> 0 | C56: =IF($V$2=0,$C33,$J33) -> 0 | D56: =IF($V$2=0,$D33,$K33) -> 0 | E56: =IF($V$2=0,$E33,$L33) -> 0 | F56: =IF($V$2=0,$F33,M33) -> 0
C57: =SUM(C51:C56) -> 0 | D57: =SUM(D51:D56) -> 0 | E57: =SUM(E51:E56) -> 0 | F57: =SUM(F51:F56) -> 0
A60: =A1 -> 2026 아르케 존 00회 정기 번개 점수
L61: 날짜 | N61: =N2 -> 46113
...

Sheet 00회번개 5인팀
A1: 2026 아르케 존 00회 번개 모임 점수
L2: 날짜 | N2: 46113 | U2: 팀전에버기준 | V2: 0 | W2: 순위에버오차기준 | X2: 0
B3: 이 름 | C3: 1 G | D3: 2 G | E3: 3 G | F3: 4G | G3: 합 계 | H3: 에 버 | I3: 기본에버 | J3: 1 G | K3: 2 G | L3: 3 G | M3: 4G | N3: 합 계 | O3: 오 차 | U3: 수식입력부분 삭제하지마세요~
A4: 1 | G4: =F4+E4+D4+C4 -> 0 | H4: =G4/4 -> 0 | I4: =IF(B4="","",IFERROR(INDEX('회원명단 및 기준에버'!D:G,MATCH(B4,'회원명단 및 기준에버'!$C:$C,0),CHOOSE(INT((MONTH($N$2)-1)/3)+1,1,2,3,4)),"")) | J4: =IFERROR(C4+-I4,0) -> 0 | K4: =IFERROR(D4+-I4,0) -> 0 | L4: =IFERROR(E4+-I4,0) -> 0 | M4: =IFERROR(F4+-I4,0) -> 0 | N4: =SUM(J4:M4) -> 0 | O4: =IFERROR(H4+-I4,0) -> 0 | U4: =MAX(C4:F4)-MIN(C4:F4) -> 0 | V4: =IF($X$2=0,(G4*1000000+U4*1000+A4),(O4*1000000+U4*1000+A4)) -> 1 | W4: =_xlfn.RANK.EQ(V4,$V$4:$V$33,0) -> 30
A5: 2 | G5: =F5+E5+D5+C5 -> 0 | H5: =G5/4 -> 0 | I5: =IF(B5="","",IFERROR(INDEX('회원명단 및 기준에버'!D:G,MATCH(B5,'회원명단 및 기준에버'!$C:$C,0),CHOOSE(INT((MONTH($N$2)-1)/3)+1,1,2,3,4)),"")) | J5: =IFERROR(C5+-I5,0) -> 0 | K5: =IFERROR(D5+-I5,0) -> 0 | L5: =IFERROR(E5+-I5,0) -> 0 | M5: =IFERROR(F5+-I5,0) -> 0 | N5: =SUM(J5:M5) -> 0 | O5: =IFERROR(H5+-I5,0) -> 0 | U5: =MAX(C5:F5)-MIN(C5:F5) -> 0 | V5: =IF($X$2=0,(G5*1000000+U5*1000+A5),(O5*1000000+U5*1000+A5)) -> 2 | W5: =_xlfn.RANK.EQ(V5,$V$4:$V$33,0) -> 29
A6: 3 | G6: =F6+E6+D6+C6 -> 0 | H6: =G6/4 -> 0 | I6: =IF(B6="","",IFERROR(INDEX('회원명단 및 기준에버'!D:G,MATCH(B6,'회원명단 및 기준에버'!$C:$C,0),CHOOSE(INT((MONTH($N$2)-1)/3)+1,1,2,3,4)),"")) | J6: =IFERROR(C6+-I6,0) -> 0 | K6: =IFERROR(D6+-I6,0) -> 0 | L6: =IFERROR(E6+-I6,0) -> 0 | M6: =IFERROR(F6+-I6,0) -> 0 | N6: =SUM(J6:M6) -> 0 | O6: =IFERROR(H6+-I6,0) -> 0 | U6: =MAX(C6:F6)-MIN(C6:F6) -> 0 | V6: =IF($X$2=0,(G6*1000000+U6*1000+A6),(O6*1000000+U6*1000+A6)) -> 3 | W6: =_xlfn.RANK.EQ(V6,$V$4:$V$33,0) -> 28
A7: 4 | G7: =F7+E7+D7+C7 -> 0 | H7: =G7/4 -> 0 | I7: =IF(B7="","",IFERROR(INDEX('회원명단 및 기준에버'!D:G,MATCH(B7,'회원명단 및 기준에버'!$C:$C,0),CHOOSE(INT((MONTH($N$2)-1)/3)+1,1,2,3,4)),"")) | J7: =IFERROR(C7+-I7,0) -> 0 | K7: =IFERROR(D7+-I7,0) -> 0 | L7: =IFERROR(E7+-I7,0) -> 0 | M7: =IFERROR(F7+-I7,0) -> 0 | N7: =SUM(J7:M7) -> 0 | O7: =IFERROR(H7+-I7,0) -> 0 | U7: =MAX(C7:F7)-MIN(C7:F7) -> 0 | V7: =IF($X$2=0,(G7*1000000+U7*1000+A7),(O7*1000000+U7*1000+A7)) -> 4 | W7: =_xlfn.RANK.EQ(V7,$V$4:$V$33,0) -> 27
A8: 5 | G8: =F8+E8+D8+C8 -> 0 | H8: =G8/4 -> 0 | I8: =IF(B8="","",IFERROR(INDEX('회원명단 및 기준에버'!D:G,MATCH(B8,'회원명단 및 기준에버'!$C:$C,0),CHOOSE(INT((MONTH($N$2)-1)/3)+1,1,2,3,4)),"")) | J8: =IFERROR(C8+-I8,0) -> 0 | K8: =IFERROR(D8+-I8,0) -> 0 | L8: =IFERROR(E8+-I8,0) -> 0 | M8: =IFERROR(F8+-I8,0) -> 0 | N8: =SUM(J8:M8) -> 0 | O8: =IFERROR(H8+-I8,0) -> 0 | U8: =MAX(C8:F8)-MIN(C8:F8) -> 0 | V8: =IF($X$2=0,(G8*1000000+U8*1000+A8),(O8*1000000+U8*1000+A8)) -> 5 | W8: =_xlfn.RANK.EQ(V8,$V$4:$V$33,0) -> 26
A9: 6 | G9: =F9+E9+D9+C9 -> 0 | H9: =G9/4 -> 0 | I9: =IF(B9="","",IFERROR(INDEX('회원명단 및 기준에버'!D:G,MATCH(B9,'회원명단 및 기준에버'!$C:$C,0),CHOOSE(INT((MONTH($N$2)-1)/3)+1,1,2,3,4)),"")) | J9: =IFERROR(C9+-I9,0) -> 0 | K9: =IFERROR(D9+-I9,0) -> 0 | L9: =IFERROR(E9+-I9,0) -> 0 | M9: =IFERROR(F9+-I9,0) -> 0 | N9: =SUM(J9:M9) -> 0 | O9: =IFERROR(H9+-I9,0) -> 0 | U9: =MAX(C9:F9)-MIN(C9:F9) -> 0 | V9: =IF($X$2=0,(G9*1000000+U9*1000+A9),(O9*1000000+U9*1000+A9)) -> 6 | W9: =_xlfn.RANK.EQ(V9,$V$4:$V$33,0) -> 25
A10: 7 | G10: =F10+E10+D10+C10 -> 0 | H10: =G10/4 -> 0 | I10: =IF(B10="","",IFERROR(INDEX('회원명단 및 기준에버'!D:G,MATCH(B10,'회원명단 및 기준에버'!$C:$C,0),CHOOSE(INT((MONTH($N$2)-1)/3)+1,1,2,3,4)),"")) | J10: =IFERROR(C10+-I10,0) -> 0 | K10: =IFERROR(D10+-I10,0) -> 0 | L10: =IFERROR(E10+-I10,0) -> 0 | M10: =IFERROR(F10+-I10,0) -> 0 | N10: =SUM(J10:M10) -> 0 | O10: =IFERROR(H10+-I10,0) -> 0 | U10: =MAX(C10:F10)-MIN(C10:F10) -> 0 | V10: =IF($X$2=0,(G10*1000000+U10*1000+A10),(O10*1000000+U10*1000+A10)) -> 7 | W10: =_xlfn.RANK.EQ(V10,$V$4:$V$33,0) -> 24
A11: 8 | G11: =F11+E11+D11+C11 -> 0 | H11: =G11/4 -> 0 | I11: =IF(B11="","",IFERROR(INDEX('회원명단 및 기준에버'!D:G,MATCH(B11,'회원명단 및 기준에버'!$C:$C,0),CHOOSE(INT((MONTH($N$2)-1)/3)+1,1,2,3,4)),"")) | J11: =IFERROR(C11+-I11,0) -> 0 | K11: =IFERROR(D11+-I11,0) -> 0 | L11: =IFERROR(E11+-I11,0) -> 0 | M11: =IFERROR(F11+-I11,0) -> 0 | N11: =SUM(J11:M11) -> 0 | O11: =IFERROR(H11+-I11,0) -> 0 | U11: =MAX(C11:F11)-MIN(C11:F11) -> 0 | V11: =IF($X$2=0,(G11*1000000+U11*1000+A11),(O11*1000000+U11*1000+A11)) -> 8 | W11: =_xlfn.RANK.EQ(V11,$V$4:$V$33,0) -> 23
A12: 9 | G12: =F12+E12+D12+C12 -> 0 | H12: =G12/4 -> 0 | I12: =IF(B12="","",IFERROR(INDEX('회원명단 및 기준에버'!D:G,MATCH(B12,'회원명단 및 기준에버'!$C:$C,0),CHOOSE(INT((MONTH($N$2)-1)/3)+1,1,2,3,4)),"")) | J12: =IFERROR(C12+-I12,0) -> 0 | K12: =IFERROR(D12+-I12,0) -> 0 | L12: =IFERROR(E12+-I12,0) -> 0 | M12: =IFERROR(F12+-I12,0) -> 0 | N12: =SUM(J12:M12) -> 0 | O12: =IFERROR(H12+-I12,0) -> 0 | U12: =MAX(C12:F12)-MIN(C12:F12) -> 0 | V12: =IF($X$2=0,(G12*1000000+U12*1000+A12),(O12*1000000+U12*1000+A12)) -> 9 | W12: =_xlfn.RANK.EQ(V12,$V$4:$V$33,0) -> 22
A13: 10 | G13: =F13+E13+D13+C13 -> 0 | H13: =G13/4 -> 0 | I13: =IF(B13="","",IFERROR(INDEX('회원명단 및 기준에버'!D:G,MATCH(B13,'회원명단 및 기준에버'!$C:$C,0),CHOOSE(INT((MONTH($N$2)-1)/3)+1,1,2,3,4)),"")) | J13: =IFERROR(C13+-I13,0) -> 0 | K13: =IFERROR(D13+-I13,0) -> 0 | L13: =IFERROR(E13+-I13,0) -> 0 | M13: =IFERROR(F13+-I13,0) -> 0 | N13: =SUM(J13:M13) -> 0 | O13: =IFERROR(H13+-I13,0) -> 0 | U13: =MAX(C13:F13)-MIN(C13:F13) -> 0 | V13: =IF($X$2=0,(G13*1000000+U13*1000+A13),(O13*1000000+U13*1000+A13)) -> 10 | W13: =_xlfn.RANK.EQ(V13,$V$4:$V$33,0) -> 21
A14: 11 | G14: =F14+E14+D14+C14 -> 0 | H14: =G14/4 -> 0 | I14: =IF(B14="","",IFERROR(INDEX('회원명단 및 기준에버'!D:G,MATCH(B14,'회원명단 및 기준에버'!$C:$C,0),CHOOSE(INT((MONTH($N$2)-1)/3)+1,1,2,3,4)),"")) | J14: =IFERROR(C14+-I14,0) -> 0 | K14: =IFERROR(D14+-I14,0) -> 0 | L14: =IFERROR(E14+-I14,0) -> 0 | M14: =IFERROR(F14+-I14,0) -> 0 | N14: =SUM(J14:M14) -> 0 | O14: =IFERROR(H14+-I14,0) -> 0 | U14: =MAX(C14:F14)-MIN(C14:F14) -> 0 | V14: =IF($X$2=0,(G14*1000000+U14*1000+A14),(O14*1000000+U14*1000+A14)) -> 11 | W14: =_xlfn.RANK.EQ(V14,$V$4:$V$33,0) -> 20
A15: 12 | G15: =F15+E15+D15+C15 -> 0 | H15: =G15/4 -> 0 | I15: =IF(B15="","",IFERROR(INDEX('회원명단 및 기준에버'!D:G,MATCH(B15,'회원명단 및 기준에버'!$C:$C,0),CHOOSE(INT((MONTH($N$2)-1)/3)+1,1,2,3,4)),"")) | J15: =IFERROR(C15+-I15,0) -> 0 | K15: =IFERROR(D15+-I15,0) -> 0 | L15: =IFERROR(E15+-I15,0) -> 0 | M15: =IFERROR(F15+-I15,0) -> 0 | N15: =SUM(J15:M15) -> 0 | O15: =IFERROR(H15+-I15,0) -> 0 | U15: =MAX(C15:F15)-MIN(C15:F15) -> 0 | V15: =IF($X$2=0,(G15*1000000+U15*1000+A15),(O15*1000000+U15*1000+A15)) -> 12 | W15: =_xlfn.RANK.EQ(V15,$V$4:$V$33,0) -> 19
... A33: 30 | G33: =F33+E33+D33+C33 -> 0 | H33: =G33/4 -> 0 | I33: =IF(B33="","",IFERROR(INDEX('회원명단 및 기준에버'!D:G,MATCH(B33,'회원명단 및 기준에버'!$C:$C,0),CHOOSE(INT((MONTH($N$2)-1)/3)+1,1,2,3,4)),"")) | J33: =IFERROR(C33+-I33,0) -> 0 | K33: =IFERROR(D33+-I33,0) -> 0 | L33: =IFERROR(E33+-I33,0) -> 0 | M33: =IFERROR(F33+-I33,0) -> 0 | N33: =SUM(J33:M33) -> 0 | O33: =IFERROR(H33+-I33,0) -> 0 | U33: =MAX(C33:F33)-MIN(C33:F33) -> 0 | V33: =IF($X$2=0,(G33*1000000+U33*1000+A33),(O33*1000000+U33*1000+A33)) -> 30 | W33: =_xlfn.RANK.EQ(V33,$V$4:$V$33,0) -> 1
B34: 팀 전
B35: =$B4 -> 0 | C35: =IF($V$2=0,$C4,$J4) -> 0 | D35: =IF($V$2=0,$D4,$K4) -> 0 | E35: =IF($V$2=0,$E4,$L4) -> 0 | F35: =IF($V$2=0,$F4,$M4) -> 0 | G35: =E40+D40+C40+F40 -> 0 | I35: =$B9 -> 0 | J35: =IF($V$2=0,$C9,$J9) -> 0 | K35: =IF($V$2=0,$D9,$K9) -> 0 | L35: =IF($V$2=0,$E9,$L9) -> 0 | M35: =IF($V$2=0,$F9,$M9) -> 0 | N35: =L40+K40+J40+M40 -> 0
B36: =$B5 -> 0 | C36: =IF($V$2=0,$C5,$J5) -> 0 | D36: =IF($V$2=0,$D5,$K5) -> 0 | E36: =IF($V$2=0,$E5,$L5) -> 0 | F36: =IF($V$2=0,$F5,$M5) -> 0 | I36: =$B10 -> 0 | J36: =IF($V$2=0,$C10,$J10) -> 0 | K36: =IF($V$2=0,$D10,$K10) -> 0 | L36: =IF($V$2=0,$E10,$L10) -> 0 | M36: =IF($V$2=0,$F10,$M10) -> 0
B37: =$B6 -> 0 | C37: =IF($V$2=0,$C6,$J6) -> 0 | D37: =IF($V$2=0,$D6,$K6) -> 0 | E37: =IF($V$2=0,$E6,$L6) -> 0 | F37: =IF($V$2=0,$F6,$M6) -> 0 | I37: =$B11 -> 0 | J37: =IF($V$2=0,$C11,$J11) -> 0 | K37: =IF($V$2=0,$D11,$K11) -> 0 | L37: =IF($V$2=0,$E11,$L11) -> 0 | M37: =IF($V$2=0,$F11,$M11) -> 0
B38: =$B7 -> 0 | C38: =IF($V$2=0,$C7,$J7) -> 0 | D38: =IF($V$2=0,$D7,$K7) -> 0 | E38: =IF($V$2=0,$E7,$L7) -> 0 | F38: =IF($V$2=0,$F7,$M7) -> 0 | I38: =$B12 -> 0 | J38: =IF($V$2=0,$C12,$J12) -> 0 | K38: =IF($V$2=0,$D12,$K12) -> 0 | L38: =IF($V$2=0,$E12,$L12) -> 0 | M38: =IF($V$2=0,$F12,$M12) -> 0
B39: =$B8 -> 0 | C39: =IF($V$2=0,$C8,$J8) -> 0 | D39: =IF($V$2=0,$D8,$K8) -> 0 | E39: =IF($V$2=0,$E8,$L8) -> 0 | F39: =IF($V$2=0,$F8,$M8) -> 0 | I39: =$B13 -> 0 | J39: =IF($V$2=0,$C13,$J13) -> 0 | K39: =IF($V$2=0,$D13,$K13) -> 0 | L39: =IF($V$2=0,$E13,$L13) -> 0 | M39: =IF($V$2=0,$F13,$M13) -> 0
C40: =SUM(C35:C39) -> 0 | D40: =SUM(D35:D39) -> 0 | E40: =SUM(E35:E39) -> 0 | F40: =SUM(F35:F39) -> 0 | J40: =SUM(J35:J39) -> 0 | K40: =SUM(K35:K39) -> 0 | L40: =SUM(L35:L39) -> 0 | M40: =SUM(M35:M39) -> 0
B42: =$B14 -> 0 | C42: =IF($V$2=0,$C14,$J14) -> 0 | D42: =IF($V$2=0,$D14,$K14) -> 0 | E42: =IF($V$2=0,$E14,$L14) -> 0 | F42: =IF($V$2=0,$F14,$M14) -> 0 | G42: =E47+D47+C47+F47 -> 0 | I42: =$B19 -> 0 | J42: =IF($V$2=0,$C19,$J19) -> 0 | K42: =IF($V$2=0,$D19,$K19) -> 0 | L42: =IF($V$2=0,$E19,$L19) -> 0 | M42: =IF($V$2=0,$F19,$M19) -> 0 | N42: =L47+K47+J47+M47 -> 0
B43: =$B15 -> 0 | C43: =IF($V$2=0,$C15,$J15) -> 0 | D43: =IF($V$2=0,$D15,$K15) -> 0 | E43: =IF($V$2=0,$E15,$L15) -> 0 | F43: =IF($V$2=0,$F15,$M15) -> 0 | I43: =$B20 -> 0 | J43: =IF($V$2=0,$C20,$J20) -> 0 | K43: =IF($V$2=0,$D20,$K20) -> 0 | L43: =IF($V$2=0,$E20,$L20) -> 0 | M43: =IF($V$2=0,$F20,$M20) -> 0
B44: =$B16 -> 0 | C44: =IF($V$2=0,$C16,$J16) -> 0 | D44: =IF($V$2=0,$D16,$K16) -> 0 | E44: =IF($V$2=0,$E16,$L16) -> 0 | F44: =IF($V$2=0,$F16,$M16) -> 0 | I44: =$B21 -> 0 | J44: =IF($V$2=0,$C21,$J21) -> 0 | K44: =IF($V$2=0,$D21,$K21) -> 0 | L44: =IF($V$2=0,$E21,$L21) -> 0 | M44: =IF($V$2=0,$F21,$M21) -> 0
B45: =$B17 -> 0 | C45: =IF($V$2=0,$C17,$J17) -> 0 | D45: =IF($V$2=0,$D17,$K17) -> 0 | E45: =IF($V$2=0,$E17,$L17) -> 0 | F45: =IF($V$2=0,$F17,$M17) -> 0 | I45: =$B22 -> 0 | J45: =IF($V$2=0,$C22,$J22) -> 0 | K45: =IF($V$2=0,$D22,$K22) -> 0 | L45: =IF($V$2=0,$E22,$L22) -> 0 | M45: =IF($V$2=0,$F22,$M22) -> 0
B46: =$B18 -> 0 | C46: =IF($V$2=0,$C18,$J18) -> 0 | D46: =IF($V$2=0,$D18,$K18) -> 0 | E46: =IF($V$2=0,$E18,$L18) -> 0 | F46: =IF($V$2=0,$F18,$M18) -> 0 | I46: =$B23 -> 0 | J46: =IF($V$2=0,$C23,$J23) -> 0 | K46: =IF($V$2=0,$D23,$K23) -> 0 | L46: =IF($V$2=0,$E23,$L23) -> 0 | M46: =IF($V$2=0,$F23,$M23) -> 0
C47: =SUM(C42:C46) -> 0 | D47: =SUM(D42:D46) -> 0 | E47: =SUM(E42:E46) -> 0 | F47: =SUM(F42:F46) -> 0 | J47: =SUM(J42:J46) -> 0 | K47: =SUM(K42:K46) -> 0 | L47: =SUM(L42:L46) -> 0 | M47: =SUM(M42:M46) -> 0
B49: =$B24 -> 0 | C49: =IF($V$2=0,$C24,$J24) -> 0 | D49: =IF($V$2=0,$D24,$K24) -> 0 | E49: =IF($V$2=0,$E24,$L24) -> 0 | F49: =IF($V$2=0,$F24,$M24) -> 0 | G49: =E54+D54+C54+F54 -> 0
B50: =$B25 -> 0 | C50: =IF($V$2=0,$C25,$J25) -> 0 | D50: =IF($V$2=0,$D25,$K25) -> 0 | E50: =IF($V$2=0,$E25,$L25) -> 0 | F50: =IF($V$2=0,$F25,$M25) -> 0
B51: =$B26 -> 0 | C51: =IF($V$2=0,$C26,$J26) -> 0 | D51: =IF($V$2=0,$D26,$K26) -> 0 | E51: =IF($V$2=0,$E26,$L26) -> 0 | F51: =IF($V$2=0,$F26,$M26) -> 0
B52: =$B27 -> 0 | C52: =IF($V$2=0,$C27,$J27) -> 0 | D52: =IF($V$2=0,$D27,$K27) -> 0 | E52: =IF($V$2=0,$E27,$L27) -> 0 | F52: =IF($V$2=0,$F27,$M27) -> 0
B53: =$B28 -> 0 | C53: =IF($V$2=0,$C28,$J28) -> 0 | D53: =IF($V$2=0,$D28,$K28) -> 0 | E53: =IF($V$2=0,$E28,$L28) -> 0 | F53: =IF($V$2=0,$F28,$M28) -> 0
C54: =SUM(C49:C53) -> 0 | D54: =SUM(D49:D53) -> 0 | E54: =SUM(E49:E53) -> 0 | F54: =SUM(F49:F53) -> 0
A58: =A1 -> 2026 아르케 존 00회 번개 모임 점수
L59: 날짜 | N59: =N2 -> 46113
B60: 이 름 | C60: 1 G | D60: 2 G | E60: 3 G | F60: 4G | G60: 합 계 | H60: 에 버 | I60: 기본에버 | J60: 1 G | K60: 2 G | L60: 3 G | M60: 4G | N60: 합 계 | O60: 오 차
A61: 1 | B61: {=INDEX($B$4:$O$33,MATCH($A61,$W$4:$W$33,0),COLUMN(A$1))} -> 0 | C61: {=INDEX($B$4:$O$33,MATCH($A61,$W$4:$W$33,0),COLUMN(B$1))} -> 0 | D61: {=INDEX($B$4:$O$33,MATCH($A61,$W$4:$W$33,0),COLUMN(C$1))} -> 0 | E61: {=INDEX($B$4:$O$33,MATCH($A61,$W$4:$W$33,0),COLUMN(D$1))} -> 0 | F61: {=INDEX($B$4:$O$33,MATCH($A61,$W$4:$W$33,0),COLUMN(E$1))} -> 0 | G61: =SUM(C61:F61) -> 0 | H61: =G61/4 -> 0 | I61: =IF(B61="","",IFERROR(INDEX('회원명단 및 기준에버'!D:G,MATCH(B61,'회원명단 및 기준에버'!$C:$C,0),CHOOSE(INT((MONTH($N$2)-1)/3)+1,1,2,3,4)),"")) | J61: =IFERROR(C61+-I61,0) -> 0 | K61: =IFERROR(D61+-I61,0) -> 0 | L61: =IFERROR(E61+-I61,0) -> 0 | M61: =IFERROR(F61+-I61,0) -> 0 | N61: =SUM(J61:M61) -> 0 | O61: =IFERROR(H61+-I61,0) -> 0
A62: 2 | B62: {=INDEX($B$4:$O$33,MATCH($A62,$W$4:$W$33,0),COLUMN(A$1))} -> 0 | C62: {=INDEX($B$4:$O$33,MATCH($A62,$W$4:$W$33,0),COLUMN(B$1))} -> 0 | D62: {=INDEX($B$4:$O$33,MATCH($A62,$W$4:$W$33,0),COLUMN(C$1))} -> 0 | E62: {=INDEX($B$4:$O$33,MATCH($A62,$W$4:$W$33,0),COLUMN(D$1))} -> 0 | F62: {=INDEX($B$4:$O$33,MATCH($A62,$W$4:$W$33,0),COLUMN(E$1))} -> 0 | G62: =SUM(C62:F62) -> 0 | H62: =G62/4 -> 0 | I62: =IF(B62="","",IFERROR(INDEX('회원명단 및 기준에버'!D:G,MATCH(B62,'회원명단 및 기준에버'!$C:$C,0),CHOOSE(INT((MONTH($N$2)-1)/3)+1,1,2,3,4)),"")) | J62: =IFERROR(C62+-I62,0) -> 0 | K62: =IFERROR(D62+-I62,0) -> 0 | L62: =IFERROR(E62+-I62,0) -> 0 | M62: =IFERROR(F62+-I62,0) -> 0 | N62: =SUM(J62:M62) -> 0 | O62: =IFERROR(H62+-I62,0) -> 0
...

Sheet 00회번개 4인팀
A1: 2026 아르케 존 00회 정기 번개 점수
L2: 날짜 | N2: 46113 | U2: 팀전에버기준 | V2: 0 | W2: 순위에버오차기준 | X2: 0
B3: 이 름 | C3: 1 G | D3: 2 G | E3: 3 G | F3: 4G | G3: 합 계 | H3: 에 버 | I3: 기본에버 | J3: 1 G | K3: 2 G | L3: 3 G | M3: 4G | N3: 합 계 | O3: 오 차 | U3: 수식입력부분 삭제하지마세요~
A4: 1 | G4: =SUM(C4:F4) -> 0 | H4: =G4/4 -> 0 | I4: =IF(B4="","",IFERROR(INDEX('회원명단 및 기준에버'!D:G,MATCH(B4,'회원명단 및 기준에버'!$C:$C,0),CHOOSE(INT((MONTH($N$2)-1)/3)+1,1,2,3,4)),"")) | J4: =IFERROR(C4+-I4,0) -> 0 | K4: =IFERROR(D4+-I4,0) -> 0 | L4: =IFERROR(E4+-I4,0) -> 0 | M4: =IFERROR(F4+-I4,0) -> 0 | N4: =SUM(J4:M4) -> 0 | O4: =IFERROR(H4+-I4,0) -> 0 | U4: =MAX(C4:F4)-MIN(C4:F4) -> 0 | V4: =IF($X$2=0,(G4*1000000+U4*1000+A4),(O4*1000000+U4*1000+A4)) -> 1 | W4: =_xlfn.RANK.EQ(V4,$V$4:$V$27,0) -> 24
A5: 2 | G5: =SUM(C5:F5) -> 0 | H5: =G5/4 -> 0 | I5: =IF(B5="","",IFERROR(INDEX('회원명단 및 기준에버'!D:G,MATCH(B5,'회원명단 및 기준에버'!$C:$C,0),CHOOSE(INT((MONTH($N$2)-1)/3)+1,1,2,3,4)),"")) | J5: =IFERROR(C5+-I5,0) -> 0 | K5: =IFERROR(D5+-I5,0) -> 0 | L5: =IFERROR(E5+-I5,0) -> 0 | M5: =IFERROR(F5+-I5,0) -> 0 | N5: =SUM(J5:M5) -> 0 | O5: =IFERROR(H5+-I5,0) -> 0 | U5: =MAX(C5:F5)-MIN(C5:F5) -> 0 | V5: =IF($X$2=0,(G5*1000000+U5*1000+A5),(O5*1000000+U5*1000+A5)) -> 2 | W5: =_xlfn.RANK.EQ(V5,$V$4:$V$27,0) -> 23
A6: 3 | G6: =SUM(C6:F6) -> 0 | H6: =G6/4 -> 0 | I6: =IF(B6="","",IFERROR(INDEX('회원명단 및 기준에버'!D:G,MATCH(B6,'회원명단 및 기준에버'!$C:$C,0),CHOOSE(INT((MONTH($N$2)-1)/3)+1,1,2,3,4)),"")) | J6: =IFERROR(C6+-I6,0) -> 0 | K6: =IFERROR(D6+-I6,0) -> 0 | L6: =IFERROR(E6+-I6,0) -> 0 | M6: =IFERROR(F6+-I6,0) -> 0 | N6: =SUM(J6:M6) -> 0 | O6: =IFERROR(H6+-I6,0) -> 0 | U6: =MAX(C6:F6)-MIN(C6:F6) -> 0 | V6: =IF($X$2=0,(G6*1000000+U6*1000+A6),(O6*1000000+U6*1000+A6)) -> 3 | W6: =_xlfn.RANK.EQ(V6,$V$4:$V$27,0) -> 22
A7: 4 | G7: =SUM(C7:F7) -> 0 | H7: =G7/4 -> 0 | I7: =IF(B7="","",IFERROR(INDEX('회원명단 및 기준에버'!D:G,MATCH(B7,'회원명단 및 기준에버'!$C:$C,0),CHOOSE(INT((MONTH($N$2)-1)/3)+1,1,2,3,4)),"")) | J7: =IFERROR(C7+-I7,0) -> 0 | K7: =IFERROR(D7+-I7,0) -> 0 | L7: =IFERROR(E7+-I7,0) -> 0 | M7: =IFERROR(F7+-I7,0) -> 0 | N7: =SUM(J7:M7) -> 0 | O7: =IFERROR(H7+-I7,0) -> 0 | U7: =MAX(C7:F7)-MIN(C7:F7) -> 0 | V7: =IF($X$2=0,(G7*1000000+U7*1000+A7),(O7*1000000+U7*1000+A7)) -> 4 | W7: =_xlfn.RANK.EQ(V7,$V$4:$V$27,0) -> 21
A8: 5 | G8: =SUM(C8:E8) -> 0 | H8: =G8/4 -> 0 | I8: =IF(B8="","",IFERROR(INDEX('회원명단 및 기준에버'!D:G,MATCH(B8,'회원명단 및 기준에버'!$C:$C,0),CHOOSE(INT((MONTH($N$2)-1)/3)+1,1,2,3,4)),"")) | J8: =IFERROR(C8+-I8,0) -> 0 | K8: =IFERROR(D8+-I8,0) -> 0 | L8: =IFERROR(E8+-I8,0) -> 0 | M8: =IFERROR(F8+-I8,0) -> 0 | N8: =SUM(J8:M8) -> 0 | O8: =IFERROR(H8+-I8,0) -> 0 | U8: =MAX(C8:F8)-MIN(C8:F8) -> 0 | V8: =IF($X$2=0,(G8*1000000+U8*1000+A8),(O8*1000000+U8*1000+A8)) -> 5 | W8: =_xlfn.RANK.EQ(V8,$V$4:$V$27,0) -> 20
A9: 6 | G9: =SUM(C9:E9) -> 0 | H9: =G9/4 -> 0 | I9: =IF(B9="","",IFERROR(INDEX('회원명단 및 기준에버'!D:G,MATCH(B9,'회원명단 및 기준에버'!$C:$C,0),CHOOSE(INT((MONTH($N$2)-1)/3)+1,1,2,3,4)),"")) | J9: =IFERROR(C9+-I9,0) -> 0 | K9: =IFERROR(D9+-I9,0) -> 0 | L9: =IFERROR(E9+-I9,0) -> 0 | M9: =IFERROR(F9+-I9,0) -> 0 | N9: =SUM(J9:M9) -> 0 | O9: =IFERROR(H9+-I9,0) -> 0 | U9: =MAX(C9:F9)-MIN(C9:F9) -> 0 | V9: =IF($X$2=0,(G9*1000000+U9*1000+A9),(O9*1000000+U9*1000+A9)) -> 6 | W9: =_xlfn.RANK.EQ(V9,$V$4:$V$27,0) -> 19
A10: 7 | G10: =SUM(C10:E10) -> 0 | H10: =G10/4 -> 0 | I10: =IF(B10="","",IFERROR(INDEX('회원명단 및 기준에버'!D:G,MATCH(B10,'회원명단 및 기준에버'!$C:$C,0),CHOOSE(INT((MONTH($N$2)-1)/3)+1,1,2,3,4)),"")) | J10: =IFERROR(C10+-I10,0) -> 0 | K10: =IFERROR(D10+-I10,0) -> 0 | L10: =IFERROR(E10+-I10,0) -> 0 | M10: =IFERROR(F10+-I10,0) -> 0 | N10: =SUM(J10:M10) -> 0 | O10: =IFERROR(H10+-I10,0) -> 0 | U10: =MAX(C10:F10)-MIN(C10:F10) -> 0 | V10: =IF($X$2=0,(G10*1000000+U10*1000+A10),(O10*1000000+U10*1000+A10)) -> 7 | W10: =_xlfn.RANK.EQ(V10,$V$4:$V$27,0) -> 18
A11: 8 | G11: =SUM(C11:E11) -> 0 | H11: =G11/4 -> 0 | I11: =IF(B11="","",IFERROR(INDEX('회원명단 및 기준에버'!D:G,MATCH(B11,'회원명단 및 기준에버'!$C:$C,0),CHOOSE(INT((MONTH($N$2)-1)/3)+1,1,2,3,4)),"")) | J11: =IFERROR(C11+-I11,0) -> 0 | K11: =IFERROR(D11+-I11,0) -> 0 | L11: =IFERROR(E11+-I11,0) -> 0 | M11: =IFERROR(F11+-I11,0) -> 0 | N11: =SUM(J11:M11) -> 0 | O11: =IFERROR(H11+-I11,0) -> 0 | U11: =MAX(C11:F11)-MIN(C11:F11) -> 0 | V11: =IF($X$2=0,(G11*1000000+U11*1000+A11),(O11*1000000+U11*1000+A11)) -> 8 | W11: =_xlfn.RANK.EQ(V11,$V$4:$V$27,0) -> 17
A12: 9 | G12: =SUM(C12:E12) -> 0 | H12: =G12/4 -> 0 | I12: =IF(B12="","",IFERROR(INDEX('회원명단 및 기준에버'!D:G,MATCH(B12,'회원명단 및 기준에버'!$C:$C,0),CHOOSE(INT((MONTH($N$2)-1)/3)+1,1,2,3,4)),"")) | J12: =IFERROR(C12+-I12,0) -> 0 | K12: =IFERROR(D12+-I12,0) -> 0 | L12: =IFERROR(E12+-I12,0) -> 0 | M12: =IFERROR(F12+-I12,0) -> 0 | N12: =SUM(J12:M12) -> 0 | O12: =IFERROR(H12+-I12,0) -> 0 | U12: =MAX(C12:F12)-MIN(C12:F12) -> 0 | V12: =IF($X$2=0,(G12*1000000+U12*1000+A12),(O12*1000000+U12*1000+A12)) -> 9 | W12: =_xlfn.RANK.EQ(V12,$V$4:$V$27,0) -> 16
A13: 10 | G13: =SUM(C13:E13) -> 0 | H13: =G13/4 -> 0 | I13: =IF(B13="","",IFERROR(INDEX('회원명단 및 기준에버'!D:G,MATCH(B13,'회원명단 및 기준에버'!$C:$C,0),CHOOSE(INT((MONTH($N$2)-1)/3)+1,1,2,3,4)),"")) | J13: =IFERROR(C13+-I13,0) -> 0 | K13: =IFERROR(D13+-I13,0) -> 0 | L13: =IFERROR(E13+-I13,0) -> 0 | M13: =IFERROR(F13+-I13,0) -> 0 | N13: =SUM(J13:M13) -> 0 | O13: =IFERROR(H13+-I13,0) -> 0 | U13: =MAX(C13:F13)-MIN(C13:F13) -> 0 | V13: =IF($X$2=0,(G13*1000000+U13*1000+A13),(O13*1000000+U13*1000+A13)) -> 10 | W13: =_xlfn.RANK.EQ(V13,$V$4:$V$27,0) -> 15
A14: 11 | G14: =SUM(C14:E14) -> 0 | H14: =G14/4 -> 0 | I14: =IF(B14="","",IFERROR(INDEX('회원명단 및 기준에버'!D:G,MATCH(B14,'회원명단 및 기준에버'!$C:$C,0),CHOOSE(INT((MONTH($N$2)-1)/3)+1,1,2,3,4)),"")) | J14: =IFERROR(C14+-I14,0) -> 0 | K14: =IFERROR(D14+-I14,0) -> 0 | L14: =IFERROR(E14+-I14,0) -> 0 | M14: =IFERROR(F14+-I14,0) -> 0 | N14: =SUM(J14:M14) -> 0 | O14: =IFERROR(H14+-I14,0) -> 0 | U14: =MAX(C14:F14)-MIN(C14:F14) -> 0 | V14: =IF($X$2=0,(G14*1000000+U14*1000+A14),(O14*1000000+U14*1000+A14)) -> 11 | W14: =_xlfn.RANK.EQ(V14,$V$4:$V$27,0) -> 14
A15: 12 | G15: =SUM(C15:E15) -> 0 | H15: =G15/4 -> 0 | I15: =IF(B15="","",IFERROR(INDEX('회원명단 및 기준에버'!D:G,MATCH(B15,'회원명단 및 기준에버'!$C:$C,0),CHOOSE(INT((MONTH($N$2)-1)/3)+1,1,2,3,4)),"")) | J15: =IFERROR(C15+-I15,0) -> 0 | K15: =IFERROR(D15+-I15,0) -> 0 | L15: =IFERROR(E15+-I15,0) -> 0 | M15: =IFERROR(F15+-I15,0) -> 0 | N15: =SUM(J15:M15) -> 0 | O15: =IFERROR(H15+-I15,0) -> 0 | U15: =MAX(C15:F15)-MIN(C15:F15) -> 0 | V15: =IF($X$2=0,(G15*1000000+U15*1000+A15),(O15*1000000+U15*1000+A15)) -> 12 | W15: =_xlfn.RANK.EQ(V15,$V$4:$V$27,0) -> 13
A16: 13 | G16: =SUM(C16:E16) -> 0 | H16: =G16/4 -> 0 | I16: =IF(B16="","",IFERROR(INDEX('회원명단 및 기준에버'!D:G,MATCH(B16,'회원명단 및 기준에버'!$C:$C,0),CHOOSE(INT((MONTH($N$2)-1)/3)+1,1,2,3,4)),"")) | J16: =IFERROR(C16+-I16,0) -> 0 | K16: =IFERROR(D16+-I16,0) -> 0 | L16: =IFERROR(E16+-I16,0) -> 0 | M16: =IFERROR(F16+-I16,0) -> 0 | N16: =SUM(J16:M16) -> 0 | O16: =IFERROR(H16+-I16,0) -> 0 | U16: =MAX(C16:F16)-MIN(C16:F16) -> 0 | V16: =IF($X$2=0,(G16*1000000+U16*1000+A16),(O16*1000000+U16*1000+A16)) -> 13 | W16: =_xlfn.RANK.EQ(V16,$V$4:$V$27,0) -> 12
A17: 14 | G17: =SUM(C17:E17) -> 0 | H17: =G17/4 -> 0 | I17: =IF(B17="","",IFERROR(INDEX('회원명단 및 기준에버'!D:G,MATCH(B17,'회원명단 및 기준에버'!$C:$C,0),CHOOSE(INT((MONTH($N$2)-1)/3)+1,1,2,3,4)),"")) | J17: =IFERROR(C17+-I17,0) -> 0 | K17: =IFERROR(D17+-I17,0) -> 0 | L17: =IFERROR(E17+-I17,0) -> 0 | M17: =IFERROR(F17+-I17,0) -> 0 | N17: =SUM(J17:M17) -> 0 | O17: =IFERROR(H17+-I17,0) -> 0 | U17: =MAX(C17:F17)-MIN(C17:F17) -> 0 | V17: =IF($X$2=0,(G17*1000000+U17*1000+A17),(O17*1000000+U17*1000+A17)) -> 14 | W17: =_xlfn.RANK.EQ(V17,$V$4:$V$27,0) -> 11
A18: 15 | G18: =SUM(C18:E18) -> 0 | H18: =G18/4 -> 0 | I18: =IF(B18="","",IFERROR(INDEX('회원명단 및 기준에버'!D:G,MATCH(B18,'회원명단 및 기준에버'!$C:$C,0),CHOOSE(INT((MONTH($N$2)-1)/3)+1,1,2,3,4)),"")) | J18: =IFERROR(C18+-I18,0) -> 0 | K18: =IFERROR(D18+-I18,0) -> 0 | L18: =IFERROR(E18+-I18,0) -> 0 | M18: =IFERROR(F18+-I18,0) -> 0 | N18: =SUM(J18:M18) -> 0 | O18: =IFERROR(H18+-I18,0) -> 0 | U18: =MAX(C18:F18)-MIN(C18:F18) -> 0 | V18: =IF($X$2=0,(G18*1000000+U18*1000+A18),(O18*1000000+U18*1000+A18)) -> 15 | W18: =_xlfn.RANK.EQ(V18,$V$4:$V$27,0) -> 10
A19: 16 | G19: =SUM(C19:E19) -> 0 | H19: =G19/4 -> 0 | I19: =IF(B19="","",IFERROR(INDEX('회원명단 및 기준에버'!D:G,MATCH(B19,'회원명단 및 기준에버'!$C:$C,0),CHOOSE(INT((MONTH($N$2)-1)/3)+1,1,2,3,4)),"")) | J19: =IFERROR(C19+-I19,0) -> 0 | K19: =IFERROR(D19+-I19,0) -> 0 | L19: =IFERROR(E19+-I19,0) -> 0 | M19: =IFERROR(F19+-I19,0) -> 0 | N19: =SUM(J19:M19) -> 0 | O19: =IFERROR(H19+-I19,0) -> 0 | U19: =MAX(C19:F19)-MIN(C19:F19) -> 0 | V19: =IF($X$2=0,(G19*1000000+U19*1000+A19),(O19*1000000+U19*1000+A19)) -> 16 | W19: =_xlfn.RANK.EQ(V19,$V$4:$V$27,0) -> 9
... A27: 24 | G27: =SUM(C27:E27) -> 0 | H27: =G27/4 -> 0 | I27: =IF(B27="","",IFERROR(INDEX('회원명단 및 기준에버'!D:G,MATCH(B27,'회원명단 및 기준에버'!$C:$C,0),CHOOSE(INT((MONTH($N$2)-1)/3)+1,1,2,3,4)),"")) | J27: =IFERROR(C27+-I27,0) -> 0 | K27: =IFERROR(D27+-I27,0) -> 0 | L27: =IFERROR(E27+-I27,0) -> 0 | M27: =IFERROR(F27+-I27,0) -> 0 | N27: =SUM(J27:M27) -> 0 | O27: =IFERROR(H27+-I27,0) -> 0 | U27: =MAX(C27:F27)-MIN(C27:F27) -> 0 | V27: =IF($X$2=0,(G27*1000000+U27*1000+A27),(O27*1000000+U27*1000+A27)) -> 24 | W27: =_xlfn.RANK.EQ(V27,$V$4:$V$27,0) -> 1
B28: 팀 전
B29: =$B4 -> 0 | C29: =IF($V$2=0,$C4,$J4) -> 0 | D29: =IF($V$2=0,$D4,$K4) -> 0 | E29: =IF($V$2=0,$E4,$L4) -> 0 | F29: =IF($V$2=0,$F4,$M4) -> 0 | G29: =E33+D33+C33+F33 -> 0 | I29: =$B8 -> 0 | J29: =IF($V$2=0,$C8,$J8) -> 0 | K29: =IF($V$2=0,$D8,$K8) -> 0 | L29: =IF($V$2=0,$E8,$L8) -> 0 | M29: =IF($V$2=0,$F8,$M8) -> 0 | N29: =L33+K33+J33+M33 -> 0
B30: =$B5 -> 0 | C30: =IF($V$2=0,$C5,$J5) -> 0 | D30: =IF($V$2=0,$D5,$K5) -> 0 | E30: =IF($V$2=0,$E5,$L5) -> 0 | F30: =IF($V$2=0,$F5,$M5) -> 0 | I30: =$B9 -> 0 | J30: =IF($V$2=0,$C9,$J9) -> 0 | K30: =IF($V$2=0,$D9,$K9) -> 0 | L30: =IF($V$2=0,$E9,$L9) -> 0 | M30: =IF($V$2=0,$F9,$M9) -> 0
B31: =$B6 -> 0 | C31: =IF($V$2=0,$C6,$J6) -> 0 | D31: =IF($V$2=0,$D6,$K6) -> 0 | E31: =IF($V$2=0,$E6,$L6) -> 0 | F31: =IF($V$2=0,$F6,$M6) -> 0 | I31: =$B10 -> 0 | J31: =IF($V$2=0,$C10,$J10) -> 0 | K31: =IF($V$2=0,$D10,$K10) -> 0 | L31: =IF($V$2=0,$E10,$L10) -> 0 | M31: =IF($V$2=0,$F10,$M10) -> 0
B32: =$B7 -> 0 | C32: =IF($V$2=0,$C7,$J7) -> 0 | D32: =IF($V$2=0,$D7,$K7) -> 0 | E32: =IF($V$2=0,$E7,$L7) -> 0 | F32: =IF($V$2=0,$F7,$M7) -> 0 | I32: =$B11 -> 0 | J32: =IF($V$2=0,$C11,$J11) -> 0 | K32: =IF($V$2=0,$D11,$K11) -> 0 | L32: =IF($V$2=0,$E11,$L11) -> 0 | M32: =IF($V$2=0,$F11,$M11) -> 0
C33: =SUM(C29:C32) -> 0 | D33: =SUM(D29:D32) -> 0 | E33: =SUM(E29:E32) -> 0 | F33: =SUM(F29:F32) -> 0 | J33: =SUM(J29:J32) -> 0 | K33: =SUM(K29:K32) -> 0 | L33: =SUM(L29:L32) -> 0 | M33: =SUM(M29:M32) -> 0
B35: =$B12 -> 0 | C35: =IF($V$2=0,$C12,$J12) -> 0 | D35: =IF($V$2=0,$D12,$K12) -> 0 | E35: =IF($V$2=0,$E12,$L12) -> 0 | F35: =IF($V$2=0,$F12,$M12) -> 0 | G35: =E39+D39+C39+F39 -> 0 | I35: =$B16 -> 0 | J35: =IF($V$2=0,$C16,$J16) -> 0 | K35: =IF($V$2=0,$D16,$K16) -> 0 | L35: =IF($V$2=0,$E16,$L16) -> 0 | M35: =IF($V$2=0,$F16,$M16) -> 0 | N35: =L39+K39+J39+M39 -> 0
B36: =$B13 -> 0 | C36: =IF($V$2=0,$C13,$J13) -> 0 | D36: =IF($V$2=0,$D13,$K13) -> 0 | E36: =IF($V$2=0,$E13,$L13) -> 0 | F36: =IF($V$2=0,$F13,$M13) -> 0 | I36: =$B17 -> 0 | J36: =IF($V$2=0,$C17,$J17) -> 0 | K36: =IF($V$2=0,$D17,$K17) -> 0 | L36: =IF($V$2=0,$E17,$L17) -> 0 | M36: =IF($V$2=0,$F17,$M17) -> 0
B37: =$B14 -> 0 | C37: =IF($V$2=0,$C14,$J14) -> 0 | D37: =IF($V$2=0,$D14,$K14) -> 0 | E37: =IF($V$2=0,$E14,$L14) -> 0 | F37: =IF($V$2=0,$F14,$M14) -> 0 | I37: =$B18 -> 0 | J37: =IF($V$2=0,$C18,$J18) -> 0 | K37: =IF($V$2=0,$D18,$K18) -> 0 | L37: =IF($V$2=0,$E18,$L18) -> 0 | M37: =IF($V$2=0,$F18,$M18) -> 0
B38: =$B15 -> 0 | C38: =IF($V$2=0,$C15,$J15) -> 0 | D38: =IF($V$2=0,$D15,$K15) -> 0 | E38: =IF($V$2=0,$E15,$L15) -> 0 | F38: =IF($V$2=0,$F15,$M15) -> 0 | I38: =$B19 -> 0 | J38: =IF($V$2=0,$C19,$J19) -> 0 | K38: =IF($V$2=0,$D19,$K19) -> 0 | L38: =IF($V$2=0,$E19,$L19) -> 0 | M38: =IF($V$2=0,$F19,$M19) -> 0
C39: =SUM(C35:C38) -> 0 | D39: =SUM(D35:D38) -> 0 | E39: =SUM(E35:E38) -> 0 | F39: =SUM(F35:F38) -> 0 | J39: =SUM(J35:J38) -> 0 | K39: =SUM(K35:K38) -> 0 | L39: =SUM(L35:L38) -> 0 | M39: =SUM(M35:M38) -> 0
B41: =$B20 -> 0 | C41: =IF($V$2=0,$C20,$J20) -> 0 | D41: =IF($V$2=0,$D20,$K20) -> 0 | E41: =IF($V$2=0,$E20,$L20) -> 0 | F41: =IF($V$2=0,$F20,$M20) -> 0 | G41: =E45+D45+C45+F45 -> 0 | I41: =$B24 -> 0 | J41: =IF($V$2=0,$C24,$J24) -> 0 | K41: =IF($V$2=0,$D24,$K24) -> 0 | L41: =IF($V$2=0,$E24,$L24) -> 0 | M41: =IF($V$2=0,$F24,$M24) -> 0 | N41: =L45+K45+J45+M45 -> 0
B42: =$B21 -> 0 | C42: =IF($V$2=0,$C21,$J21) -> 0 | D42: =IF($V$2=0,$D21,$K21) -> 0 | E42: =IF($V$2=0,$E21,$L21) -> 0 | F42: =IF($V$2=0,$F21,$M21) -> 0 | I42: =$B25 -> 0 | J42: =IF($V$2=0,$C25,$J25) -> 0 | K42: =IF($V$2=0,$D25,$K25) -> 0 | L42: =IF($V$2=0,$E25,$L25) -> 0 | M42: =IF($V$2=0,$F25,$M25) -> 0
B43: =$B22 -> 0 | C43: =IF($V$2=0,$C22,$J22) -> 0 | D43: =IF($V$2=0,$D22,$K22) -> 0 | E43: =IF($V$2=0,$E22,$L22) -> 0 | F43: =IF($V$2=0,$F22,$M22) -> 0 | I43: =$B26 -> 0 | J43: =IF($V$2=0,$C26,$J26) -> 0 | K43: =IF($V$2=0,$D26,$K26) -> 0 | L43: =IF($V$2=0,$E26,$L26) -> 0 | M43: =IF($V$2=0,$F26,$M26) -> 0
B44: =$B23 -> 0 | C44: =IF($V$2=0,$C23,$J23) -> 0 | D44: =IF($V$2=0,$D23,$K23) -> 0 | E44: =IF($V$2=0,$E23,$L23) -> 0 | F44: =IF($V$2=0,$F23,$M23) -> 0 | I44: =$B27 -> 0 | J44: =IF($V$2=0,$C27,$J27) -> 0 | K44: =IF($V$2=0,$D27,$K27) -> 0 | L44: =IF($V$2=0,$E27,$L27) -> 0 | M44: =IF($V$2=0,$F27,$M27) -> 0
C45: =SUM(C41:C44) -> 0 | D45: =SUM(D41:D44) -> 0 | E45: =SUM(E41:E44) -> 0 | F45: =SUM(F41:F44) -> 0 | J45: =SUM(J41:J44) -> 0 | K45: =SUM(K41:K44) -> 0 | L45: =SUM(L41:L44) -> 0 | M45: =SUM(M41:M44) -> 0
A48: =A1 -> 2026 아르케 존 00회 정기 번개 점수
L49: 날짜 | N49: =N2 -> 46113
B50: 이 름 | C50: 1 G | D50: 2 G | E50: 3 G | F50: 4G | G50: 합 계 | H50: 에 버 | I50: 기본에버 | J50: 1 G | K50: 2 G | L50: 3 G | M50: 4G | N50: 합 계 | O50: 오 차
A51: 1 | B51: {=INDEX($B$4:$O$27,MATCH($A51,$W$4:$W$27,0),COLUMN(A$1))} -> 0 | C51: {=INDEX($B$4:$O$27,MATCH($A51,$W$4:$W$27,0),COLUMN(B$1))} -> 0 | D51: {=INDEX($B$4:$O$27,MATCH($A51,$W$4:$W$27,0),COLUMN(C$1))} -> 0 | E51: {=INDEX($B$4:$O$27,MATCH($A51,$W$4:$W$27,0),COLUMN(D$1))} -> 0 | F51: {=INDEX($B$4:$O$27,MATCH($A51,$W$4:$W$27,0),COLUMN(E$1))} -> 0 | G51: =SUM(C51:F51) -> 0 | H51: =G51/4 -> 0 | I51: =IF(B51="","",IFERROR(INDEX('회원명단 및 기준에버'!D:G,MATCH(B51,'회원명단 및 기준에버'!$C:$C,0),CHOOSE(INT((MONTH($N$2)-1)/3)+1,1,2,3,4)),"")) | J51: =IFERROR(C51+-I51,0) -> 0 | K51: =IFERROR(D51+-I51,0) -> 0 | L51: =IFERROR(E51+-I51,0) -> 0 | M51: =IFERROR(F51+-I51,0) -> 0 | N51: =SUM(J51:M51) -> 0 | O51: =IFERROR(H51+-I51,0) -> 0
...

Sheet 07회번개
A1: 2026 아르케 존 07회 번개 모임 점수
L2: 날짜 | N2: 46121 | U2: 팀전에버기준 | V2: 1 | W2: 순위에버오차기준 | X2: 1
B3: 이 름 | C3: 1 G | D3: 2 G | E3: 3 G | F3: 4G | G3: 합 계 | H3: 에 버 | I3: 기본에버 | J3: 1 G | K3: 2 G | L3: 3 G | M3: 4G | N3: 합 계 | O3: 오 차 | U3: 수식입력부분 삭제하지마세요~
A4: 1 | B4: 장 영 민 | C4: 223 | D4: 149 | E4: 189 | F4: 225 | G4: =F4+E4+D4+C4 -> 786 | H4: =G4/4 -> 196.5 | I4: =IF(B4="","",IFERROR(INDEX('회원명단 및 기준에버'!D:G,MATCH(B4,'회원명단 및 기준에버'!$C:$C,0),CHOOSE(INT((MONTH($N$2)-1)/3)+1,1,2,3,4)),"")) -> 200 | J4: =IFERROR(C4+-I4,0) -> 23 | K4: =IFERROR(D4+-I4,0) -> -51 | L4: =IFERROR(E4+-I4,0) -> -11 | M4: =IFERROR(F4+-I4,0) -> 25 | N4: =SUM(J4:M4) -> -14 | O4: =IFERROR(H4+-I4,0) -> -3.5 | U4: =MAX(C4:F4)-MIN(C4:F4) -> 76 | V4: =IF($X$2=0,(G4*1000000+U4*1000+A4),(O4*1000000+U4*1000+A4)) -> -3423999 | W4: =_xlfn.RANK.EQ(V4,$V$4:$V$28,0) -> 12
A5: 2 | B5: 김 정 희 | C5: 199 | D5: 198 | E5: 202 | F5: 0 | G5: =F5+E5+D5+C5 -> 599 | H5: =G5/3 -> 199.66667 | I5: =IF(B5="","",IFERROR(INDEX('회원명단 및 기준에버'!D:G,MATCH(B5,'회원명단 및 기준에버'!$C:$C,0),CHOOSE(INT((MONTH($N$2)-1)/3)+1,1,2,3,4)),"")) -> 200 | J5: =IFERROR(C5+-I5,0) -> -1 | K5: =IFERROR(D5+-I5,0) -> -2 | L5: =IFERROR(E5+-I5,0) -> 2 | M5: 0 | N5: =SUM(J5:M5) -> -1 | O5: =IFERROR(H5+-I5,0) -> -0.33333333 | U5: =MAX(C5:F5)-MIN(C5:F5) -> 202 | V5: =IF($X$2=0,(G5*1000000+U5*1000+A5),(O5*1000000+U5*1000+A5)) -> -131331.33 | W5: =_xlfn.RANK.EQ(V5,$V$4:$V$28,0) -> 9
A6: 3 | B6: 황 인 교 | C6: 221 | D6: 190 | E6: 183 | F6: 199 | G6: =F6+E6+D6+C6 -> 793 | H6: =G6/4 -> 198.25 | I6: =IF(B6="","",IFERROR(INDEX('회원명단 및 기준에버'!D:G,MATCH(B6,'회원명단 및 기준에버'!$C:$C,0),CHOOSE(INT((MONTH($N$2)-1)/3)+1,1,2,3,4)),"")) -> 184 | J6: =IFERROR(C6+-I6,0) -> 37 | K6: =IFERROR(D6+-I6,0) -> 6 | L6: =IFERROR(E6+-I6,0) -> -1 | M6: =IFERROR(F6+-I6,0) -> 15 | N6: =SUM(J6:M6) -> 57 | O6: =IFERROR(H6+-I6,0) -> 14.25 | U6: =MAX(C6:F6)-MIN(C6:F6) -> 38 | V6: =IF($X$2=0,(G6*1000000+U6*1000+A6),(O6*1000000+U6*1000+A6)) -> 14288003 | W6: =_xlfn.RANK.EQ(V6,$V$4:$V$28,0) -> 3
A7: 4 | B7: 천 성 일 | C7: 190 | D7: 197 | E7: 217 | F7: 212 | G7: =F7+E7+D7+C7 -> 816 | H7: =G7/4 -> 204 | I7: =IF(B7="","",IFERROR(INDEX('회원명단 및 기준에버'!D:G,MATCH(B7,'회원명단 및 기준에버'!$C:$C,0),CHOOSE(INT((MONTH($N$2)-1)/3)+1,1,2,3,4)),"")) -> 191 | J7: =IFERROR(C7+-I7,0) -> -1 | K7: =IFERROR(D7+-I7,0) -> 6 | L7: =IFERROR(E7+-I7,0) -> 26 | M7: =IFERROR(F7+-I7,0) -> 21 | N7: =SUM(J7:M7) -> 52 | O7: =IFERROR(H7+-I7,0) -> 13 | U7: =MAX(C7:F7)-MIN(C7:F7) -> 27 | V7: =IF($X$2=0,(G7*1000000+U7*1000+A7),(O7*1000000+U7*1000+A7)) -> 13027004 | W7: =_xlfn.RANK.EQ(V7,$V$4:$V$28,0) -> 4
A8: 5 | B8: 김 미 란 | C8: 180 | D8: 156 | E8: 223 | F8: 159 | G8: =F8+E8+D8+C8 -> 718 | H8: =G8/4 -> 179.5 | I8: =IF(B8="","",IFERROR(INDEX('회원명단 및 기준에버'!D:G,MATCH(B8,'회원명단 및 기준에버'!$C:$C,0),CHOOSE(INT((MONTH($N$2)-1)/3)+1,1,2,3,4)),"")) -> 183 | J8: =IFERROR(C8+-I8,0) -> -3 | K8: =IFERROR(D8+-I8,0) -> -27 | L8: =IFERROR(E8+-I8,0) -> 40 | M8: =IFERROR(F8+-I8,0) -> -24 | N8: =SUM(J8:M8) -> -14 | O8: =IFERROR(H8+-I8,0) -> -3.5 | U8: =MAX(C8:F8)-MIN(C8:F8) -> 67 | V8: =IF($X$2=0,(G8*1000000+U8*1000+A8),(O8*1000000+U8*1000+A8)) -> -3432995 | W8: =_xlfn.RANK.EQ(V8,$V$4:$V$28,0) -> 14
A9: 6 | B9: 최 현 수 | C9: 256 | D9: 226 | E9: 192 | F9: 211 | G9: =F9+E9+D9+C9 -> 885 | H9: =G9/4 -> 221.25 | I9: =IF(B9="","",IFERROR(INDEX('회원명단 및 기준에버'!D:G,MATCH(B9,'회원명단 및 기준에버'!$C:$C,0),CHOOSE(INT((MONTH($N$2)-1)/3)+1,1,2,3,4)),"")) -> 200 | J9: =IFERROR(C9+-I9,0) -> 56 | K9: =IFERROR(D9+-I9,0) -> 26 | L9: =IFERROR(E9+-I9,0) -> -8 | M9: =IFERROR(F9+-I9,0) -> 11 | N9: =SUM(J9:M9) -> 85 | O9: =IFERROR(H9+-I9,0) -> 21.25 | U9: =MAX(C9:F9)-MIN(C9:F9) -> 64 | V9: =IF($X$2=0,(G9*1000000+U9*1000+A9),(O9*1000000+U9*1000+A9)) -> 21314006 | W9: =_xlfn.RANK.EQ(V9,$V$4:$V$28,0) -> 2
A10: 7 | B10: 이 승 미 | C10: 167 | D10: 163 | E10: 182 | F10: 160 | G10: =F10+E10+D10+C10 -> 672 | H10: =G10/4 -> 168 | I10: =IF(B10="","",IFERROR(INDEX('회원명단 및 기준에버'!D:G,MATCH(B10,'회원명단 및 기준에버'!$C:$C,0),CHOOSE(INT((MONTH($N$2)-1)/3)+1,1,2,3,4)),"")) -> 165 | J10: =IFERROR(C10+-I10,0) -> 2 | K10: =IFERROR(D10+-I10,0) -> -2 | L10: =IFERROR(E10+-I10,0) -> 17 | M10: =IFERROR(F10+-I10,0) -> -5 | N10: =SUM(J10:M10) -> 12 | O10: =IFERROR(H10+-I10,0) -> 3 | U10: =MAX(C10:F10)-MIN(C10:F10) -> 22 | V10: =IF($X$2=0,(G10*1000000+U10*1000+A10),(O10*1000000+U10*1000+A10)) -> 3022007 | W10: =_xlfn.RANK.EQ(V10,$V$4:$V$28,0) -> 8
A11: 8 | B11: 박 성 현 | C11: 155 | D11: 257 | E11: 204 | F11: 178 | G11: =F11+E11+D11+C11 -> 794 | H11: =G11/4 -> 198.5 | I11: =IF(B11="","",IFERROR(INDEX('회원명단 및 기준에버'!D:G,MATCH(B11,'회원명단 및 기준에버'!$C:$C,0),CHOOSE(INT((MONTH($N$2)-1)/3)+1,1,2,3,4)),"")) -> 191 | J11: =IFERROR(C11+-I11,0) -> -36 | K11: =IFERROR(D11+-I11,0) -> 66 | L11: =IFERROR(E11+-I11,0) -> 13 | M11: =IFERROR(F11+-I11,0) -> -13 | N11: =SUM(J11:M11) -> 30 | O11: =IFERROR(H11+-I11,0) -> 7.5 | U11: =MAX(C11:F11)-MIN(C11:F11) -> 102 | V11: =IF($X$2=0,(G11*1000000+U11*1000+A11),(O11*1000000+U11*1000+A11)) -> 7602008 | W11: =_xlfn.RANK.EQ(V11,$V$4:$V$28,0) -> 5
A12: 9 | B12: 고 경 훈 | C12: 209 | D12: 192 | E12: 182 | F12: 192 | G12: =F12+E12+D12+C12 -> 775 | H12: =G12/4 -> 193.75 | I12: =IF(B12="","",IFERROR(INDEX('회원명단 및 기준에버'!D:G,MATCH(B12,'회원명단 및 기준에버'!$C:$C,0),CHOOSE(INT((MONTH($N$2)-1)/3)+1,1,2,3,4)),"")) -> 196 | J12: =IFERROR(C12+-I12,0) -> 13 | K12: =IFERROR(D12+-I12,0) -> -4 | L12: =IFERROR(E12+-I12,0) -> -14 | M12: =IFERROR(F12+-I12,0) -> -4 | N12: =SUM(J12:M12) -> -9 | O12: =IFERROR(H12+-I12,0) -> -2.25 | U12: =MAX(C12:F12)-MIN(C12:F12) -> 27 | V12: =IF($X$2=0,(G12*1000000+U12*1000+A12),(O12*1000000+U12*1000+A12)) -> -2222991 | W12: =_xlfn.RANK.EQ(V12,$V$4:$V$28,0) -> 11
A13: 10 | B13: 임 연 진 | C13: 203 | D13: 269 | E13: 226 | F13: 211 | G13: =F13+E13+D13+C13 -> 909 | H13: =G13/4 -> 227.25 | I13: =IF(B13="","",IFERROR(INDEX('회원명단 및 기준에버'!D:G,MATCH(B13,'회원명단 및 기준에버'!$C:$C,0),CHOOSE(INT((MONTH($N$2)-1)/3)+1,1,2,3,4)),"")) -> 200 | J13: =IFERROR(C13+-I13,0) -> 3 | K13: =IFERROR(D13+-I13,0) -> 69 | L13: =IFERROR(E13+-I13,0) -> 26 | M13: =IFERROR(F13+-I13,0) -> 11 | N13: =SUM(J13:M13) -> 109 | O13: =IFERROR(H13+-I13,0) -> 27.25 | U13: =MAX(C13:F13)-MIN(C13:F13) -> 66 | V13: =IF($X$2=0,(G13*1000000+U13*1000+A13),(O13*1000000+U13*1000+A13)) -> 27316010 | W13: =_xlfn.RANK.EQ(V13,$V$4:$V$28,0) -> 1
A14: 11 | B14: 이 대 용 | C14: 205 | D14: 253 | E14: 188 | F14: 168 | G14: =F14+E14+D14+C14 -> 814 | H14: =G14/4 -> 203.5 | I14: =IF(B14="","",IFERROR(INDEX('회원명단 및 기준에버'!D:G,MATCH(B14,'회원명단 및 기준에버'!$C:$C,0),CHOOSE(INT((MONTH($N$2)-1)/3)+1,1,2,3,4)),"")) -> 200 | J14: =IFERROR(C14+-I14,0) -> 5 | K14: =IFERROR(D14+-I14,0) -> 53 | L14: =IFERROR(E14+-I14,0) -> -12 | M14: =IFERROR(F14+-I14,0) -> -32 | N14: =SUM(J14:M14) -> 14 | O14: =IFERROR(H14+-I14,0) -> 3.5 | U14: =MAX(C14:F14)-MIN(C14:F14) -> 85 | V14: =IF($X$2=0,(G14*1000000+U14*1000+A14),(O14*1000000+U14*1000+A14)) -> 3585011 | W14: =_xlfn.RANK.EQ(V14,$V$4:$V$28,0) -> 7
A15: 12 | B15: 지 옥 명 | C15: 166 | D15: 143 | E15: 184 | F15: 131 | G15: =F15+E15+D15+C15 -> 624 | H15: =G15/4 -> 156 | I15: =IF(B15="","",IFERROR(INDEX('회원명단 및 기준에버'!D:G,MATCH(B15,'회원명단 및 기준에버'!$C:$C,0),CHOOSE(INT((MONTH($N$2)-1)/3)+1,1,2,3,4)),"")) -> 177 | J15: =IFERROR(C15+-I15,0) -> -11 | K15: =IFERROR(D15+-I15,0) -> -34 | L15: =IFERROR(E15+-I15,0) -> 7 | M15: =IFERROR(F15+-I15,0) -> -46 | N15: =SUM(J15:M15) -> -84 | O15: =IFERROR(H15+-I15,0) -> -21 | U15: =MAX(C15:F15)-MIN(C15:F15) -> 53 | V15: =IF($X$2=0,(G15*1000000+U15*1000+A15),(O15*1000000+U15*1000+A15)) -> -20946988 | W15: =_xlfn.RANK.EQ(V15,$V$4:$V$28,0) -> 22
A16: 13 | B16: 정 영 우 | C16: 181 | D16: 191 | E16: 192 | F16: 169 | G16: =F16+E16+D16+C16 -> 733 | H16: =G16/4 -> 183.25 | I16: =IF(B16="","",IFERROR(INDEX('회원명단 및 기준에버'!D:G,MATCH(B16,'회원명단 및 기준에버'!$C:$C,0),CHOOSE(INT((MONTH($N$2)-1)/3)+1,1,2,3,4)),"")) -> 194 | J16: =IFERROR(C16+-I16,0) -> -13 | K16: =IFERROR(D16+-I16,0) -> -3 | L16: =IFERROR(E16+-I16,0) -> -2 | M16: =IFERROR(F16+-I16,0) -> -25 | N16: =SUM(J16:M16) -> -43 | O16: =IFERROR(H16+-I16,0) -> -10.75 | U16: =MAX(C16:F16)-MIN(C16:F16) -> 23 | V16: =IF($X$2=0,(G16*1000000+U16*1000+A16),(O16*1000000+U16*1000+A16)) -> -10726987 | W16: =_xlfn.RANK.EQ(V16,$V$4:$V$28,0) -> 16
A17: 14 | B17: 이 우 석 | C17: 187 | D17: 159 | E17: 191 | F17: 166 | G17: =F17+E17+D17+C17 -> 703 | H17: =G17/4 -> 175.75 | I17: =IF(B17="","",IFERROR(INDEX('회원명단 및 기준에버'!D:G,MATCH(B17,'회원명단 및 기준에버'!$C:$C,0),CHOOSE(INT((MONTH($N$2)-1)/3)+1,1,2,3,4)),"")) -> 199 | J17: =IFERROR(C17+-I17,0) -> -12 | K17: =IFERROR(D17+-I17,0) -> -40 | L17: =IFERROR(E17+-I17,0) -> -8 | M17: =IFERROR(F17+-I17,0) -> -33 | N17: =SUM(J17:M17) -> -93 | O17: =IFERROR(H17+-I17,0) -> -23.25 | U17: =MAX(C17:F17)-MIN(C17:F17) -> 32 | V17: =IF($X$2=0,(G17*1000000+U17*1000+A17),(O17*1000000+U17*1000+A17)) -> -23217986 | W17: =_xlfn.RANK.EQ(V17,$V$4:$V$28,0) -> 24
... A28: 25 | B28: 송 정 현 | C28: 144 | D28: 144 | E28: 215 | F28: 226 | G28: =F28+E28+D28+C28 -> 729 | H28: =G28/4 -> 182.25 | I28: =IF(B28="","",IFERROR(INDEX('회원명단 및 기준에버'!D:G,MATCH(B28,'회원명단 및 기준에버'!$C:$C,0),CHOOSE(INT((MONTH($N$2)-1)/3)+1,1,2,3,4)),"")) -> 200 | J28: =IFERROR(C28+-I28,0) -> -56 | K28: =IFERROR(D28+-I28,0) -> -56 | L28: =IFERROR(E28+-I28,0) -> 15 | M28: =IFERROR(F28+-I28,0) -> 26 | N28: =SUM(J28:M28) -> -71 | O28: =IFERROR(H28+-I28,0) -> -17.75 | U28: =MAX(C28:F28)-MIN(C28:F28) -> 82 | V28: =IF($X$2=0,(G28*1000000+U28*1000+A28),(O28*1000000+U28*1000+A28)) -> -17667975 | W28: =_xlfn.RANK.EQ(V28,$V$4:$V$28,0) -> 19
B29: 팀 전
B30: =$B4 -> 장 영 민 | C30: =IF($V$2=0,$C4,$J4) -> 23 | D30: =IF($V$2=0,$D4,$K4) -> -51 | E30: =IF($V$2=0,$E4,$L4) -> -11 | F30: =IF($V$2=0,$F4,$M4) -> 25 | G30: =E35+D35+C35+F35 -> 80 | H30: 2 | I30: =$B9 -> 최 현 수 | J30: =IF($V$2=0,$C9,$J9) -> 56 | K30: =IF($V$2=0,$D9,$K9) -> 26 | L30: =IF($V$2=0,$E9,$L9) -> -8 | M30: =IF($V$2=0,$F9,$M9) -> 11 | N30: =L35+K35+J35+M35 -> 227 | O30: 1
B31: =$B5 -> 김 정 희 | C31: =IF($V$2=0,$C5,$J5) -> -1 | D31: =IF($V$2=0,$D5,$K5) -> -2 | E31: =IF($V$2=0,$E5,$L5) -> 2 | F31: =IF($V$2=0,$F5,$M5) -> 0 | I31: =$B10 -> 이 승 미 | J31: =IF($V$2=0,$C10,$J10) -> 2 | K31: =IF($V$2=0,$D10,$K10) -> -2 | L31: =IF($V$2=0,$E10,$L10) -> 17 | M31: =IF($V$2=0,$F10,$M10) -> -5
B32: =$B6 -> 황 인 교 | C32: =IF($V$2=0,$C6,$J6) -> 37 | D32: =IF($V$2=0,$D6,$K6) -> 6 | E32: =IF($V$2=0,$E6,$L6) -> -1 | F32: =IF($V$2=0,$F6,$M6) -> 15 | I32: =$B11 -> 박 성 현 | J32: =IF($V$2=0,$C11,$J11) -> -36 | K32: =IF($V$2=0,$D11,$K11) -> 66 | L32: =IF($V$2=0,$E11,$L11) -> 13 | M32: =IF($V$2=0,$F11,$M11) -> -13
B33: =$B7 -> 천 성 일 | C33: =IF($V$2=0,$C7,$J7) -> -1 | D33: =IF($V$2=0,$D7,$K7) -> 6 | E33: =IF($V$2=0,$E7,$L7) -> 26 | F33: =IF($V$2=0,$F7,$M7) -> 21 | I33: =$B12 -> 고 경 훈 | J33: =IF($V$2=0,$C12,$J12) -> 13 | K33: =IF($V$2=0,$D12,$K12) -> -4 | L33: =IF($V$2=0,$E12,$L12) -> -14 | M33: =IF($V$2=0,$F12,$M12) -> -4
B34: =$B8 -> 김 미 란 | C34: =IF($V$2=0,$C8,$J8) -> -3 | D34: =IF($V$2=0,$D8,$K8) -> -27 | E34: =IF($V$2=0,$E8,$L8) -> 40 | F34: =IF($V$2=0,$F8,$M8) -> -24 | I34: =$B13 -> 임 연 진 | J34: =IF($V$2=0,$C13,$J13) -> 3 | K34: =IF($V$2=0,$D13,$K13) -> 69 | L34: =IF($V$2=0,$E13,$L13) -> 26 | M34: =IF($V$2=0,$F13,$M13) -> 11
C35: =SUM(C30:C34) -> 55 | D35: =SUM(D30:D34) -> -68 | E35: =SUM(E30:E34) -> 56 | F35: =SUM(F30:F34) -> 37 | J35: =SUM(J30:J34) -> 38 | K35: =SUM(K30:K34) -> 155 | L35: =SUM(L30:L34) -> 34 | M35: =SUM(M30:M34) -> 0
B37: =$B14 -> 이 대 용 | C37: =IF($V$2=0,$C14,$J14) -> 5 | D37: =IF($V$2=0,$D14,$K14) -> 53 | E37: =IF($V$2=0,$E14,$L14) -> -12 | F37: =IF($V$2=0,$F14,$M14) -> -32 | G37: =E42+D42+C42+F42 -> -280 | H37: 4 | I37: =$B19 -> 임 승 기 | J37: =IF($V$2=0,$C19,$J19) -> -2 | K37: =IF($V$2=0,$D19,$K19) -> 11 | L37: =IF($V$2=0,$E19,$L19) -> -26 | M37: =IF($V$2=0,$F19,$M19) -> 3 | N37: =L42+K42+J42+M42 -> -222 | O37: 3
B38: =$B15 -> 지 옥 명 | C38: =IF($V$2=0,$C15,$J15) -> -11 | D38: =IF($V$2=0,$D15,$K15) -> -34 | E38: =IF($V$2=0,$E15,$L15) -> 7 | F38: =IF($V$2=0,$F15,$M15) -> -46 | I38: =$B20 -> 김 규 희 | J38: =IF($V$2=0,$C20,$J20) -> 20 | K38: =IF($V$2=0,$D20,$K20) -> -20 | L38: =IF($V$2=0,$E20,$L20) -> -34 | M38: =IF($V$2=0,$F20,$M20) -> -47
B39: =$B16 -> 정 영 우 | C39: =IF($V$2=0,$C16,$J16) -> -13 | D39: =IF($V$2=0,$D16,$K16) -> -3 | E39: =IF($V$2=0,$E16,$L16) -> -2 | F39: =IF($V$2=0,$F16,$M16) -> -25 | I39: =$B21 -> 이 상 현 | J39: =IF($V$2=0,$C21,$J21) -> -12 | K39: =IF($V$2=0,$D21,$K21) -> -55 | L39: =IF($V$2=0,$E21,$L21) -> 2 | M39: =IF($V$2=0,$F21,$M21) -> -26
B40: =$B17 -> 이 우 석 | C40: =IF($V$2=0,$C17,$J17) -> -12 | D40: =IF($V$2=0,$D17,$K17) -> -40 | E40: =IF($V$2=0,$E17,$L17) -> -8 | F40: =IF($V$2=0,$F17,$M17) -> -33 | I40: =$B22 -> 이 범 수 | J40: =IF($V$2=0,$C22,$J22) -> -18 | K40: =IF($V$2=0,$D22,$K22) -> -20 | L40: =IF($V$2=0,$E22,$L22) -> 7 | M40: =IF($V$2=0,$F22,$M22) -> -21
B41: =$B18 -> 나 경 주 | C41: =IF($V$2=0,$C18,$J18) -> -1 | D41: =IF($V$2=0,$D18,$K18) -> -28 | E41: =IF($V$2=0,$E18,$L18) -> -29 | F41: =IF($V$2=0,$F18,$M18) -> -16 | I41: =$B23 -> 손 은 주 | J41: =IF($V$2=0,$C23,$J23) -> 29 | K41: =IF($V$2=0,$D23,$K23) -> -2 | L41: =IF($V$2=0,$E23,$L23) -> -23 | M41: =IF($V$2=0,$F23,$M23) -> 12
C42: =SUM(C37:C41) -> -32 | D42: =SUM(D37:D41) -> -52 | E42: =SUM(E37:E41) -> -44 | F42: =SUM(F37:F41) -> -152 | J42: =SUM(J37:J41) -> 17 | K42: =SUM(K37:K41) -> -86 | L42: =SUM(L37:L41) -> -74 | M42: =SUM(M37:M41) -> -79
B44: =$B24 -> 변 상 필 | C44: =IF($V$2=0,$C24,$J24) -> -22 | D44: =IF($V$2=0,$D24,$K24) -> -38 | E44: =IF($V$2=0,$E24,$L24) -> 37 | F44: =IF($V$2=0,$F24,$M24) -> 9 | G44: =E49+D49+C49+F49 -> -250 | H44: 5
B45: =$B25 -> 진 명 옥 | C45: =IF($V$2=0,$C25,$J25) -> -22 | D45: =IF($V$2=0,$D25,$K25) -> -34 | E45: =IF($V$2=0,$E25,$L25) -> 17 | F45: =IF($V$2=0,$F25,$M25) -> -25
B46: =$B26 -> 이 정 석 | C46: =IF($V$2=0,$C26,$J26) -> -21 | D46: =IF($V$2=0,$D26,$K26) -> 4 | E46: =IF($V$2=0,$E26,$L26) -> 1 | F46: =IF($V$2=0,$F26,$M26) -> 12
B47: =$B27 -> 김 태 환 | C47: =IF($V$2=0,$C27,$J27) -> -38 | D47: =IF($V$2=0,$D27,$K27) -> -26 | E47: =IF($V$2=0,$E27,$L27) -> -5 | F47: =IF($V$2=0,$F27,$M27) -> -28
B48: =$B28 -> 송 정 현 | C48: =IF($V$2=0,$C28,$J28) -> -56 | D48: =IF($V$2=0,$D28,$K28) -> -56 | E48: =IF($V$2=0,$E28,$L28) -> 15 | F48: =IF($V$2=0,$F28,$M28) -> 26
C49: =SUM(C44:C48) -> -159 | D49: =SUM(D44:D48) -> -150 | E49: =SUM(E44:E48) -> 65 | F49: =SUM(F44:F48) -> -6
A53: =A1 -> 2026 아르케 존 07회 번개 모임 점수
L54: 날짜 | N54: =N2 -> 46121
B55: 이 름 | C55: 1 G | D55: 2 G | E55: 3 G | F55: 4G | G55: 합 계 | H55: 에 버 | I55: 기본에버 | J55: 1 G | K55: 2 G | L55: 3 G | M55: 4G | N55: 합 계 | O55: 오 차
...

Sheet 06회번개
A1: 2026 아르케 존 06회 번개 모임 점수
L2: 날짜 | N2: 46107 | U2: 팀전에버기준 | V2: 0 | W2: 순위에버오차기준 | X2: 1
B3: 이 름 | C3: 1 G | D3: 2 G | E3: 3 G | F3: 4G | G3: 합 계 | H3: 에 버 | I3: 기본에버 | J3: 1 G | K3: 2 G | L3: 3 G | M3: 4G | N3: 합 계 | O3: 오 차 | U3: 수식입력부분 삭제하지마세요~
A4: 1 | B4: 장 영 민 | C4: 147 | D4: 141 | E4: 201 | F4: 192 | G4: =F4+E4+D4+C4 -> 681 | H4: =G4/4 -> 170.25 | I4: =IF(B4="","",IFERROR(INDEX('회원명단 및 기준에버'!D:G,MATCH(B4,'회원명단 및 기준에버'!$C:$C,0),CHOOSE(INT((MONTH($N$2)-1)/3)+1,1,2,3,4)),"")) -> 200 | J4: =IFERROR(C4+-I4,0) -> -53 | K4: =IFERROR(D4+-I4,0) -> -59 | L4: =IFERROR(E4+-I4,0) -> 1 | M4: =IFERROR(F4+-I4,0) -> -8 | N4: =SUM(J4:M4) -> -119 | O4: =IFERROR(H4+-I4,0) -> -29.75 | U4: =MAX(C4:F4)-MIN(C4:F4) -> 60 | V4: =IF($X$2=0,(G4*1000000+U4*1000+A4),(O4*1000000+U4*1000+A4)) -> -29689999 | W4: =_xlfn.RANK.EQ(V4,$V$4:$V$28,0) -> 25
A5: 2 | B5: 김 정 희 | C5: 236 | D5: 202 | E5: 199 | F5: 151 | G5: =F5+E5+D5+C5 -> 788 | H5: =G5/4 -> 197 | I5: =IF(B5="","",IFERROR(INDEX('회원명단 및 기준에버'!D:G,MATCH(B5,'회원명단 및 기준에버'!$C:$C,0),CHOOSE(INT((MONTH($N$2)-1)/3)+1,1,2,3,4)),"")) -> 200 | J5: =IFERROR(C5+-I5,0) -> 36 | K5: =IFERROR(D5+-I5,0) -> 2 | L5: =IFERROR(E5+-I5,0) -> -1 | M5: =IFERROR(F5+-I5,0) -> -49 | N5: =SUM(J5:M5) -> -12 | O5: =IFERROR(H5+-I5,0) -> -3 | U5: =MAX(C5:F5)-MIN(C5:F5) -> 85 | V5: =IF($X$2=0,(G5*1000000+U5*1000+A5),(O5*1000000+U5*1000+A5)) -> -2914998 | W5: =_xlfn.RANK.EQ(V5,$V$4:$V$28,0) -> 16
A6: 3 | B6: 이 재 용 | C6: 251 | D6: 200 | E6: 211 | F6: 171 | G6: =F6+E6+D6+C6 -> 833 | H6: =G6/4 -> 208.25 | I6: 190 | J6: =IFERROR(C6+-I6,0) -> 61 | K6: =IFERROR(D6+-I6,0) -> 10 | L6: =IFERROR(E6+-I6,0) -> 21 | M6: =IFERROR(F6+-I6,0) -> -19 | N6: =SUM(J6:M6) -> 73 | O6: =IFERROR(H6+-I6,0) -> 18.25 | U6: =MAX(C6:F6)-MIN(C6:F6) -> 80 | V6: =IF($X$2=0,(G6*1000000+U6*1000+A6),(O6*1000000+U6*1000+A6)) -> 18330003 | W6: =_xlfn.RANK.EQ(V6,$V$4:$V$28,0) -> 3
A7: 4 | B7: 천 성 일 | C7: 192 | D7: 162 | E7: 188 | F7: 181 | G7: =F7+E7+D7+C7 -> 723 | H7: =G7/4 -> 180.75 | I7: =IF(B7="","",IFERROR(INDEX('회원명단 및 기준에버'!D:G,MATCH(B7,'회원명단 및 기준에버'!$C:$C,0),CHOOSE(INT((MONTH($N$2)-1)/3)+1,1,2,3,4)),"")) -> 191 | J7: =IFERROR(C7+-I7,0) -> 1 | K7: =IFERROR(D7+-I7,0) -> -29 | L7: =IFERROR(E7+-I7,0) -> -3 | M7: =IFERROR(F7+-I7,0) -> -10 | N7: =SUM(J7:M7) -> -41 | O7: =IFERROR(H7+-I7,0) -> -10.25 | U7: =MAX(C7:F7)-MIN(C7:F7) -> 30 | V7: =IF($X$2=0,(G7*1000000+U7*1000+A7),(O7*1000000+U7*1000+A7)) -> -10219996 | W7: =_xlfn.RANK.EQ(V7,$V$4:$V$28,0) -> 18
A8: 5 | B8: 윤 주 | C8: 159 | D8: 151 | E8: 178 | F8: 149 | G8: =F8+E8+D8+C8 -> 637 | H8: =G8/4 -> 159.25 | I8: =IF(B8="","",IFERROR(INDEX('회원명단 및 기준에버'!D:G,MATCH(B8,'회원명단 및 기준에버'!$C:$C,0),CHOOSE(INT((MONTH($N$2)-1)/3)+1,1,2,3,4)),"")) | J8: =IFERROR(C8+-I8,0) -> 0 | K8: =IFERROR(D8+-I8,0) -> 0 | L8: =IFERROR(E8+-I8,0) -> 0 | M8: =IFERROR(F8+-I8,0) -> 0 | N8: =SUM(J8:M8) -> 0 | O8: =IFERROR(H8+-I8,0) -> 0 | U8: =MAX(C8:F8)-MIN(C8:F8) -> 29 | V8: =IF($X$2=0,(G8*1000000+U8*1000+A8),(O8*1000000+U8*1000+A8)) -> 29005 | W8: =_xlfn.RANK.EQ(V8,$V$4:$V$28,0) -> 13
A9: 6 | B9: 이 우 석 | C9: 159 | D9: 251 | E9: 187 | F9: 195 | G9: =F9+E9+D9+C9 -> 792 | H9: =G9/4 -> 198 | I9: =IF(B9="","",IFERROR(INDEX('회원명단 및 기준에버'!D:G,MATCH(B9,'회원명단 및 기준에버'!$C:$C,0),CHOOSE(INT((MONTH($N$2)-1)/3)+1,1,2,3,4)),"")) -> 200 | J9: =IFERROR(C9+-I9,0) -> -41 | K9: =IFERROR(D9+-I9,0) -> 51 | L9: =IFERROR(E9+-I9,0) -> -13 | M9: =IFERROR(F9+-I9,0) -> -5 | N9: =SUM(J9:M9) -> -8 | O9: =IFERROR(H9+-I9,0) -> -2 | U9: =MAX(C9:F9)-MIN(C9:F9) -> 92 | V9: =IF($X$2=0,(G9*1000000+U9*1000+A9),(O9*1000000+U9*1000+A9)) -> -1907994 | W9: =_xlfn.RANK.EQ(V9,$V$4:$V$28,0) -> 14
A10: 7 | B10: 이 승 미 | C10: 172 | D10: 182 | E10: 176 | F10: 170 | G10: =F10+E10+D10+C10 -> 700 | H10: =G10/4 -> 175 | I10: =IF(B10="","",IFERROR(INDEX('회원명단 및 기준에버'!D:G,MATCH(B10,'회원명단 및 기준에버'!$C:$C,0),CHOOSE(INT((MONTH($N$2)-1)/3)+1,1,2,3,4)),"")) -> 165 | J10: =IFERROR(C10+-I10,0) -> 7 | K10: =IFERROR(D10+-I10,0) -> 17 | L10: =IFERROR(E10+-I10,0) -> 11 | M10: =IFERROR(F10+-I10,0) -> 5 | N10: =SUM(J10:M10) -> 40 | O10: =IFERROR(H10+-I10,0) -> 10 | U10: =MAX(C10:F10)-MIN(C10:F10) -> 12 | V10: =IF($X$2=0,(G10*1000000+U10*1000+A10),(O10*1000000+U10*1000+A10)) -> 10012007 | W10: =_xlfn.RANK.EQ(V10,$V$4:$V$28,0) -> 8
A11: 8 | B11: 김 태 환 | C11: 190 | D11: 203 | E11: 253 | F11: 237 | G11: =F11+E11+D11+C11 -> 883 | H11: =G11/4 -> 220.75 | I11: =IF(B11="","",IFERROR(INDEX('회원명단 및 기준에버'!D:G,MATCH(B11,'회원명단 및 기준에버'!$C:$C,0),CHOOSE(INT((MONTH($N$2)-1)/3)+1,1,2,3,4)),"")) -> 198 | J11: =IFERROR(C11+-I11,0) -> -8 | K11: =IFERROR(D11+-I11,0) -> 5 | L11: =IFERROR(E11+-I11,0) -> 55 | M11: =IFERROR(F11+-I11,0) -> 39 | N11: =SUM(J11:M11) -> 91 | O11: =IFERROR(H11+-I11,0) -> 22.75 | U11: =MAX(C11:F11)-MIN(C11:F11) -> 63 | V11: =IF($X$2=0,(G11*1000000+U11*1000+A11),(O11*1000000+U11*1000+A11)) -> 22813008 | W11: =_xlfn.RANK.EQ(V11,$V$4:$V$28,0) -> 1
