Workbook

Sheet 회원명단 및 기준에버
B3: 기준 에버
B4: 순번 | C4: 이름 | D4: 1분기 | E4: 2분기 | F4: 3분기 | G4: 4분기
B5: 1 | C5: 최 현 수 | D5: 200 | E5: 200
B6: 2 | C6: 임 승 기 | D6: 200 | E6: 200
B7: 3 | C7: 이 범 수 | D7: 193 | E7: 200
B8: 4 | C8: 강 희 태 | D8: 200 | E8: 200
B9: 5 | C9: 박 시 진 | D9: 196 | E9: 200
B10: 6 | C10: 김 남 주 | D10: 195 | E10: 200
B11: 7 | C11: 장 영 민 | D11: 200 | E11: 200
B12: 8 | C12: 변 상 필 | D12: 200 | E12: 200
B13: 9 | C13: 임 연 진 | D13: 194 | E13: 200
B14: 10 | C14: 송 정 현 | D14: 187 | E14: 200
B15: 11 | C15: 김 정 희 | D15: 200 | E15: 200
B16: 12 | C16: 이 대 용 | D16: 200 | E16: 200
... B39: 35 | C39: 손 은 주 | D39: 151 | E39: 144
B40: 36 | C40: 채 윤 주
B41: 37
B42: 38

Sheet 00회정모 6인팀
A1: 2026 아르케 존 00회 정기 모임 점수
K2: 날짜 | L2: 46113 | S2: 팀전에버기준 | T2: 0 | U2: 순위에버오차기준 | V2: 0
B3: 이 름 | C3: 1 G | D3: 2 G | E3: 3 G | F3: 합 계 | G3: 에 버 | H3: 기본에버 | I3: 1 G | J3: 2 G | K3: 3 G | L3: 합 계 | M3: 오 차 | S3: 수식입력부분 삭제하지마세요~
A4: 1 | F4: =SUM(C4:E4) -> 0 | G4: =F4/3 -> 0 | H4: {=IF(B4="","",IFERROR(INDEX('회원명단 및 기준에버'!D:G,MATCH(B4,'회원명단 및 기준에버'!$C:$C,0),CHOOSE(INT((MONTH($L$2)-1)/3)+1,1,2,3,4)),""))} | I4: =IFERROR(C4+-H4,0) -> 0 | J4: =IFERROR(D4+-H4,0) -> 0 | K4: =IFERROR(E4+-H4,0) -> 0 | L4: =SUM(I4:K4) -> 0 | M4: =IFERROR(G4+-H4,0) -> 0 | S4: =MAX(C4:E4)-MIN(C4:E4) -> 0 | T4: =IF($B4="",-999999999+A4,IF($V$2=0,(F4*10000+S4*1000+A4),(M4*10000+S4*10+A4))) -> -999999998 | U4: =_xlfn.RANK.EQ(T4,$T$4:$T$33,0) -> 30
A5: 2 | F5: =SUM(C5:E5) -> 0 | G5: =F5/3 -> 0 | H5: {=IF(B5="","",IFERROR(INDEX('회원명단 및 기준에버'!D:G,MATCH(B5,'회원명단 및 기준에버'!$C:$C,0),CHOOSE(INT((MONTH($L$2)-1)/3)+1,1,2,3,4)),""))} | I5: =IFERROR(C5+-H5,0) -> 0 | J5: =IFERROR(D5+-H5,0) -> 0 | K5: =IFERROR(E5+-H5,0) -> 0 | L5: =SUM(I5:K5) -> 0 | M5: =IFERROR(G5+-H5,0) -> 0 | S5: =MAX(C5:E5)-MIN(C5:E5) -> 0 | T5: =IF($B5="",-999999999+A5,IF($V$2=0,(F5*10000+S5*1000+A5),(M5*10000+S5*10+A5))) -> -999999997 | U5: =_xlfn.RANK.EQ(T5,$T$4:$T$33,0) -> 29
A6: 3 | F6: =SUM(C6:E6) -> 0 | G6: =F6/3 -> 0 | H6: {=IF(B6="","",IFERROR(INDEX('회원명단 및 기준에버'!D:G,MATCH(B6,'회원명단 및 기준에버'!$C:$C,0),CHOOSE(INT((MONTH($L$2)-1)/3)+1,1,2,3,4)),""))} | I6: =IFERROR(C6+-H6,0) -> 0 | J6: =IFERROR(D6+-H6,0) -> 0 | K6: =IFERROR(E6+-H6,0) -> 0 | L6: =SUM(I6:K6) -> 0 | M6: =IFERROR(G6+-H6,0) -> 0 | S6: =MAX(C6:E6)-MIN(C6:E6) -> 0 | T6: =IF($B6="",-999999999+A6,IF($V$2=0,(F6*10000+S6*1000+A6),(M6*10000+S6*10+A6))) -> -999999996 | U6: =_xlfn.RANK.EQ(T6,$T$4:$T$33,0) -> 28
A7: 4 | F7: =SUM(C7:E7) -> 0 | G7: =F7/3 -> 0 | H7: {=IF(B7="","",IFERROR(INDEX('회원명단 및 기준에버'!D:G,MATCH(B7,'회원명단 및 기준에버'!$C:$C,0),CHOOSE(INT((MONTH($L$2)-1)/3)+1,1,2,3,4)),""))} | I7: =IFERROR(C7+-H7,0) -> 0 | J7: =IFERROR(D7+-H7,0) -> 0 | K7: =IFERROR(E7+-H7,0) -> 0 | L7: =SUM(I7:K7) -> 0 | M7: =IFERROR(G7+-H7,0) -> 0 | S7: =MAX(C7:E7)-MIN(C7:E7) -> 0 | T7: =IF($B7="",-999999999+A7,IF($V$2=0,(F7*10000+S7*1000+A7),(M7*10000+S7*10+A7))) -> -999999995 | U7: =_xlfn.RANK.EQ(T7,$T$4:$T$33,0) -> 27
A8: 5 | F8: =SUM(C8:E8) -> 0 | G8: =F8/3 -> 0 | H8: {=IF(B8="","",IFERROR(INDEX('회원명단 및 기준에버'!D:G,MATCH(B8,'회원명단 및 기준에버'!$C:$C,0),CHOOSE(INT((MONTH($L$2)-1)/3)+1,1,2,3,4)),""))} | I8: =IFERROR(C8+-H8,0) -> 0 | J8: =IFERROR(D8+-H8,0) -> 0 | K8: =IFERROR(E8+-H8,0) -> 0 | L8: =SUM(I8:K8) -> 0 | M8: =IFERROR(G8+-H8,0) -> 0 | S8: =MAX(C8:E8)-MIN(C8:E8) -> 0 | T8: =IF($B8="",-999999999+A8,IF($V$2=0,(F8*10000+S8*1000+A8),(M8*10000+S8*10+A8))) -> -999999994 | U8: =_xlfn.RANK.EQ(T8,$T$4:$T$33,0) -> 26
A9: 6 | F9: =SUM(C9:E9) -> 0 | G9: =F9/3 -> 0 | H9: {=IF(B9="","",IFERROR(INDEX('회원명단 및 기준에버'!D:G,MATCH(B9,'회원명단 및 기준에버'!$C:$C,0),CHOOSE(INT((MONTH($L$2)-1)/3)+1,1,2,3,4)),""))} | I9: =IFERROR(C9+-H9,0) -> 0 | J9: =IFERROR(D9+-H9,0) -> 0 | K9: =IFERROR(E9+-H9,0) -> 0 | L9: =SUM(I9:K9) -> 0 | M9: =IFERROR(G9+-H9,0) -> 0 | S9: =MAX(C9:E9)-MIN(C9:E9) -> 0 | T9: =IF($B9="",-999999999+A9,IF($V$2=0,(F9*10000+S9*1000+A9),(M9*10000+S9*10+A9))) -> -999999993 | U9: =_xlfn.RANK.EQ(T9,$T$4:$T$33,0) -> 25
A10: 7 | F10: =SUM(C10:E10) -> 0 | G10: =F10/3 -> 0 | H10: {=IF(B10="","",IFERROR(INDEX('회원명단 및 기준에버'!D:G,MATCH(B10,'회원명단 및 기준에버'!$C:$C,0),CHOOSE(INT((MONTH($L$2)-1)/3)+1,1,2,3,4)),""))} | I10: =IFERROR(C10+-H10,0) -> 0 | J10: =IFERROR(D10+-H10,0) -> 0 | K10: =IFERROR(E10+-H10,0) -> 0 | L10: =SUM(I10:K10) -> 0 | M10: =IFERROR(G10+-H10,0) -> 0 | S10: =MAX(C10:E10)-MIN(C10:E10) -> 0 | T10: =IF($B10="",-999999999+A10,IF($V$2=0,(F10*10000+S10*1000+A10),(M10*10000+S10*10+A10))) -> -999999992 | U10: =_xlfn.RANK.EQ(T10,$T$4:$T$33,0) -> 24
A11: 8 | F11: =SUM(C11:E11) -> 0 | G11: =F11/3 -> 0 | H11: {=IF(B11="","",IFERROR(INDEX('회원명단 및 기준에버'!D:G,MATCH(B11,'회원명단 및 기준에버'!$C:$C,0),CHOOSE(INT((MONTH($L$2)-1)/3)+1,1,2,3,4)),""))} | I11: =IFERROR(C11+-H11,0) -> 0 | J11: =IFERROR(D11+-H11,0) -> 0 | K11: =IFERROR(E11+-H11,0) -> 0 | L11: =SUM(I11:K11) -> 0 | M11: =IFERROR(G11+-H11,0) -> 0 | S11: =MAX(C11:E11)-MIN(C11:E11) -> 0 | T11: =IF($B11="",-999999999+A11,IF($V$2=0,(F11*10000+S11*1000+A11),(M11*10000+S11*10+A11))) -> -999999991 | U11: =_xlfn.RANK.EQ(T11,$T$4:$T$33,0) -> 23
A12: 9 | F12: =SUM(C12:E12) -> 0 | G12: =F12/3 -> 0 | H12: {=IF(B12="","",IFERROR(INDEX('회원명단 및 기준에버'!D:G,MATCH(B12,'회원명단 및 기준에버'!$C:$C,0),CHOOSE(INT((MONTH($L$2)-1)/3)+1,1,2,3,4)),""))} | I12: =IFERROR(C12+-H12,0) -> 0 | J12: =IFERROR(D12+-H12,0) -> 0 | K12: =IFERROR(E12+-H12,0) -> 0 | L12: =SUM(I12:K12) -> 0 | M12: =IFERROR(G12+-H12,0) -> 0 | S12: =MAX(C12:E12)-MIN(C12:E12) -> 0 | T12: =IF($B12="",-999999999+A12,IF($V$2=0,(F12*10000+S12*1000+A12),(M12*10000+S12*10+A12))) -> -999999990 | U12: =_xlfn.RANK.EQ(T12,$T$4:$T$33,0) -> 22
A13: 10 | F13: =SUM(C13:E13) -> 0 | G13: =F13/3 -> 0 | H13: {=IF(B13="","",IFERROR(INDEX('회원명단 및 기준에버'!D:G,MATCH(B13,'회원명단 및 기준에버'!$C:$C,0),CHOOSE(INT((MONTH($L$2)-1)/3)+1,1,2,3,4)),""))} | I13: =IFERROR(C13+-H13,0) -> 0 | J13: =IFERROR(D13+-H13,0) -> 0 | K13: =IFERROR(E13+-H13,0) -> 0 | L13: =SUM(I13:K13) -> 0 | M13: =IFERROR(G13+-H13,0) -> 0 | S13: =MAX(C13:E13)-MIN(C13:E13) -> 0 | T13: =IF($B13="",-999999999+A13,IF($V$2=0,(F13*10000+S13*1000+A13),(M13*10000+S13*10+A13))) -> -999999989 | U13: =_xlfn.RANK.EQ(T13,$T$4:$T$33,0) -> 21
A14: 11 | F14: =SUM(C14:E14) -> 0 | G14: =F14/3 -> 0 | H14: {=IF(B14="","",IFERROR(INDEX('회원명단 및 기준에버'!D:G,MATCH(B14,'회원명단 및 기준에버'!$C:$C,0),CHOOSE(INT((MONTH($L$2)-1)/3)+1,1,2,3,4)),""))} | I14: =IFERROR(C14+-H14,0) -> 0 | J14: =IFERROR(D14+-H14,0) -> 0 | K14: =IFERROR(E14+-H14,0) -> 0 | L14: =SUM(I14:K14) -> 0 | M14: =IFERROR(G14+-H14,0) -> 0 | S14: =MAX(C14:E14)-MIN(C14:E14) -> 0 | T14: =IF($B14="",-999999999+A14,IF($V$2=0,(F14*10000+S14*1000+A14),(M14*10000+S14*10+A14))) -> -999999988 | U14: =_xlfn.RANK.EQ(T14,$T$4:$T$33,0) -> 20
A15: 12 | F15: =SUM(C15:E15) -> 0 | G15: =F15/3 -> 0 | H15: {=IF(B15="","",IFERROR(INDEX('회원명단 및 기준에버'!D:G,MATCH(B15,'회원명단 및 기준에버'!$C:$C,0),CHOOSE(INT((MONTH($L$2)-1)/3)+1,1,2,3,4)),""))} | I15: =IFERROR(C15+-H15,0) -> 0 | J15: =IFERROR(D15+-H15,0) -> 0 | K15: =IFERROR(E15+-H15,0) -> 0 | L15: =SUM(I15:K15) -> 0 | M15: =IFERROR(G15+-H15,0) -> 0 | S15: =MAX(C15:E15)-MIN(C15:E15) -> 0 | T15: =IF($B15="",-999999999+A15,IF($V$2=0,(F15*10000+S15*1000+A15),(M15*10000+S15*10+A15))) -> -999999987 | U15: =_xlfn.RANK.EQ(T15,$T$4:$T$33,0) -> 19
... A33: 30 | F33: =SUM(C33:E33) -> 0 | G33: =F33/3 -> 0 | H33: {=IF(B33="","",IFERROR(INDEX('회원명단 및 기준에버'!D:G,MATCH(B33,'회원명단 및 기준에버'!$C:$C,0),CHOOSE(INT((MONTH($L$2)-1)/3)+1,1,2,3,4)),""))} | I33: =IFERROR(C33+-H33,0) -> 0 | J33: =IFERROR(D33+-H33,0) -> 0 | K33: =IFERROR(E33+-H33,0) -> 0 | L33: =SUM(I33:K33) -> 0 | M33: =IFERROR(G33+-H33,0) -> 0 | S33: =MAX(C33:E33)-MIN(C33:E33) -> 0 | T33: =IF($B33="",-999999999+A33,IF($V$2=0,(F33*10000+S33*1000+A33),(M33*10000+S33*10+A33))) -> -999999969 | U33: =_xlfn.RANK.EQ(T33,$T$4:$T$33,0) -> 1
B34: 시 상 및 벌 금
B35: 에버상승상 남+20점,여+10점 이상 상위1명 | F35: 에버벌금 | G35: 정기전 만 해당 함 | J35: 유니품 벌금(3.000원)
G36: 1점부터 2000원
B37: 올카바 상 | I37: 초구가터벌금1회1000원 | K37: 광 박 1회 2000원
B41: 팀 전
B42: =$B4 -> 0 | C42: =IF($T$2=0,$C4,$I4) -> 0 | D42: =IF($T$2=0,$D4,$J4) -> 0 | E42: =IF($T$2=0,$E4,$K4) -> 0 | F42: =E48+D48+C48 -> 0 | H42: =$B10 -> 0 | I42: =IF($T$2=0,$C10,$I10) -> 0 | J42: =IF($T$2=0,$D10,$J10) -> 0 | K42: =IF($T$2=0,$E10,$K10) -> 0 | L42: =K48+J48+I48 -> 0
B43: =$B5 -> 0 | C43: =IF($T$2=0,$C5,$I5) -> 0 | D43: =IF($T$2=0,$D5,$J5) -> 0 | E43: =IF($T$2=0,$E5,$K5) -> 0 | H43: =$B11 -> 0 | I43: =IF($T$2=0,$C11,$I11) -> 0 | J43: =IF($T$2=0,$D11,$J11) -> 0 | K43: =IF($T$2=0,$E11,$K11) -> 0
B44: =$B6 -> 0 | C44: =IF($T$2=0,$C6,$I6) -> 0 | D44: =IF($T$2=0,$D6,$J6) -> 0 | E44: =IF($T$2=0,$E6,$K6) -> 0 | H44: =$B12 -> 0 | I44: =IF($T$2=0,$C12,$I12) -> 0 | J44: =IF($T$2=0,$D12,$J12) -> 0 | K44: =IF($T$2=0,$E12,$K12) -> 0
B45: =$B7 -> 0 | C45: =IF($T$2=0,$C7,$I7) -> 0 | D45: =IF($T$2=0,$D7,$J7) -> 0 | E45: =IF($T$2=0,$E7,$K7) -> 0 | H45: =$B13 -> 0 | I45: =IF($T$2=0,$C13,$I13) -> 0 | J45: =IF($T$2=0,$D13,$J13) -> 0 | K45: =IF($T$2=0,$E13,$K13) -> 0
B46: =$B8 -> 0 | C46: =IF($T$2=0,$C8,$I8) -> 0 | D46: =IF($T$2=0,$D8,$J8) -> 0 | E46: =IF($T$2=0,$E8,$K8) -> 0 | H46: =$B14 -> 0 | I46: =IF($T$2=0,$C14,$I14) -> 0 | J46: =IF($T$2=0,$D14,$J14) -> 0 | K46: =IF($T$2=0,$E14,$K14) -> 0
B47: =$B9 -> 0 | C47: =IF($T$2=0,$C9,$I9) -> 0 | D47: =IF($T$2=0,$D9,$J9) -> 0 | E47: =IF($T$2=0,$E9,$K9) -> 0 | H47: =$B15 -> 0 | I47: =IF($T$2=0,$C15,$I15) -> 0 | J47: =IF($T$2=0,$D15,$J15) -> 0 | K47: =IF($T$2=0,$E15,$K15) -> 0
C48: =SUM(C42:C47) -> 0 | D48: =SUM(D42:D47) -> 0 | E48: =SUM(E42:E47) -> 0 | I48: =SUM(I42:I47) -> 0 | J48: =SUM(J42:J47) -> 0 | K48: =SUM(K42:K47) -> 0
B50: =$B16 -> 0 | C50: =IF($T$2=0,$C16,$I16) -> 0 | D50: =IF($T$2=0,$D16,$J16) -> 0 | E50: =IF($T$2=0,$E16,$K16) -> 0 | F50: =E56+D56+C56 -> 0 | H50: =$B22 -> 0 | I50: =IF($T$2=0,$C22,$I22) -> 0 | J50: =IF($T$2=0,$D22,$J22) -> 0 | K50: =IF($T$2=0,$E22,$K22) -> 0 | L50: =K56+J56+I56 -> 0
B51: =$B17 -> 0 | C51: =IF($T$2=0,$C17,$I17) -> 0 | D51: =IF($T$2=0,$D17,$J17) -> 0 | E51: =IF($T$2=0,$E17,$K17) -> 0 | H51: =$B23 -> 0 | I51: =IF($T$2=0,$C23,$I23) -> 0 | J51: =IF($T$2=0,$D23,$J23) -> 0 | K51: =IF($T$2=0,$E23,$K23) -> 0
B52: =$B18 -> 0 | C52: =IF($T$2=0,$C18,$I18) -> 0 | D52: =IF($T$2=0,$D18,$J18) -> 0 | E52: =IF($T$2=0,$E18,$K18) -> 0 | H52: =$B24 -> 0 | I52: =IF($T$2=0,$C24,$I24) -> 0 | J52: =IF($T$2=0,$D24,$J24) -> 0 | K52: =IF($T$2=0,$E24,$K24) -> 0
B53: =$B19 -> 0 | C53: =IF($T$2=0,$C19,$I19) -> 0 | D53: =IF($T$2=0,$D19,$J19) -> 0 | E53: =IF($T$2=0,$E19,$K19) -> 0 | H53: =$B25 -> 0 | I53: =IF($T$2=0,$C25,$I25) -> 0 | J53: =IF($T$2=0,$D25,$J25) -> 0 | K53: =IF($T$2=0,$E25,$K25) -> 0
B54: =$B20 -> 0 | C54: =IF($T$2=0,$C20,$I20) -> 0 | D54: =IF($T$2=0,$D20,$J20) -> 0 | E54: =IF($T$2=0,$E20,$K20) -> 0 | H54: =$B26 -> 0 | I54: =IF($T$2=0,$C26,$I26) -> 0 | J54: =IF($T$2=0,$D26,$J26) -> 0 | K54: =IF($T$2=0,$E26,$K26) -> 0
B55: =$B21 -> 0 | C55: =IF($T$2=0,$C21,$I21) -> 0 | D55: =IF($T$2=0,$D21,$J21) -> 0 | E55: =IF($T$2=0,$E21,$K21) -> 0 | H55: =$B27 -> 0 | I55: =IF($T$2=0,$C27,$I27) -> 0 | J55: =IF($T$2=0,$D27,$J27) -> 0 | K55: =IF($T$2=0,$E27,$K27) -> 0
C56: =SUM(C50:C55) -> 0 | D56: =SUM(D50:D55) -> 0 | E56: =SUM(E50:E55) -> 0 | I56: =SUM(I50:I55) -> 0 | J56: =SUM(J50:J55) -> 0 | K56: =SUM(K50:K55) -> 0
B58: =$B28 -> 0 | C58: =IF($T$2=0,$C28,$I28) -> 0 | D58: =IF($T$2=0,$D28,$J28) -> 0 | E58: =IF($T$2=0,$E28,$K28) -> 0 | F58: =E64+D64+C64 -> 0
B59: =$B29 -> 0 | C59: =IF($T$2=0,$C29,$I29) -> 0 | D59: =IF($T$2=0,$D29,$J29) -> 0 | E59: =IF($T$2=0,$E29,$K29) -> 0
B60: =$B30 -> 0 | C60: =IF($T$2=0,$C30,$I30) -> 0 | D60: =IF($T$2=0,$D30,$J30) -> 0 | E60: =IF($T$2=0,$E30,$K30) -> 0
B61: =$B31 -> 0 | C61: =IF($T$2=0,$C31,$I31) -> 0 | D61: =IF($T$2=0,$D31,$J31) -> 0 | E61: =IF($T$2=0,$E31,$K31) -> 0
B62: =$B32 -> 0 | C62: =IF($T$2=0,$C32,$I32) -> 0 | D62: =IF($T$2=0,$D32,$J32) -> 0 | E62: =IF($T$2=0,$E32,$K32) -> 0
...

Sheet 00회정모 5인팀
A1: 2026 아르케 존 00회 정기 모임 점수
K2: 날짜 | L2: 46113 | S2: 팀전에버기준 | T2: 0 | U2: 순위에버오차기준 | V2: 0
B3: 이 름 | C3: 1 G | D3: 2 G | E3: 3 G | F3: 합 계 | G3: 에 버 | H3: 기본에버 | I3: 1 G | J3: 2 G | K3: 3 G | L3: 합 계 | M3: 오 차 | S3: 수식입력부분 삭제하지마세요~
A4: 1 | F4: =SUM(C4:E4) -> 0 | G4: =F4/3 -> 0 | H4: {=IF(B4="","",IFERROR(INDEX('회원명단 및 기준에버'!D:G,MATCH(B4,'회원명단 및 기준에버'!$C:$C,0),CHOOSE(INT((MONTH($L$2)-1)/3)+1,1,2,3,4)),""))} | I4: =IFERROR(C4+-H4,0) -> 0 | J4: =IFERROR(D4+-H4,0) -> 0 | K4: =IFERROR(E4+-H4,0) -> 0 | L4: =SUM(I4:K4) -> 0 | M4: =IFERROR(G4+-H4,0) -> 0 | S4: =MAX(C4:E4)-MIN(C4:E4) -> 0 | T4: =IF($B4="",-999999999+A4,IF($V$2=0,(F4*10000+S4*1000+A4),(M4*10000+S4*10+A4))) -> -999999998 | U4: =_xlfn.RANK.EQ(T4,$T$4:$T$33,0) -> 30
A5: 2 | F5: =SUM(C5:E5) -> 0 | G5: =F5/3 -> 0 | H5: {=IF(B5="","",IFERROR(INDEX('회원명단 및 기준에버'!D:G,MATCH(B5,'회원명단 및 기준에버'!$C:$C,0),CHOOSE(INT((MONTH($L$2)-1)/3)+1,1,2,3,4)),""))} | I5: =IFERROR(C5+-H5,0) -> 0 | J5: =IFERROR(D5+-H5,0) -> 0 | K5: =IFERROR(E5+-H5,0) -> 0 | L5: =SUM(I5:K5) -> 0 | M5: =IFERROR(G5+-H5,0) -> 0 | S5: =MAX(C5:E5)-MIN(C5:E5) -> 0 | T5: =IF($B5="",-999999999+A5,IF($V$2=0,(F5*10000+S5*1000+A5),(M5*10000+S5*10+A5))) -> -999999997 | U5: =_xlfn.RANK.EQ(T5,$T$4:$T$33,0) -> 29
A6: 3 | F6: =SUM(C6:E6) -> 0 | G6: =F6/3 -> 0 | H6: {=IF(B6="","",IFERROR(INDEX('회원명단 및 기준에버'!D:G,MATCH(B6,'회원명단 및 기준에버'!$C:$C,0),CHOOSE(INT((MONTH($L$2)-1)/3)+1,1,2,3,4)),""))} | I6: =IFERROR(C6+-H6,0) -> 0 | J6: =IFERROR(D6+-H6,0) -> 0 | K6: =IFERROR(E6+-H6,0) -> 0 | L6: =SUM(I6:K6) -> 0 | M6: =IFERROR(G6+-H6,0) -> 0 | S6: =MAX(C6:E6)-MIN(C6:E6) -> 0 | T6: =IF($B6="",-999999999+A6,IF($V$2=0,(F6*10000+S6*1000+A6),(M6*10000+S6*10+A6))) -> -999999996 | U6: =_xlfn.RANK.EQ(T6,$T$4:$T$33,0) -> 28
A7: 4 | F7: =SUM(C7:E7) -> 0 | G7: =F7/3 -> 0 | H7: {=IF(B7="","",IFERROR(INDEX('회원명단 및 기준에버'!D:G,MATCH(B7,'회원명단 및 기준에버'!$C:$C,0),CHOOSE(INT((MONTH($L$2)-1)/3)+1,1,2,3,4)),""))} | I7: =IFERROR(C7+-H7,0) -> 0 | J7: =IFERROR(D7+-H7,0) -> 0 | K7: =IFERROR(E7+-H7,0) -> 0 | L7: =SUM(I7:K7) -> 0 | M7: =IFERROR(G7+-H7,0) -> 0 | S7: =MAX(C7:E7)-MIN(C7:E7) -> 0 | T7: =IF($B7="",-999999999+A7,IF($V$2=0,(F7*10000+S7*1000+A7),(M7*10000+S7*10+A7))) -> -999999995 | U7: =_xlfn.RANK.EQ(T7,$T$4:$T$33,0) -> 27
A8: 5 | F8: =SUM(C8:E8) -> 0 | G8: =F8/3 -> 0 | H8: {=IF(B8="","",IFERROR(INDEX('회원명단 및 기준에버'!D:G,MATCH(B8,'회원명단 및 기준에버'!$C:$C,0),CHOOSE(INT((MONTH($L$2)-1)/3)+1,1,2,3,4)),""))} | I8: =IFERROR(C8+-H8,0) -> 0 | J8: =IFERROR(D8+-H8,0) -> 0 | K8: =IFERROR(E8+-H8,0) -> 0 | L8: =SUM(I8:K8) -> 0 | M8: =IFERROR(G8+-H8,0) -> 0 | S8: =MAX(C8:E8)-MIN(C8:E8) -> 0 | T8: =IF($B8="",-999999999+A8,IF($V$2=0,(F8*10000+S8*1000+A8),(M8*10000+S8*10+A8))) -> -999999994 | U8: =_xlfn.RANK.EQ(T8,$T$4:$T$33,0) -> 26
A9: 6 | F9: =SUM(C9:E9) -> 0 | G9: =F9/3 -> 0 | H9: {=IF(B9="","",IFERROR(INDEX('회원명단 및 기준에버'!D:G,MATCH(B9,'회원명단 및 기준에버'!$C:$C,0),CHOOSE(INT((MONTH($L$2)-1)/3)+1,1,2,3,4)),""))} | I9: =IFERROR(C9+-H9,0) -> 0 | J9: =IFERROR(D9+-H9,0) -> 0 | K9: =IFERROR(E9+-H9,0) -> 0 | L9: =SUM(I9:K9) -> 0 | M9: =IFERROR(G9+-H9,0) -> 0 | S9: =MAX(C9:E9)-MIN(C9:E9) -> 0 | T9: =IF($B9="",-999999999+A9,IF($V$2=0,(F9*10000+S9*1000+A9),(M9*10000+S9*10+A9))) -> -999999993 | U9: =_xlfn.RANK.EQ(T9,$T$4:$T$33,0) -> 25
A10: 7 | F10: =SUM(C10:E10) -> 0 | G10: =F10/3 -> 0 | H10: {=IF(B10="","",IFERROR(INDEX('회원명단 및 기준에버'!D:G,MATCH(B10,'회원명단 및 기준에버'!$C:$C,0),CHOOSE(INT((MONTH($L$2)-1)/3)+1,1,2,3,4)),""))} | I10: =IFERROR(C10+-H10,0) -> 0 | J10: =IFERROR(D10+-H10,0) -> 0 | K10: =IFERROR(E10+-H10,0) -> 0 | L10: =SUM(I10:K10) -> 0 | M10: =IFERROR(G10+-H10,0) -> 0 | S10: =MAX(C10:E10)-MIN(C10:E10) -> 0 | T10: =IF($B10="",-999999999+A10,IF($V$2=0,(F10*10000+S10*1000+A10),(M10*10000+S10*10+A10))) -> -999999992 | U10: =_xlfn.RANK.EQ(T10,$T$4:$T$33,0) -> 24
A11: 8 | F11: =SUM(C11:E11) -> 0 | G11: =F11/3 -> 0 | H11: {=IF(B11="","",IFERROR(INDEX('회원명단 및 기준에버'!D:G,MATCH(B11,'회원명단 및 기준에버'!$C:$C,0),CHOOSE(INT((MONTH($L$2)-1)/3)+1,1,2,3,4)),""))} | I11: =IFERROR(C11+-H11,0) -> 0 | J11: =IFERROR(D11+-H11,0) -> 0 | K11: =IFERROR(E11+-H11,0) -> 0 | L11: =SUM(I11:K11) -> 0 | M11: =IFERROR(G11+-H11,0) -> 0 | S11: =MAX(C11:E11)-MIN(C11:E11) -> 0 | T11: =IF($B11="",-999999999+A11,IF($V$2=0,(F11*10000+S11*1000+A11),(M11*10000+S11*10+A11))) -> -999999991 | U11: =_xlfn.RANK.EQ(T11,$T$4:$T$33,0) -> 23
A12: 9 | F12: =SUM(C12:E12) -> 0 | G12: =F12/3 -> 0 | H12: {=IF(B12="","",IFERROR(INDEX('회원명단 및 기준에버'!D:G,MATCH(B12,'회원명단 및 기준에버'!$C:$C,0),CHOOSE(INT((MONTH($L$2)-1)/3)+1,1,2,3,4)),""))} | I12: =IFERROR(C12+-H12,0) -> 0 | J12: =IFERROR(D12+-H12,0) -> 0 | K12: =IFERROR(E12+-H12,0) -> 0 | L12: =SUM(I12:K12) -> 0 | M12: =IFERROR(G12+-H12,0) -> 0 | S12: =MAX(C12:E12)-MIN(C12:E12) -> 0 | T12: =IF($B12="",-999999999+A12,IF($V$2=0,(F12*10000+S12*1000+A12),(M12*10000+S12*10+A12))) -> -999999990 | U12: =_xlfn.RANK.EQ(T12,$T$4:$T$33,0) -> 22
A13: 10 | F13: =SUM(C13:E13) -> 0 | G13: =F13/3 -> 0 | H13: {=IF(B13="","",IFERROR(INDEX('회원명단 및 기준에버'!D:G,MATCH(B13,'회원명단 및 기준에버'!$C:$C,0),CHOOSE(INT((MONTH($L$2)-1)/3)+1,1,2,3,4)),""))} | I13: =IFERROR(C13+-H13,0) -> 0 | J13: =IFERROR(D13+-H13,0) -> 0 | K13: =IFERROR(E13+-H13,0) -> 0 | L13: =SUM(I13:K13) -> 0 | M13: =IFERROR(G13+-H13,0) -> 0 | S13: =MAX(C13:E13)-MIN(C13:E13) -> 0 | T13: =IF($B13="",-999999999+A13,IF($V$2=0,(F13*10000+S13*1000+A13),(M13*10000+S13*10+A13))) -> -999999989 | U13: =_xlfn.RANK.EQ(T13,$T$4:$T$33,0) -> 21
A14: 11 | F14: =SUM(C14:E14) -> 0 | G14: =F14/3 -> 0 | H14: {=IF(B14="","",IFERROR(INDEX('회원명단 및 기준에버'!D:G,MATCH(B14,'회원명단 및 기준에버'!$C:$C,0),CHOOSE(INT((MONTH($L$2)-1)/3)+1,1,2,3,4)),""))} | I14: =IFERROR(C14+-H14,0) -> 0 | J14: =IFERROR(D14+-H14,0) -> 0 | K14: =IFERROR(E14+-H14,0) -> 0 | L14: =SUM(I14:K14) -> 0 | M14: =IFERROR(G14+-H14,0) -> 0 | S14: =MAX(C14:E14)-MIN(C14:E14) -> 0 | T14: =IF($B14="",-999999999+A14,IF($V$2=0,(F14*10000+S14*1000+A14),(M14*10000+S14*10+A14))) -> -999999988 | U14: =_xlfn.RANK.EQ(T14,$T$4:$T$33,0) -> 20
A15: 12 | F15: =SUM(C15:E15) -> 0 | G15: =F15/3 -> 0 | H15: {=IF(B15="","",IFERROR(INDEX('회원명단 및 기준에버'!D:G,MATCH(B15,'회원명단 및 기준에버'!$C:$C,0),CHOOSE(INT((MONTH($L$2)-1)/3)+1,1,2,3,4)),""))} | I15: =IFERROR(C15+-H15,0) -> 0 | J15: =IFERROR(D15+-H15,0) -> 0 | K15: =IFERROR(E15+-H15,0) -> 0 | L15: =SUM(I15:K15) -> 0 | M15: =IFERROR(G15+-H15,0) -> 0 | S15: =MAX(C15:E15)-MIN(C15:E15) -> 0 | T15: =IF($B15="",-999999999+A15,IF($V$2=0,(F15*10000+S15*1000+A15),(M15*10000+S15*10+A15))) -> -999999987 | U15: =_xlfn.RANK.EQ(T15,$T$4:$T$33,0) -> 19
... A33: 30 | F33: =SUM(C33:E33) -> 0 | G33: =F33/3 -> 0 | H33: {=IF(B33="","",IFERROR(INDEX('회원명단 및 기준에버'!D:G,MATCH(B33,'회원명단 및 기준에버'!$C:$C,0),CHOOSE(INT((MONTH($L$2)-1)/3)+1,1,2,3,4)),""))} | I33: =IFERROR(C33+-H33,0) -> 0 | J33: =IFERROR(D33+-H33,0) -> 0 | K33: =IFERROR(E33+-H33,0) -> 0 | L33: =SUM(I33:K33) -> 0 | M33: =IFERROR(G33+-H33,0) -> 0 | S33: =MAX(C33:E33)-MIN(C33:E33) -> 0 | T33: =IF($B33="",-999999999+A33,IF($V$2=0,(F33*10000+S33*1000+A33),(M33*10000+S33*10+A33))) -> -999999969 | U33: =_xlfn.RANK.EQ(T33,$T$4:$T$33,0) -> 1
B34: 시 상 및 벌 금
B35: 에버상승상 남+20점,여+10점 이상 상위1명 | F35: 에버벌금 | G35: 정기전 만 해당 함 | J35: 유니품 벌금(3.000원)
G36: 1점부터 2000원
B37: 올카바 상 | I37: 초구가터벌금1회1000원 | K37: 광 박 1회 2000원
B41: 팀 전
B42: =$B4 -> 0 | C42: =IF($T$2=0,$C4,$I4) -> 0 | D42: =IF($T$2=0,$D4,$J4) -> 0 | E42: =IF($T$2=0,$E4,$K4) -> 0 | F42: =E47+D47+C47 -> 0 | H42: =$B9 -> 0 | I42: =IF($T$2=0,$C9,$I9) -> 0 | J42: =IF($T$2=0,$D9,$J9) -> 0 | K42: =IF($T$2=0,$E9,$K9) -> 0 | L42: =K47+J47+I47 -> 0
B43: =$B5 -> 0 | C43: =IF($T$2=0,$C5,$I5) -> 0 | D43: =IF($T$2=0,$D5,$J5) -> 0 | E43: =IF($T$2=0,$E5,$K5) -> 0 | H43: =$B10 -> 0 | I43: =IF($T$2=0,$C10,$I10) -> 0 | J43: =IF($T$2=0,$D10,$J10) -> 0 | K43: =IF($T$2=0,$E10,$K10) -> 0
B44: =$B6 -> 0 | C44: =IF($T$2=0,$C6,$I6) -> 0 | D44: =IF($T$2=0,$D6,$J6) -> 0 | E44: =IF($T$2=0,$E6,$K6) -> 0 | H44: =$B11 -> 0 | I44: =IF($T$2=0,$C11,$I11) -> 0 | J44: =IF($T$2=0,$D11,$J11) -> 0 | K44: =IF($T$2=0,$E11,$K11) -> 0
B45: =$B7 -> 0 | C45: =IF($T$2=0,$C7,$I7) -> 0 | D45: =IF($T$2=0,$D7,$J7) -> 0 | E45: =IF($T$2=0,$E7,$K7) -> 0 | H45: =$B12 -> 0 | I45: =IF($T$2=0,$C12,$I12) -> 0 | J45: =IF($T$2=0,$D12,$J12) -> 0 | K45: =IF($T$2=0,$E12,$K12) -> 0
B46: =$B8 -> 0 | C46: =IF($T$2=0,$C8,$I8) -> 0 | D46: =IF($T$2=0,$D8,$J8) -> 0 | E46: =IF($T$2=0,$E8,$K8) -> 0 | H46: =$B13 -> 0 | I46: =IF($T$2=0,$C13,$I13) -> 0 | J46: =IF($T$2=0,$D13,$J13) -> 0 | K46: =IF($T$2=0,$E13,$K13) -> 0
C47: =SUM(C42:C46) -> 0 | D47: =SUM(D42:D46) -> 0 | E47: =SUM(E42:E46) -> 0 | I47: =SUM(I42:I46) -> 0 | J47: =SUM(J42:J46) -> 0 | K47: =SUM(K42:K46) -> 0
B49: =$B14 -> 0 | C49: =IF($T$2=0,$C14,$I14) -> 0 | D49: =IF($T$2=0,$D14,$J14) -> 0 | E49: =IF($T$2=0,$E14,$K14) -> 0 | F49: =E54+D54+C54 -> 0 | H49: =$B19 -> 0 | I49: =IF($T$2=0,$C19,$I19) -> 0 | J49: =IF($T$2=0,$D19,$J19) -> 0 | K49: =IF($T$2=0,$E19,$K19) -> 0 | L49: =K54+J54+I54 -> 0
B50: =$B15 -> 0 | C50: =IF($T$2=0,$C15,$I15) -> 0 | D50: =IF($T$2=0,$D15,$J15) -> 0 | E50: =IF($T$2=0,$E15,$K15) -> 0 | H50: =$B20 -> 0 | I50: =IF($T$2=0,$C20,$I20) -> 0 | J50: =IF($T$2=0,$D20,$J20) -> 0 | K50: =IF($T$2=0,$E20,$K20) -> 0
B51: =$B16 -> 0 | C51: =IF($T$2=0,$C16,$I16) -> 0 | D51: =IF($T$2=0,$D16,$J16) -> 0 | E51: =IF($T$2=0,$E16,$K16) -> 0 | H51: =$B21 -> 0 | I51: =IF($T$2=0,$C21,$I21) -> 0 | J51: =IF($T$2=0,$D21,$J21) -> 0 | K51: =IF($T$2=0,$E21,$K21) -> 0
B52: =$B17 -> 0 | C52: =IF($T$2=0,$C17,$I17) -> 0 | D52: =IF($T$2=0,$D17,$J17) -> 0 | E52: =IF($T$2=0,$E17,$K17) -> 0 | H52: =$B22 -> 0 | I52: =IF($T$2=0,$C22,$I22) -> 0 | J52: =IF($T$2=0,$D22,$J22) -> 0 | K52: =IF($T$2=0,$E22,$K22) -> 0
B53: =$B18 -> 0 | C53: =IF($T$2=0,$C18,$I18) -> 0 | D53: =IF($T$2=0,$D18,$J18) -> 0 | E53: =IF($T$2=0,$E18,$K18) -> 0 | H53: =$B23 -> 0 | I53: =IF($T$2=0,$C23,$I23) -> 0 | J53: =IF($T$2=0,$D23,$J23) -> 0 | K53: =IF($T$2=0,$E23,$K23) -> 0
C54: =SUM(C49:C53) -> 0 | D54: =SUM(D49:D53) -> 0 | E54: =SUM(E49:E53) -> 0 | I54: =SUM(I49:I53) -> 0 | J54: =SUM(J49:J53) -> 0 | K54: =SUM(K49:K53) -> 0
B56: =$B24 -> 0 | C56: =IF($T$2=0,$C24,$I24) -> 0 | D56: =IF($T$2=0,$D24,$J24) -> 0 | E56: =IF($T$2=0,$E24,$K24) -> 0 | F56: =E61+D61+C61 -> 0 | H56: =$B29 -> 0 | I56: =IF($T$2=0,$C29,$I29) -> 0 | J56: =IF($T$2=0,$D29,$J29) -> 0 | K56: =IF($T$2=0,$E29,$K29) -> 0 | L56: =K61+J61+I61 -> 0
B57: =$B25 -> 0 | C57: =IF($T$2=0,$C25,$I25) -> 0 | D57: =IF($T$2=0,$D25,$J25) -> 0 | E57: =IF($T$2=0,$E25,$K25) -> 0 | H57: =$B30 -> 0 | I57: =IF($T$2=0,$C30,$I30) -> 0 | J57: =IF($T$2=0,$D30,$J30) -> 0 | K57: =IF($T$2=0,$E30,$K30) -> 0
B58: =$B26 -> 0 | C58: =IF($T$2=0,$C26,$I26) -> 0 | D58: =IF($T$2=0,$D26,$J26) -> 0 | E58: =IF($T$2=0,$E26,$K26) -> 0 | H58: =$B31 -> 0 | I58: =IF($T$2=0,$C31,$I31) -> 0 | J58: =IF($T$2=0,$D31,$J31) -> 0 | K58: =IF($T$2=0,$E31,$K31) -> 0
B59: =$B27 -> 0 | C59: =IF($T$2=0,$C27,$I27) -> 0 | D59: =IF($T$2=0,$D27,$J27) -> 0 | E59: =IF($T$2=0,$E27,$K27) -> 0 | H59: =$B32 -> 0 | I59: =IF($T$2=0,$C32,$I32) -> 0 | J59: =IF($T$2=0,$D32,$J32) -> 0 | K59: =IF($T$2=0,$E32,$K32) -> 0
B60: =$B28 -> 0 | C60: =IF($T$2=0,$C28,$I28) -> 0 | D60: =IF($T$2=0,$D28,$J28) -> 0 | E60: =IF($T$2=0,$E28,$K28) -> 0 | H60: =$B33 -> 0 | I60: =IF($T$2=0,$C33,$I33) -> 0 | J60: =IF($T$2=0,$D33,$J33) -> 0 | K60: =IF($T$2=0,$E33,$K33) -> 0
C61: =SUM(C56:C60) -> 0 | D61: =SUM(D56:D60) -> 0 | E61: =SUM(E56:E60) -> 0 | I61: =SUM(I56:I60) -> 0 | J61: =SUM(J56:J60) -> 0 | K61: =SUM(K56:K60) -> 0
A65: =A1 -> 2026 아르케 존 00회 정기 모임 점수
...

Sheet 00회정모 4인팀
A1: 2026 아르케 존 00회 정기 모임 점수
K2: 날짜 | L2: 46113 | S2: 팀전에버기준 | T2: 0 | U2: 순위에버오차기준 | V2: 0
B3: 이 름 | C3: 1 G | D3: 2 G | E3: 3 G | F3: 합 계 | G3: 에 버 | H3: 기본에버 | I3: 1 G | J3: 2 G | K3: 3 G | L3: 합 계 | M3: 오 차 | S3: 수식입력부분 삭제하지마세요~
A4: 1 | F4: =SUM(C4:E4) -> 0 | G4: =F4/3 -> 0 | H4: {=IF(B4="","",IFERROR(INDEX('회원명단 및 기준에버'!D:G,MATCH(B4,'회원명단 및 기준에버'!$C:$C,0),CHOOSE(INT((MONTH($L$2)-1)/3)+1,1,2,3,4)),""))} | I4: =IFERROR(C4+-H4,0) -> 0 | J4: =IFERROR(D4+-H4,0) -> 0 | K4: =IFERROR(E4+-H4,0) -> 0 | L4: =SUM(I4:K4) -> 0 | M4: =IFERROR(G4+-H4,0) -> 0 | S4: =MAX(C4:E4)-MIN(C4:E4) -> 0 | T4: =IF($B4="",-999999999+A4,IF($V$2=0,(F4*10000+S4*1000+A4),(M4*10000+S4*10+A4))) -> -999999998 | U4: =_xlfn.RANK.EQ(T4,$T$4:$T$33,0) -> #VALUE!
A5: 2 | F5: =SUM(C5:E5) -> 0 | G5: =F5/3 -> 0 | H5: {=IF(B5="","",IFERROR(INDEX('회원명단 및 기준에버'!D:G,MATCH(B5,'회원명단 및 기준에버'!$C:$C,0),CHOOSE(INT((MONTH($L$2)-1)/3)+1,1,2,3,4)),""))} | I5: =IFERROR(C5+-H5,0) -> 0 | J5: =IFERROR(D5+-H5,0) -> 0 | K5: =IFERROR(E5+-H5,0) -> 0 | L5: =SUM(I5:K5) -> 0 | M5: =IFERROR(G5+-H5,0) -> 0 | S5: =MAX(C5:E5)-MIN(C5:E5) -> 0 | T5: =IF($B5="",-999999999+A5,IF($V$2=0,(F5*10000+S5*1000+A5),(M5*10000+S5*10+A5))) -> -999999997 | U5: =_xlfn.RANK.EQ(T5,$T$4:$T$33,0) -> #VALUE!
A6: 3 | F6: =SUM(C6:E6) -> 0 | G6: =F6/3 -> 0 | H6: {=IF(B6="","",IFERROR(INDEX('회원명단 및 기준에버'!D:G,MATCH(B6,'회원명단 및 기준에버'!$C:$C,0),CHOOSE(INT((MONTH($L$2)-1)/3)+1,1,2,3,4)),""))} | I6: =IFERROR(C6+-H6,0) -> 0 | J6: =IFERROR(D6+-H6,0) -> 0 | K6: =IFERROR(E6+-H6,0) -> 0 | L6: =SUM(I6:K6) -> 0 | M6: =IFERROR(G6+-H6,0) -> 0 | S6: =MAX(C6:E6)-MIN(C6:E6) -> 0 | T6: =IF($B6="",-999999999+A6,IF($V$2=0,(F6*10000+S6*1000+A6),(M6*10000+S6*10+A6))) -> -999999996 | U6: =_xlfn.RANK.EQ(T6,$T$4:$T$33,0) -> #VALUE!
A7: 4 | F7: =SUM(C7:E7) -> 0 | G7: =F7/3 -> 0 | H7: {=IF(B7="","",IFERROR(INDEX('회원명단 및 기준에버'!D:G,MATCH(B7,'회원명단 및 기준에버'!$C:$C,0),CHOOSE(INT((MONTH($L$2)-1)/3)+1,1,2,3,4)),""))} | I7: =IFERROR(C7+-H7,0) -> 0 | J7: =IFERROR(D7+-H7,0) -> 0 | K7: =IFERROR(E7+-H7,0) -> 0 | L7: =SUM(I7:K7) -> 0 | M7: =IFERROR(G7+-H7,0) -> 0 | S7: =MAX(C7:E7)-MIN(C7:E7) -> 0 | T7: =IF($B7="",-999999999+A7,IF($V$2=0,(F7*10000+S7*1000+A7),(M7*10000+S7*10+A7))) -> -999999995 | U7: =_xlfn.RANK.EQ(T7,$T$4:$T$33,0) -> #VALUE!
A8: 5 | F8: =SUM(C8:E8) -> 0 | G8: =F8/3 -> 0 | H8: {=IF(B8="","",IFERROR(INDEX('회원명단 및 기준에버'!D:G,MATCH(B8,'회원명단 및 기준에버'!$C:$C,0),CHOOSE(INT((MONTH($L$2)-1)/3)+1,1,2,3,4)),""))} | I8: =IFERROR(C8+-H8,0) -> 0 | J8: =IFERROR(D8+-H8,0) -> 0 | K8: =IFERROR(E8+-H8,0) -> 0 | L8: =SUM(I8:K8) -> 0 | M8: =IFERROR(G8+-H8,0) -> 0 | S8: =MAX(C8:E8)-MIN(C8:E8) -> 0 | T8: =IF($B8="",-999999999+A8,IF($V$2=0,(F8*10000+S8*1000+A8),(M8*10000+S8*10+A8))) -> -999999994 | U8: =_xlfn.RANK.EQ(T8,$T$4:$T$33,0) -> #VALUE!
A9: 6 | F9: =SUM(C9:E9) -> 0 | G9: =F9/3 -> 0 | H9: {=IF(B9="","",IFERROR(INDEX('회원명단 및 기준에버'!D:G,MATCH(B9,'회원명단 및 기준에버'!$C:$C,0),CHOOSE(INT((MONTH($L$2)-1)/3)+1,1,2,3,4)),""))} | I9: =IFERROR(C9+-H9,0) -> 0 | J9: =IFERROR(D9+-H9,0) -> 0 | K9: =IFERROR(E9+-H9,0) -> 0 | L9: =SUM(I9:K9) -> 0 | M9: =IFERROR(G9+-H9,0) -> 0 | S9: =MAX(C9:E9)-MIN(C9:E9) -> 0 | T9: =IF($B9="",-999999999+A9,IF($V$2=0,(F9*10000+S9*1000+A9),(M9*10000+S9*10+A9))) -> -999999993 | U9: =_xlfn.RANK.EQ(T9,$T$4:$T$33,0) -> #VALUE!
A10: 7 | F10: =SUM(C10:E10) -> 0 | G10: =F10/3 -> 0 | H10: {=IF(B10="","",IFERROR(INDEX('회원명단 및 기준에버'!D:G,MATCH(B10,'회원명단 및 기준에버'!$C:$C,0),CHOOSE(INT((MONTH($L$2)-1)/3)+1,1,2,3,4)),""))} | I10: =IFERROR(C10+-H10,0) -> 0 | J10: =IFERROR(D10+-H10,0) -> 0 | K10: =IFERROR(E10+-H10,0) -> 0 | L10: =SUM(I10:K10) -> 0 | M10: =IFERROR(G10+-H10,0) -> 0 | S10: =MAX(C10:E10)-MIN(C10:E10) -> 0 | T10: =IF($B10="",-999999999+A10,IF($V$2=0,(F10*10000+S10*1000+A10),(M10*10000+S10*10+A10))) -> -999999992 | U10: =_xlfn.RANK.EQ(T10,$T$4:$T$33,0) -> #VALUE!
A11: 8 | F11: =SUM(C11:E11) -> 0 | G11: =F11/3 -> 0 | H11: {=IF(B11="","",IFERROR(INDEX('회원명단 및 기준에버'!D:G,MATCH(B11,'회원명단 및 기준에버'!$C:$C,0),CHOOSE(INT((MONTH($L$2)-1)/3)+1,1,2,3,4)),""))} | I11: =IFERROR(C11+-H11,0) -> 0 | J11: =IFERROR(D11+-H11,0) -> 0 | K11: =IFERROR(E11+-H11,0) -> 0 | L11: =SUM(I11:K11) -> 0 | M11: =IFERROR(G11+-H11,0) -> 0 | S11: =MAX(C11:E11)-MIN(C11:E11) -> 0 | T11: =IF($B11="",-999999999+A11,IF($V$2=0,(F11*10000+S11*1000+A11),(M11*10000+S11*10+A11))) -> -999999991 | U11: =_xlfn.RANK.EQ(T11,$T$4:$T$33,0) -> #VALUE!
A12: 9 | F12: =SUM(C12:E12) -> 0 | G12: =F12/3 -> 0 | H12: {=IF(B12="","",IFERROR(INDEX('회원명단 및 기준에버'!D:G,MATCH(B12,'회원명단 및 기준에버'!$C:$C,0),CHOOSE(INT((MONTH($L$2)-1)/3)+1,1,2,3,4)),""))} | I12: =IFERROR(C12+-H12,0) -> 0 | J12: =IFERROR(D12+-H12,0) -> 0 | K12: =IFERROR(E12+-H12,0) -> 0 | L12: =SUM(I12:K12) -> 0 | M12: =IFERROR(G12+-H12,0) -> 0 | S12: =MAX(C12:E12)-MIN(C12:E12) -> 0 | T12: =IF($B12="",-999999999+A12,IF($V$2=0,(F12*10000+S12*1000+A12),(M12*10000+S12*10+A12))) -> -999999990 | U12: =_xlfn.RANK.EQ(T12,$T$4:$T$33,0) -> #VALUE!
A13: 10 | F13: =SUM(C13:E13) -> 0 | G13: =F13/3 -> 0 | H13: {=IF(B13="","",IFERROR(INDEX('회원명단 및 기준에버'!D:G,MATCH(B13,'회원명단 및 기준에버'!$C:$C,0),CHOOSE(INT((MONTH($L$2)-1)/3)+1,1,2,3,4)),""))} | I13: =IFERROR(C13+-H13,0) -> 0 | J13: =IFERROR(D13+-H13,0) -> 0 | K13: =IFERROR(E13+-H13,0) -> 0 | L13: =SUM(I13:K13) -> 0 | M13: =IFERROR(G13+-H13,0) -> 0 | S13: =MAX(C13:E13)-MIN(C13:E13) -> 0 | T13: =IF($B13="",-999999999+A13,IF($V$2=0,(F13*10000+S13*1000+A13),(M13*10000+S13*10+A13))) -> -999999989 | U13: =_xlfn.RANK.EQ(T13,$T$4:$T$33,0) -> #VALUE!
A14: 11 | F14: =SUM(C14:E14) -> 0 | G14: =F14/3 -> 0 | H14: {=IF(B14="","",IFERROR(INDEX('회원명단 및 기준에버'!D:G,MATCH(B14,'회원명단 및 기준에버'!$C:$C,0),CHOOSE(INT((MONTH($L$2)-1)/3)+1,1,2,3,4)),""))} | I14: =IFERROR(C14+-H14,0) -> 0 | J14: =IFERROR(D14+-H14,0) -> 0 | K14: =IFERROR(E14+-H14,0) -> 0 | L14: =SUM(I14:K14) -> 0 | M14: =IFERROR(G14+-H14,0) -> 0 | S14: =MAX(C14:E14)-MIN(C14:E14) -> 0 | T14: =IF($B14="",-999999999+A14,IF($V$2=0,(F14*10000+S14*1000+A14),(M14*10000+S14*10+A14))) -> -999999988 | U14: =_xlfn.RANK.EQ(T14,$T$4:$T$33,0) -> #VALUE!
A15: 12 | F15: =SUM(C15:E15) -> 0 | G15: =F15/3 -> 0 | H15: {=IF(B15="","",IFERROR(INDEX('회원명단 및 기준에버'!D:G,MATCH(B15,'회원명단 및 기준에버'!$C:$C,0),CHOOSE(INT((MONTH($L$2)-1)/3)+1,1,2,3,4)),""))} | I15: =IFERROR(C15+-H15,0) -> 0 | J15: =IFERROR(D15+-H15,0) -> 0 | K15: =IFERROR(E15+-H15,0) -> 0 | L15: =SUM(I15:K15) -> 0 | M15: =IFERROR(G15+-H15,0) -> 0 | S15: =MAX(C15:E15)-MIN(C15:E15) -> 0 | T15: =IF($B15="",-999999999+A15,IF($V$2=0,(F15*10000+S15*1000+A15),(M15*10000+S15*10+A15))) -> -999999987 | U15: =_xlfn.RANK.EQ(T15,$T$4:$T$33,0) -> #VALUE!
... A27: 24 | F27: =SUM(C27:E27) -> 0 | G27: =F27/3 -> 0 | H27: {=IF(B27="","",IFERROR(INDEX('회원명단 및 기준에버'!D:G,MATCH(B27,'회원명단 및 기준에버'!$C:$C,0),CHOOSE(INT((MONTH($L$2)-1)/3)+1,1,2,3,4)),""))} | I27: =IFERROR(C27+-H27,0) -> 0 | J27: =IFERROR(D27+-H27,0) -> 0 | K27: =IFERROR(E27+-H27,0) -> 0 | L27: =SUM(I27:K27) -> 0 | M27: =IFERROR(G27+-H27,0) -> 0 | S27: =MAX(C27:E27)-MIN(C27:E27) -> 0 | T27: =IF($B27="",-999999999+A27,IF($V$2=0,(F27*10000+S27*1000+A27),(M27*10000+S27*10+A27))) -> -999999975 | U27: =_xlfn.RANK.EQ(T27,$T$4:$T$33,0) -> #VALUE!
A28: 25 | F28: =SUM(C28:E28) -> 0 | G28: =F28/3 -> 0 | H28: {=IF(B28="","",IFERROR(INDEX('회원명단 및 기준에버'!D:G,MATCH(B28,'회원명단 및 기준에버'!$C:$C,0),CHOOSE(INT((MONTH($L$2)-1)/3)+1,1,2,3,4)),""))} | I28: =IFERROR(C28+-H28,0) -> 0 | J28: =IFERROR(D28+-H28,0) -> 0 | K28: =IFERROR(E28+-H28,0) -> 0 | L28: =SUM(I28:K28) -> 0 | M28: =IFERROR(G28+-H28,0) -> 0 | T28: =IF($B28="",-999999999+A28,IF($V$2=0,(F28*10000+S28*1000+A28),(M28*10000+S28*10+A28))) -> -999999974
B29: 시 상 및 벌 금 | T29: =IF($B29="",-999999999+A29,IF($V$2=0,(F29*10000+S29*1000+A29),(M29*10000+S29*10+A29))) -> 0
B30: 에버상승상 남+20점,여+10점 이상 상위1명 | F30: 에버벌금 | G30: 정기전 만 해당 함 | J30: 유니품 벌금(3.000원) | T30: =IF($B30="",-999999999+A30,IF($V$2=0,(F30*10000+S30*1000+A30),(M30*10000+S30*10+A30))) -> #VALUE!
G31: 1점부터 2000원 | T31: =IF($B31="",-999999999+A31,IF($V$2=0,(F31*10000+S31*1000+A31),(M31*10000+S31*10+A31))) -> -999999999
B32: 올카바 상 | I32: 초구가터벌금1회1000원 | K32: 광 박 1회 2000원 | T32: =IF($B32="",-999999999+A32,IF($V$2=0,(F32*10000+S32*1000+A32),(M32*10000+S32*10+A32))) -> 0
T33: =IF($B33="",-999999999+A33,IF($V$2=0,(F33*10000+S33*1000+A33),(M33*10000+S33*10+A33))) -> -999999999
B36: 팀 전
B37: =$B4 -> 0 | C37: =IF($T$2=0,$C4,$I4) -> 0 | D37: =IF($T$2=0,$D4,$J4) -> 0 | E37: =IF($T$2=0,$E4,$K4) -> 0 | F37: =E41+D41+C41 -> 0 | H37: =$B8 -> 0 | I37: =IF($T$2=0,$C8,$I8) -> 0 | J37: =IF($T$2=0,$D8,$J8) -> 0 | K37: =IF($T$2=0,$E8,$K8) -> 0 | L37: =K41+J41+I41 -> 0
B38: =$B5 -> 0 | C38: =IF($T$2=0,$C5,$I5) -> 0 | D38: =IF($T$2=0,$D5,$J5) -> 0 | E38: =IF($T$2=0,$E5,$K5) -> 0 | H38: =$B9 -> 0 | I38: =IF($T$2=0,$C9,$I9) -> 0 | J38: =IF($T$2=0,$D9,$J9) -> 0 | K38: =IF($T$2=0,$E9,$K9) -> 0
B39: =$B6 -> 0 | C39: =IF($T$2=0,$C6,$I6) -> 0 | D39: =IF($T$2=0,$D6,$J6) -> 0 | E39: =IF($T$2=0,$E6,$K6) -> 0 | H39: =$B10 -> 0 | I39: =IF($T$2=0,$C10,$I10) -> 0 | J39: =IF($T$2=0,$D10,$J10) -> 0 | K39: =IF($T$2=0,$E10,$K10) -> 0
B40: =$B7 -> 0 | C40: =IF($T$2=0,$C7,$I7) -> 0 | D40: =IF($T$2=0,$D7,$J7) -> 0 | E40: =IF($T$2=0,$E7,$K7) -> 0 | H40: =$B11 -> 0 | I40: =IF($T$2=0,$C11,$I11) -> 0 | J40: =IF($T$2=0,$D11,$J11) -> 0 | K40: =IF($T$2=0,$E11,$K11) -> 0
C41: =SUM(C37:C40) -> 0 | D41: =SUM(D37:D40) -> 0 | E41: =SUM(E37:E40) -> 0 | I41: =SUM(I37:I40) -> 0 | J41: =SUM(J37:J40) -> 0 | K41: =SUM(K37:K40) -> 0
B43: =$B12 -> 0 | C43: =IF($T$2=0,$C12,$I12) -> 0 | D43: =IF($T$2=0,$D12,$J12) -> 0 | E43: =IF($T$2=0,$E12,$K12) -> 0 | F43: =E47+D47+C47 -> 0 | H43: =$B16 -> 0 | I43: =IF($T$2=0,$C16,$I16) -> 0 | J43: =IF($T$2=0,$D16,$J16) -> 0 | K43: =IF($T$2=0,$E16,$K16) -> 0 | L43: =K47+J47+I47 -> 0
B44: =$B13 -> 0 | C44: =IF($T$2=0,$C13,$I13) -> 0 | D44: =IF($T$2=0,$D13,$J13) -> 0 | E44: =IF($T$2=0,$E13,$K13) -> 0 | H44: =$B17 -> 0 | I44: =IF($T$2=0,$C17,$I17) -> 0 | J44: =IF($T$2=0,$D17,$J17) -> 0 | K44: =IF($T$2=0,$E17,$K17) -> 0
B45: =$B14 -> 0 | C45: =IF($T$2=0,$C14,$I14) -> 0 | D45: =IF($T$2=0,$D14,$J14) -> 0 | E45: =IF($T$2=0,$E14,$K14) -> 0 | H45: =$B18 -> 0 | I45: =IF($T$2=0,$C18,$I18) -> 0 | J45: =IF($T$2=0,$D18,$J18) -> 0 | K45: =IF($T$2=0,$E18,$K18) -> 0
B46: =$B15 -> 0 | C46: =IF($T$2=0,$C15,$I15) -> 0 | D46: =IF($T$2=0,$D15,$J15) -> 0 | E46: =IF($T$2=0,$E15,$K15) -> 0 | H46: =$B19 -> 0 | I46: =IF($T$2=0,$C19,$I19) -> 0 | J46: =IF($T$2=0,$D19,$J19) -> 0 | K46: =IF($T$2=0,$E19,$K19) -> 0
C47: =SUM(C43:C46) -> 0 | D47: =SUM(D43:D46) -> 0 | E47: =SUM(E43:E46) -> 0 | I47: =SUM(I43:I46) -> 0 | J47: =SUM(J43:J46) -> 0 | K47: =SUM(K43:K46) -> 0
B49: =$B20 -> 0 | C49: =IF($T$2=0,$C20,$I20) -> 0 | D49: =IF($T$2=0,$D20,$J20) -> 0 | E49: =IF($T$2=0,$E20,$K20) -> 0 | F49: =E53+D53+C53 -> 0 | H49: =$B24 -> 0 | I49: =IF($T$2=0,$C24,$I24) -> 0 | J49: =IF($T$2=0,$D24,$J24) -> 0 | K49: =IF($T$2=0,$E24,$K24) -> 0 | L49: =K53+J53+I53 -> 0
B50: =$B21 -> 0 | C50: =IF($T$2=0,$C21,$I21) -> 0 | D50: =IF($T$2=0,$D21,$J21) -> 0 | E50: =IF($T$2=0,$E21,$K21) -> 0 | H50: =$B25 -> 0 | I50: =IF($T$2=0,$C25,$I25) -> 0 | J50: =IF($T$2=0,$D25,$J25) -> 0 | K50: =IF($T$2=0,$E25,$K25) -> 0
B51: =$B22 -> 0 | C51: =IF($T$2=0,$C22,$I22) -> 0 | D51: =IF($T$2=0,$D22,$J22) -> 0 | E51: =IF($T$2=0,$E22,$K22) -> 0 | H51: =$B26 -> 0 | I51: =IF($T$2=0,$C26,$I26) -> 0 | J51: =IF($T$2=0,$D26,$J26) -> 0 | K51: =IF($T$2=0,$E26,$K26) -> 0
B52: =$B23 -> 0 | C52: =IF($T$2=0,$C23,$I23) -> 0 | D52: =IF($T$2=0,$D23,$J23) -> 0 | E52: =IF($T$2=0,$E23,$K23) -> 0 | H52: =$B27 -> 0 | I52: =IF($T$2=0,$C27,$I27) -> 0 | J52: =IF($T$2=0,$D27,$J27) -> 0 | K52: =IF($T$2=0,$E27,$K27) -> 0
C53: =SUM(C49:C52) -> 0 | D53: =SUM(D49:D52) -> 0 | E53: =SUM(E49:E52) -> 0 | I53: =SUM(I49:I52) -> 0 | J53: =SUM(J49:J52) -> 0 | K53: =SUM(K49:K52) -> 0
A56: =A1 -> 2026 아르케 존 00회 정기 모임 점수
K57: 날짜 | L57: =L2 -> 46113
...

Sheet 07회정모
A1: 2026 아르케 존 07회 정기 모임 점수
K2: 날짜 | L2: 46114 | S2: 팀전에버기준 | T2: 1 | U2: 순위에버오차기준 | V2: 1
B3: 이 름 | C3: 1 G | D3: 2 G | E3: 3 G | F3: 합 계 | G3: 에 버 | H3: 기본에버 | I3: 1 G | J3: 2 G | K3: 3 G | L3: 합 계 | M3: 오 차 | S3: 수식입력부분 삭제하지마세요~
A4: 1 | B4: 채 윤 주 | C4: 187 | D4: 214 | E4: 181 | F4: =SUM(C4:E4) -> 582 | G4: =F4/3 -> 194 | H4: {=IF(B4="","",IFERROR(INDEX('회원명단 및 기준에버'!D:G,MATCH(B4,'회원명단 및 기준에버'!$C:$C,0),CHOOSE(INT((MONTH($L$2)-1)/3)+1,1,2,3,4)),""))} -> 0 | I4: 0 | J4: 0 | K4: 0 | L4: =SUM(I4:K4) -> 0 | M4: 0 | S4: =MAX(C4:E4)-MIN(C4:E4) -> 33 | T4: =IF($B4="",-999999999+A4,IF($V$2=0,(F4*10000+S4*1000+A4),(M4*10000+S4*10+A4))) -> 331 | U4: =_xlfn.RANK.EQ(T4,$T$4:$T$28,0) -> 12
A5: 2 | B5: 이 정 석 | C5: 165 | D5: 213 | E5: 183 | F5: =SUM(C5:E5) -> 561 | G5: =F5/3 -> 187 | H5: {=IF(B5="","",IFERROR(INDEX('회원명단 및 기준에버'!D:G,MATCH(B5,'회원명단 및 기준에버'!$C:$C,0),CHOOSE(INT((MONTH($L$2)-1)/3)+1,1,2,3,4)),""))} -> 200 | I5: =IFERROR(C5+-H5,0) -> -35 | J5: =IFERROR(D5+-H5,0) -> 13 | K5: =IFERROR(E5+-H5,0) -> -17 | L5: =SUM(I5:K5) -> -39 | M5: =IFERROR(G5+-H5,0) -> -13 | S5: =MAX(C5:E5)-MIN(C5:E5) -> 48 | T5: =IF($B5="",-999999999+A5,IF($V$2=0,(F5*10000+S5*1000+A5),(M5*10000+S5*10+A5))) -> -129518 | U5: =_xlfn.RANK.EQ(T5,$T$4:$T$28,0) -> 23
A6: 3 | B6: 임 승 기 | C6: 182 | D6: 203 | E6: 193 | F6: =SUM(C6:E6) -> 578 | G6: =F6/3 -> 192.66667 | H6: {=IF(B6="","",IFERROR(INDEX('회원명단 및 기준에버'!D:G,MATCH(B6,'회원명단 및 기준에버'!$C:$C,0),CHOOSE(INT((MONTH($L$2)-1)/3)+1,1,2,3,4)),""))} -> 200 | I6: =IFERROR(C6+-H6,0) -> -18 | J6: =IFERROR(D6+-H6,0) -> 3 | K6: =IFERROR(E6+-H6,0) -> -7 | L6: =SUM(I6:K6) -> -22 | M6: =IFERROR(G6+-H6,0) -> -7.3333333 | S6: =MAX(C6:E6)-MIN(C6:E6) -> 21 | T6: =IF($B6="",-999999999+A6,IF($V$2=0,(F6*10000+S6*1000+A6),(M6*10000+S6*10+A6))) -> -73120.333 | U6: =_xlfn.RANK.EQ(T6,$T$4:$T$28,0) -> 20
A7: 4 | B7: 김 태 환 | C7: 185 | D7: 193 | E7: 245 | F7: =SUM(C7:E7) -> 623 | G7: =F7/3 -> 207.66667 | H7: {=IF(B7="","",IFERROR(INDEX('회원명단 및 기준에버'!D:G,MATCH(B7,'회원명단 및 기준에버'!$C:$C,0),CHOOSE(INT((MONTH($L$2)-1)/3)+1,1,2,3,4)),""))} -> 199 | I7: =IFERROR(C7+-H7,0) -> -14 | J7: =IFERROR(D7+-H7,0) -> -6 | K7: =IFERROR(E7+-H7,0) -> 46 | L7: =SUM(I7:K7) -> 26 | M7: =IFERROR(G7+-H7,0) -> 8.6666667 | S7: =MAX(C7:E7)-MIN(C7:E7) -> 60 | T7: =IF($B7="",-999999999+A7,IF($V$2=0,(F7*10000+S7*1000+A7),(M7*10000+S7*10+A7))) -> 87270.667 | U7: =_xlfn.RANK.EQ(T7,$T$4:$T$28,0) -> 6
A8: 5 | B8: 김 종 훈 | C8: 150 | D8: 134 | E8: 160 | F8: =SUM(C8:E8) -> 444 | G8: =F8/3 -> 148 | H8: {=IF(B8="","",IFERROR(INDEX('회원명단 및 기준에버'!D:G,MATCH(B8,'회원명단 및 기준에버'!$C:$C,0),CHOOSE(INT((MONTH($L$2)-1)/3)+1,1,2,3,4)),""))} -> 190 | I8: =IFERROR(C8+-H8,0) -> -40 | J8: =IFERROR(D8+-H8,0) -> -56 | K8: =IFERROR(E8+-H8,0) -> -30 | L8: =SUM(I8:K8) -> -126 | M8: =IFERROR(G8+-H8,0) -> -42 | S8: =MAX(C8:E8)-MIN(C8:E8) -> 26 | T8: =IF($B8="",-999999999+A8,IF($V$2=0,(F8*10000+S8*1000+A8),(M8*10000+S8*10+A8))) -> -419735 | U8: =_xlfn.RANK.EQ(T8,$T$4:$T$28,0) -> 25
A9: 6 | B9: 김 선 미 | C9: 158 | D9: 166 | E9: 188 | F9: =SUM(C9:E9) -> 512 | G9: =F9/3 -> 170.66667 | H9: {=IF(B9="","",IFERROR(INDEX('회원명단 및 기준에버'!D:G,MATCH(B9,'회원명단 및 기준에버'!$C:$C,0),CHOOSE(INT((MONTH($L$2)-1)/3)+1,1,2,3,4)),""))} -> 162 | I9: =IFERROR(C9+-H9,0) -> -4 | J9: =IFERROR(D9+-H9,0) -> 4 | K9: =IFERROR(E9+-H9,0) -> 26 | L9: =SUM(I9:K9) -> 26 | M9: =IFERROR(G9+-H9,0) -> 8.6666667 | S9: =MAX(C9:E9)-MIN(C9:E9) -> 30 | T9: =IF($B9="",-999999999+A9,IF($V$2=0,(F9*10000+S9*1000+A9),(M9*10000+S9*10+A9))) -> 86972.667 | U9: =_xlfn.RANK.EQ(T9,$T$4:$T$28,0) -> 7
A10: 7 | B10: 김 정 희 | C10: 180 | D10: 245 | E10: 217 | F10: =SUM(C10:E10) -> 642 | G10: =F10/3 -> 214 | H10: {=IF(B10="","",IFERROR(INDEX('회원명단 및 기준에버'!D:G,MATCH(B10,'회원명단 및 기준에버'!$C:$C,0),CHOOSE(INT((MONTH($L$2)-1)/3)+1,1,2,3,4)),""))} -> 200 | I10: =IFERROR(C10+-H10,0) -> -20 | J10: =IFERROR(D10+-H10,0) -> 45 | K10: =IFERROR(E10+-H10,0) -> 17 | L10: =SUM(I10:K10) -> 42 | M10: =IFERROR(G10+-H10,0) -> 14 | S10: =MAX(C10:E10)-MIN(C10:E10) -> 65 | T10: =IF($B10="",-999999999+A10,IF($V$2=0,(F10*10000+S10*1000+A10),(M10*10000+S10*10+A10))) -> 140657 | U10: =_xlfn.RANK.EQ(T10,$T$4:$T$28,0) -> 4
A11: 8 | B11: 장 영 민 | C11: 204 | D11: 222 | E11: 156 | F11: =SUM(C11:E11) -> 582 | G11: =F11/3 -> 194 | H11: {=IF(B11="","",IFERROR(INDEX('회원명단 및 기준에버'!D:G,MATCH(B11,'회원명단 및 기준에버'!$C:$C,0),CHOOSE(INT((MONTH($L$2)-1)/3)+1,1,2,3,4)),""))} -> 200 | I11: =IFERROR(C11+-H11,0) -> 4 | J11: =IFERROR(D11+-H11,0) -> 22 | K11: =IFERROR(E11+-H11,0) -> -44 | L11: =SUM(I11:K11) -> -18 | M11: =IFERROR(G11+-H11,0) -> -6 | S11: =MAX(C11:E11)-MIN(C11:E11) -> 66 | T11: =IF($B11="",-999999999+A11,IF($V$2=0,(F11*10000+S11*1000+A11),(M11*10000+S11*10+A11))) -> -59332 | U11: =_xlfn.RANK.EQ(T11,$T$4:$T$28,0) -> 17
A12: 9 | B12: 이 상 현 | C12: 180 | D12: 194 | E12: 182 | F12: =SUM(C12:E12) -> 556 | G12: =F12/3 -> 185.33333 | H12: {=IF(B12="","",IFERROR(INDEX('회원명단 및 기준에버'!D:G,MATCH(B12,'회원명단 및 기준에버'!$C:$C,0),CHOOSE(INT((MONTH($L$2)-1)/3)+1,1,2,3,4)),""))} -> 195 | I12: =IFERROR(C12+-H12,0) -> -15 | J12: =IFERROR(D12+-H12,0) -> -1 | K12: =IFERROR(E12+-H12,0) -> -13 | L12: =SUM(I12:K12) -> -29 | M12: =IFERROR(G12+-H12,0) -> -9.6666667 | S12: =MAX(C12:E12)-MIN(C12:E12) -> 14 | T12: =IF($B12="",-999999999+A12,IF($V$2=0,(F12*10000+S12*1000+A12),(M12*10000+S12*10+A12))) -> -96517.667 | U12: =_xlfn.RANK.EQ(T12,$T$4:$T$28,0) -> 21
A13: 10 | B13: 박 성 현 | C13: 208 | D13: 179 | E13: 191 | F13: =SUM(C13:E13) -> 578 | G13: =F13/3 -> 192.66667 | H13: {=IF(B13="","",IFERROR(INDEX('회원명단 및 기준에버'!D:G,MATCH(B13,'회원명단 및 기준에버'!$C:$C,0),CHOOSE(INT((MONTH($L$2)-1)/3)+1,1,2,3,4)),""))} -> 191 | I13: =IFERROR(C13+-H13,0) -> 17 | J13: =IFERROR(D13+-H13,0) -> -12 | K13: =IFERROR(E13+-H13,0) -> 0 | L13: =SUM(I13:K13) -> 5 | M13: =IFERROR(G13+-H13,0) -> 1.6666667 | S13: =MAX(C13:E13)-MIN(C13:E13) -> 29 | T13: =IF($B13="",-999999999+A13,IF($V$2=0,(F13*10000+S13*1000+A13),(M13*10000+S13*10+A13))) -> 16966.667 | U13: =_xlfn.RANK.EQ(T13,$T$4:$T$28,0) -> 11
A14: 11 | B14: 지 옥 명 | C14: 173 | D14: 166 | E14: 191 | F14: =SUM(C14:E14) -> 530 | G14: =F14/3 -> 176.66667 | H14: {=IF(B14="","",IFERROR(INDEX('회원명단 및 기준에버'!D:G,MATCH(B14,'회원명단 및 기준에버'!$C:$C,0),CHOOSE(INT((MONTH($L$2)-1)/3)+1,1,2,3,4)),""))} -> 177 | I14: =IFERROR(C14+-H14,0) -> -4 | J14: =IFERROR(D14+-H14,0) -> -11 | K14: =IFERROR(E14+-H14,0) -> 14 | L14: =SUM(I14:K14) -> -1 | M14: =IFERROR(G14+-H14,0) -> -0.33333333 | S14: =MAX(C14:E14)-MIN(C14:E14) -> 25 | T14: =IF($B14="",-999999999+A14,IF($V$2=0,(F14*10000+S14*1000+A14),(M14*10000+S14*10+A14))) -> -3072.3333 | U14: =_xlfn.RANK.EQ(T14,$T$4:$T$28,0) -> 14
A15: 12 | B15: 천 성 일 | C15: 176 | D15: 179 | E15: 214 | F15: =SUM(C15:E15) -> 569 | G15: =F15/3 -> 189.66667 | H15: {=IF(B15="","",IFERROR(INDEX('회원명단 및 기준에버'!D:G,MATCH(B15,'회원명단 및 기준에버'!$C:$C,0),CHOOSE(INT((MONTH($L$2)-1)/3)+1,1,2,3,4)),""))} -> 191 | I15: =IFERROR(C15+-H15,0) -> -15 | J15: =IFERROR(D15+-H15,0) -> -12 | K15: =IFERROR(E15+-H15,0) -> 23 | L15: =SUM(I15:K15) -> -4 | M15: =IFERROR(G15+-H15,0) -> -1.3333333 | S15: =MAX(C15:E15)-MIN(C15:E15) -> 38 | T15: =IF($B15="",-999999999+A15,IF($V$2=0,(F15*10000+S15*1000+A15),(M15*10000+S15*10+A15))) -> -12941.333 | U15: =_xlfn.RANK.EQ(T15,$T$4:$T$28,0) -> 15
A16: 13 | B16: 이 우 석 | C16: 192 | D16: 192 | E16: 194 | F16: =SUM(C16:E16) -> 578 | G16: =F16/3 -> 192.66667 | H16: {=IF(B16="","",IFERROR(INDEX('회원명단 및 기준에버'!D:G,MATCH(B16,'회원명단 및 기준에버'!$C:$C,0),CHOOSE(INT((MONTH($L$2)-1)/3)+1,1,2,3,4)),""))} -> 199 | I16: =IFERROR(C16+-H16,0) -> -7 | J16: =IFERROR(D16+-H16,0) -> -7 | K16: =IFERROR(E16+-H16,0) -> -5 | L16: =SUM(I16:K16) -> -19 | M16: =IFERROR(G16+-H16,0) -> -6.3333333 | S16: =MAX(C16:E16)-MIN(C16:E16) -> 2 | T16: =IF($B16="",-999999999+A16,IF($V$2=0,(F16*10000+S16*1000+A16),(M16*10000+S16*10+A16))) -> -63300.333 | U16: =_xlfn.RANK.EQ(T16,$T$4:$T$28,0) -> 18
... A28: 25 | B28: 이 재 용 | C28: 246 | D28: 165 | E28: 221 | F28: =SUM(C28:E28) -> 632 | G28: =F28/3 -> 210.66667 | H28: {=IF(B28="","",IFERROR(INDEX('회원명단 및 기준에버'!D:G,MATCH(B28,'회원명단 및 기준에버'!$C:$C,0),CHOOSE(INT((MONTH($L$2)-1)/3)+1,1,2,3,4)),""))} -> 196 | I28: =IFERROR(C28+-H28,0) -> 50 | J28: =IFERROR(D28+-H28,0) -> -31 | K28: =IFERROR(E28+-H28,0) -> 25 | L28: =SUM(I28:K28) -> 44 | M28: =IFERROR(G28+-H28,0) -> 14.666667 | S28: =MAX(C28:E28)-MIN(C28:E28) -> 81 | T28: =IF($B28="",-999999999+A28,IF($V$2=0,(F28*10000+S28*1000+A28),(M28*10000+S28*10+A28))) -> 147501.67 | U28: =_xlfn.RANK.EQ(T28,$T$4:$T$28,0) -> 3
B29: 시 상 및 벌 금
B30: 에버상승상 남+20점,여+10점 이상 상위1명 | F30: 에버벌금 | G30: 정기전 만 해당 함 | J30: 유니품 벌금(3.000원)
B31: 김 규 희 | C31: 61 | G31: 1점부터 2000원 | J31: 김 미 란
B32: 올카바 상 | I32: 초구가터벌금1회1000원 | K32: 광 박 1회 2000원
B33: 김 정 희 | C33: 245 | K33: 진 명 옥
B34: 고 경 훈 | C34: 225
B35: 임 연 진 | C35: 214
B36: 팀 전
B37: =$B4 -> 채 윤 주 | C37: =IF($T$2=0,$C4,$I4) -> 0 | D37: =IF($T$2=0,$D4,$J4) -> 0 | E37: =IF($T$2=0,$E4,$K4) -> 0 | F37: =E42+D42+C42 -> -161 | H37: =$B9 -> 김 선 미 | I37: =IF($T$2=0,$C9,$I9) -> -4 | J37: =IF($T$2=0,$D9,$J9) -> 4 | K37: =IF($T$2=0,$E9,$K9) -> 26 | L37: =K42+J42+I42 -> 26
B38: =$B5 -> 이 정 석 | C38: =IF($T$2=0,$C5,$I5) -> -35 | D38: =IF($T$2=0,$D5,$J5) -> 13 | E38: =IF($T$2=0,$E5,$K5) -> -17 | H38: =$B10 -> 김 정 희 | I38: =IF($T$2=0,$C10,$I10) -> -20 | J38: =IF($T$2=0,$D10,$J10) -> 45 | K38: =IF($T$2=0,$E10,$K10) -> 17
B39: =$B6 -> 임 승 기 | C39: =IF($T$2=0,$C6,$I6) -> -18 | D39: =IF($T$2=0,$D6,$J6) -> 3 | E39: =IF($T$2=0,$E6,$K6) -> -7 | H39: =$B11 -> 장 영 민 | I39: =IF($T$2=0,$C11,$I11) -> 4 | J39: =IF($T$2=0,$D11,$J11) -> 22 | K39: =IF($T$2=0,$E11,$K11) -> -44
B40: =$B7 -> 김 태 환 | C40: =IF($T$2=0,$C7,$I7) -> -14 | D40: =IF($T$2=0,$D7,$J7) -> -6 | E40: =IF($T$2=0,$E7,$K7) -> 46 | H40: =$B12 -> 이 상 현 | I40: =IF($T$2=0,$C12,$I12) -> -15 | J40: =IF($T$2=0,$D12,$J12) -> -1 | K40: =IF($T$2=0,$E12,$K12) -> -13
B41: =$B8 -> 김 종 훈 | C41: =IF($T$2=0,$C8,$I8) -> -40 | D41: =IF($T$2=0,$D8,$J8) -> -56 | E41: =IF($T$2=0,$E8,$K8) -> -30 | H41: =$B13 -> 박 성 현 | I41: =IF($T$2=0,$C13,$I13) -> 17 | J41: =IF($T$2=0,$D13,$J13) -> -12 | K41: =IF($T$2=0,$E13,$K13) -> 0
C42: =SUM(C37:C41) -> -107 | D42: =SUM(D37:D41) -> -46 | E42: =SUM(E37:E41) -> -8 | I42: =SUM(I37:I41) -> -18 | J42: =SUM(J37:J41) -> 58 | K42: =SUM(K37:K41) -> -14
B44: =$B14 -> 지 옥 명 | C44: =IF($T$2=0,$C14,$I14) -> -4 | D44: =IF($T$2=0,$D14,$J14) -> -11 | E44: =IF($T$2=0,$E14,$K14) -> 14 | F44: =E49+D49+C49 -> 103 | H44: =$B19 -> 진 명 옥 | I44: =IF($T$2=0,$C19,$I19) -> -33 | J44: =IF($T$2=0,$D19,$J19) -> -6 | K44: =IF($T$2=0,$E19,$K19) -> 8 | L44: =K49+J49+I49 -> 16
B45: =$B15 -> 천 성 일 | C45: =IF($T$2=0,$C15,$I15) -> -15 | D45: =IF($T$2=0,$D15,$J15) -> -12 | E45: =IF($T$2=0,$E15,$K15) -> 23 | H45: =$B20 -> 김 미 란 | I45: =IF($T$2=0,$C20,$I20) -> 4 | J45: =IF($T$2=0,$D20,$J20) -> 41 | K45: =IF($T$2=0,$E20,$K20) -> -30
B46: =$B16 -> 이 우 석 | C46: =IF($T$2=0,$C16,$I16) -> -7 | D46: =IF($T$2=0,$D16,$J16) -> -7 | E46: =IF($T$2=0,$E16,$K16) -> -5 | H46: =$B21 -> 변 상 필 | I46: =IF($T$2=0,$C21,$I21) -> 29 | J46: =IF($T$2=0,$D21,$J21) -> 27 | K46: =IF($T$2=0,$E21,$K21) -> -30
B47: =$B17 -> 강 완 규 | C47: =IF($T$2=0,$C17,$I17) -> -1 | D47: =IF($T$2=0,$D17,$J17) -> -30 | E47: =IF($T$2=0,$E17,$K17) -> -25 | H47: =$B22 -> 고 경 훈 | I47: =IF($T$2=0,$C22,$I22) -> -12 | J47: =IF($T$2=0,$D22,$J22) -> 32 | K47: =IF($T$2=0,$E22,$K22) -> -14
B48: =$B18 -> 김 규 희 | C48: =IF($T$2=0,$C18,$I18) -> 34 | D48: =IF($T$2=0,$D18,$J18) -> 95 | E48: =IF($T$2=0,$E18,$K18) -> 54 | H48: =$B23 -> 최 진 | I48: =IF($T$2=0,$C23,$I23) -> 0 | J48: =IF($T$2=0,$D23,$J23) -> 0 | K48: =IF($T$2=0,$E23,$K23) -> 0
C49: =SUM(C44:C48) -> 7 | D49: =SUM(D44:D48) -> 35 | E49: =SUM(E44:E48) -> 61 | I49: =SUM(I44:I48) -> -12 | J49: =SUM(J44:J48) -> 94 | K49: =SUM(K44:K48) -> -66
B51: =$B24 -> 손 은 주 | C51: =IF($T$2=0,$C24,$I24) -> -25 | D51: =IF($T$2=0,$D24,$J24) -> 15 | E51: =IF($T$2=0,$E24,$K24) -> -3 | F51: =E56+D56+C56 -> 83
B52: =$B25 -> 임 연 진 | C52: =IF($T$2=0,$C25,$I25) -> 56 | D52: =IF($T$2=0,$D25,$J25) -> 14 | E52: =IF($T$2=0,$E25,$K25) -> -8
B53: =$B26 -> 이 대 용 | C53: =IF($T$2=0,$C26,$I26) -> 34 | D53: =IF($T$2=0,$D26,$J26) -> 9 | E53: =IF($T$2=0,$E26,$K26) -> -31
...

Sheet 06회정모
A1: 2026 아르케 존 06회 정기 모임 점수
K2: 날짜 | L2: 46100 | S2: 팀전에버기준 | T2: 1 | U2: 순위에버오차기준 | V2: 1
B3: 이 름 | C3: 1 G | D3: 2 G | E3: 3 G | F3: 합 계 | G3: 에 버 | H3: 기본에버 | I3: 1 G | J3: 2 G | K3: 3 G | L3: 합 계 | M3: 오 차 | S3: 수식입력부분 삭제하지마세요~
A4: 1 | B4: 이 우 석 | C4: 212 | D4: 191 | E4: 218 | F4: =SUM(C4:E4) -> 621 | G4: =F4/3 -> 207 | H4: {=IF(B4="","",IFERROR(INDEX('회원명단 및 기준에버'!D:G,MATCH(B4,'회원명단 및 기준에버'!$C:$C,0),CHOOSE(INT((MONTH($L$2)-1)/3)+1,1,2,3,4)),""))} -> 200 | I4: =IFERROR(C4+-H4,0) -> 12 | J4: =IFERROR(D4+-H4,0) -> -9 | K4: =IFERROR(E4+-H4,0) -> 18 | L4: =SUM(I4:K4) -> 21 | M4: =IFERROR(G4+-H4,0) -> 7 | S4: =MAX(C4:E4)-MIN(C4:E4) -> 27 | T4: =IF($B4="",-999999999+A4,IF($V$2=0,(F4*10000+S4*1000+A4),(M4*10000+S4*10+A4))) -> 70271 | U4: =_xlfn.RANK.EQ(T4,$T$4:$T$28,0) -> 8
A5: 2 | B5: 김 정 희 | C5: 182 | D5: 167 | E5: 223 | F5: =SUM(C5:E5) -> 572 | G5: =F5/3 -> 190.66667 | H5: {=IF(B5="","",IFERROR(INDEX('회원명단 및 기준에버'!D:G,MATCH(B5,'회원명단 및 기준에버'!$C:$C,0),CHOOSE(INT((MONTH($L$2)-1)/3)+1,1,2,3,4)),""))} -> 200 | I5: =IFERROR(C5+-H5,0) -> -18 | J5: =IFERROR(D5+-H5,0) -> -33 | K5: =IFERROR(E5+-H5,0) -> 23 | L5: =SUM(I5:K5) -> -28 | M5: =IFERROR(G5+-H5,0) -> -9.3333333 | S5: =MAX(C5:E5)-MIN(C5:E5) -> 56 | T5: =IF($B5="",-999999999+A5,IF($V$2=0,(F5*10000+S5*1000+A5),(M5*10000+S5*10+A5))) -> -92771.333 | U5: =_xlfn.RANK.EQ(T5,$T$4:$T$28,0) -> 18
A6: 3 | B6: 이 정 석 | C6: 182 | D6: 201 | E6: 192 | F6: =SUM(C6:E6) -> 575 | G6: =F6/3 -> 191.66667 | H6: {=IF(B6="","",IFERROR(INDEX('회원명단 및 기준에버'!D:G,MATCH(B6,'회원명단 및 기준에버'!$C:$C,0),CHOOSE(INT((MONTH($L$2)-1)/3)+1,1,2,3,4)),""))} -> 196 | I6: =IFERROR(C6+-H6,0) -> -14 | J6: =IFERROR(D6+-H6,0) -> 5 | K6: =IFERROR(E6+-H6,0) -> -4 | L6: =SUM(I6:K6) -> -13 | M6: =IFERROR(G6+-H6,0) -> -4.3333333 | S6: =MAX(C6:E6)-MIN(C6:E6) -> 19 | T6: =IF($B6="",-999999999+A6,IF($V$2=0,(F6*10000+S6*1000+A6),(M6*10000+S6*10+A6))) -> -43140.333 | U6: =_xlfn.RANK.EQ(T6,$T$4:$T$28,0) -> 15
A7: 4 | B7: 황 인 교 | C7: 183 | D7: 213 | E7: 178 | F7: =SUM(C7:E7) -> 574 | G7: =F7/3 -> 191.33333 | H7: {=IF(B7="","",IFERROR(INDEX('회원명단 및 기준에버'!D:G,MATCH(B7,'회원명단 및 기준에버'!$C:$C,0),CHOOSE(INT((MONTH($L$2)-1)/3)+1,1,2,3,4)),""))} -> 184 | I7: =IFERROR(C7+-H7,0) -> -1 | J7: =IFERROR(D7+-H7,0) -> 29 | K7: =IFERROR(E7+-H7,0) -> -6 | L7: =SUM(I7:K7) -> 22 | M7: =IFERROR(G7+-H7,0) -> 7.3333333 | S7: =MAX(C7:E7)-MIN(C7:E7) -> 35 | T7: =IF($B7="",-999999999+A7,IF($V$2=0,(F7*10000+S7*1000+A7),(M7*10000+S7*10+A7))) -> 73687.333 | U7: =_xlfn.RANK.EQ(T7,$T$4:$T$28,0) -> 7
A8: 5 | B8: 손 은 주 | C8: 155 | D8: 159 | E8: 147 | F8: =SUM(C8:E8) -> 461 | G8: =F8/3 -> 153.66667 | H8: {=IF(B8="","",IFERROR(INDEX('회원명단 및 기준에버'!D:G,MATCH(B8,'회원명단 및 기준에버'!$C:$C,0),CHOOSE(INT((MONTH($L$2)-1)/3)+1,1,2,3,4)),""))} -> 151 | I8: =IFERROR(C8+-H8,0) -> 4 | J8: =IFERROR(D8+-H8,0) -> 8 | K8: =IFERROR(E8+-H8,0) -> -4 | L8: =SUM(I8:K8) -> 8 | M8: =IFERROR(G8+-H8,0) -> 2.6666667 | S8: =MAX(C8:E8)-MIN(C8:E8) -> 12 | T8: =IF($B8="",-999999999+A8,IF($V$2=0,(F8*10000+S8*1000+A8),(M8*10000+S8*10+A8))) -> 26791.667 | U8: =_xlfn.RANK.EQ(T8,$T$4:$T$28,0) -> 9
A9: 6 | B9: 장 영 민 | C9: 202 | D9: 265 | E9: 162 | F9: =SUM(C9:E9) -> 629 | G9: =F9/3 -> 209.66667 | H9: {=IF(B9="","",IFERROR(INDEX('회원명단 및 기준에버'!D:G,MATCH(B9,'회원명단 및 기준에버'!$C:$C,0),CHOOSE(INT((MONTH($L$2)-1)/3)+1,1,2,3,4)),""))} -> 200 | I9: =IFERROR(C9+-H9,0) -> 2 | J9: =IFERROR(D9+-H9,0) -> 65 | K9: =IFERROR(E9+-H9,0) -> -38 | L9: =SUM(I9:K9) -> 29 | M9: =IFERROR(G9+-H9,0) -> 9.6666667 | S9: =MAX(C9:E9)-MIN(C9:E9) -> 103 | T9: =IF($B9="",-999999999+A9,IF($V$2=0,(F9*10000+S9*1000+A9),(M9*10000+S9*10+A9))) -> 97702.667 | U9: =_xlfn.RANK.EQ(T9,$T$4:$T$28,0) -> 5
A10: 7 | B10: 김 태 환 | C10: 202 | D10: 163 | E10: 216 | F10: =SUM(C10:E10) -> 581 | G10: =F10/3 -> 193.66667 | H10: {=IF(B10="","",IFERROR(INDEX('회원명단 및 기준에버'!D:G,MATCH(B10,'회원명단 및 기준에버'!$C:$C,0),CHOOSE(INT((MONTH($L$2)-1)/3)+1,1,2,3,4)),""))} -> 198 | I10: =IFERROR(C10+-H10,0) -> 4 | J10: =IFERROR(D10+-H10,0) -> -35 | K10: =IFERROR(E10+-H10,0) -> 18 | L10: =SUM(I10:K10) -> -13 | M10: =IFERROR(G10+-H10,0) -> -4.3333333 | S10: =MAX(C10:E10)-MIN(C10:E10) -> 53 | T10: =IF($B10="",-999999999+A10,IF($V$2=0,(F10*10000+S10*1000+A10),(M10*10000+S10*10+A10))) -> -42796.333 | U10: =_xlfn.RANK.EQ(T10,$T$4:$T$28,0) -> 14
A11: 8 | B11: 천 성 일 | C11: 175 | D11: 179 | E11: 127 | F11: =SUM(C11:E11) -> 481 | G11: =F11/3 -> 160.33333 | H11: {=IF(B11="","",IFERROR(INDEX('회원명단 및 기준에버'!D:G,MATCH(B11,'회원명단 및 기준에버'!$C:$C,0),CHOOSE(INT((MONTH($L$2)-1)/3)+1,1,2,3,4)),""))} -> 191 | I11: =IFERROR(C11+-H11,0) -> -16 | J11: =IFERROR(D11+-H11,0) -> -12 | K11: =IFERROR(E11+-H11,0) -> -64 | L11: =SUM(I11:K11) -> -92 | M11: =IFERROR(G11+-H11,0) -> -30.666667 | S11: =MAX(C11:E11)-MIN(C11:E11) -> 52 | T11: =IF($B11="",-999999999+A11,IF($V$2=0,(F11*10000+S11*1000+A11),(M11*10000+S11*10+A11))) -> -306138.67 | U11: =_xlfn.RANK.EQ(T11,$T$4:$T$28,0) -> 22
A12: 9 | B12: 진 명 옥 | C12: 149 | D12: 169 | E12: 163 | F12: =SUM(C12:E12) -> 481 | G12: =F12/3 -> 160.33333 | H12: {=IF(B12="","",IFERROR(INDEX('회원명단 및 기준에버'!D:G,MATCH(B12,'회원명단 및 기준에버'!$C:$C,0),CHOOSE(INT((MONTH($L$2)-1)/3)+1,1,2,3,4)),""))} -> 171 | I12: =IFERROR(C12+-H12,0) -> -22 | J12: =IFERROR(D12+-H12,0) -> -2 | K12: =IFERROR(E12+-H12,0) -> -8 | L12: =SUM(I12:K12) -> -32 | M12: =IFERROR(G12+-H12,0) -> -10.666667 | S12: =MAX(C12:E12)-MIN(C12:E12) -> 20 | T12: =IF($B12="",-999999999+A12,IF($V$2=0,(F12*10000+S12*1000+A12),(M12*10000+S12*10+A12))) -> -106457.67 | U12: =_xlfn.RANK.EQ(T12,$T$4:$T$28,0) -> 19
A13: 10 | F13: =SUM(C13:E13) -> 0 | G13: =F13/3 -> 0 | H13: {=IF(B13="","",IFERROR(INDEX('회원명단 및 기준에버'!D:G,MATCH(B13,'회원명단 및 기준에버'!$C:$C,0),CHOOSE(INT((MONTH($L$2)-1)/3)+1,1,2,3,4)),""))} | I13: =IFERROR(C13+-H13,0) -> 0 | J13: =IFERROR(D13+-H13,0) -> 0 | K13: =IFERROR(E13+-H13,0) -> 0 | L13: =SUM(I13:K13) -> 0 | M13: =IFERROR(G13+-H13,0) -> 0 | S13: =MAX(C13:E13)-MIN(C13:E13) -> 0 | T13: =IF($B13="",-999999999+A13,IF($V$2=0,(F13*10000+S13*1000+A13),(M13*10000+S13*10+A13))) -> -999999989 | U13: =_xlfn.RANK.EQ(T13,$T$4:$T$28,0) -> 25
A14: 11 | B14: 이 대 용 | C14: 201 | D14: 192 | E14: 196 | F14: =SUM(C14:E14) -> 589 | G14: =F14/3 -> 196.33333 | H14: {=IF(B14="","",IFERROR(INDEX('회원명단 및 기준에버'!D:G,MATCH(B14,'회원명단 및 기준에버'!$C:$C,0),CHOOSE(INT((MONTH($L$2)-1)/3)+1,1,2,3,4)),""))} -> 200 | I14: =IFERROR(C14+-H14,0) -> 1 | J14: =IFERROR(D14+-H14,0) -> -8 | K14: =IFERROR(E14+-H14,0) -> -4 | L14: =SUM(I14:K14) -> -11 | M14: =IFERROR(G14+-H14,0) -> -3.6666667 | S14: =MAX(C14:E14)-MIN(C14:E14) -> 9 | T14: =IF($B14="",-999999999+A14,IF($V$2=0,(F14*10000+S14*1000+A14),(M14*10000+S14*10+A14))) -> -36565.667 | U14: =_xlfn.RANK.EQ(T14,$T$4:$T$28,0) -> 13
A15: 12 | B15: 김 미 란 | C15: 223 | D15: 174 | E15: 191 | F15: =SUM(C15:E15) -> 588 | G15: =F15/3 -> 196 | H15: {=IF(B15="","",IFERROR(INDEX('회원명단 및 기준에버'!D:G,MATCH(B15,'회원명단 및 기준에버'!$C:$C,0),CHOOSE(INT((MONTH($L$2)-1)/3)+1,1,2,3,4)),""))} -> 182 | I15: =IFERROR(C15+-H15,0) -> 41 | J15: =IFERROR(D15+-H15,0) -> -8 | K15: =IFERROR(E15+-H15,0) -> 9 | L15: =SUM(I15:K15) -> 42 | M15: =IFERROR(G15+-H15,0) -> 14 | S15: =MAX(C15:E15)-MIN(C15:E15) -> 49 | T15: =IF($B15="",-999999999+A15,IF($V$2=0,(F15*10000+S15*1000+A15),(M15*10000+S15*10+A15))) -> 140502 | U15: =_xlfn.RANK.EQ(T15,$T$4:$T$28,0) -> 4
A16: 13 | B16: 이 승 미 | C16: 188 | D16: 157 | E16: 132 | F16: =SUM(C16:E16) -> 477 | G16: =F16/3 -> 159 | H16: {=IF(B16="","",IFERROR(INDEX('회원명단 및 기준에버'!D:G,MATCH(B16,'회원명단 및 기준에버'!$C:$C,0),CHOOSE(INT((MONTH($L$2)-1)/3)+1,1,2,3,4)),""))} -> 165 | I16: =IFERROR(C16+-H16,0) -> 23 | J16: =IFERROR(D16+-H16,0) -> -8 | K16: =IFERROR(E16+-H16,0) -> -33 | L16: =SUM(I16:K16) -> -18 | M16: =IFERROR(G16+-H16,0) -> -6 | S16: =MAX(C16:E16)-MIN(C16:E16) -> 56 | T16: =IF($B16="",-999999999+A16,IF($V$2=0,(F16*10000+S16*1000+A16),(M16*10000+S16*10+A16))) -> -59427 | U16: =_xlfn.RANK.EQ(T16,$T$4:$T$28,0) -> 16
A17: 14 | B17: 나 경 주 | C17: 167 | D17: 147 | E17: 185 | F17: =SUM(C17:E17) -> 499 | G17: =F17/3 -> 166.33333 | H17: {=IF(B17="","",IFERROR(INDEX('회원명단 및 기준에버'!D:G,MATCH(B17,'회원명단 및 기준에버'!$C:$C,0),CHOOSE(INT((MONTH($L$2)-1)/3)+1,1,2,3,4)),""))} -> 192 | I17: =IFERROR(C17+-H17,0) -> -25 | J17: =IFERROR(D17+-H17,0) -> -45 | K17: =IFERROR(E17+-H17,0) -> -7 | L17: =SUM(I17:K17) -> -77 | M17: =IFERROR(G17+-H17,0) -> -25.666667 | S17: =MAX(C17:E17)-MIN(C17:E17) -> 38 | T17: =IF($B17="",-999999999+A17,IF($V$2=0,(F17*10000+S17*1000+A17),(M17*10000+S17*10+A17))) -> -256272.67 | U17: =_xlfn.RANK.EQ(T17,$T$4:$T$28,0) -> 21
A18: 15 | B18: 박 성 현 | C18: 145 | D18: 269 | E18: 201 | F18: =SUM(C18:E18) -> 615 | G18: =F18/3 -> 205 | H18: {=IF(B18="","",IFERROR(INDEX('회원명단 및 기준에버'!D:G,MATCH(B18,'회원명단 및 기준에버'!$C:$C,0),CHOOSE(INT((MONTH($L$2)-1)/3)+1,1,2,3,4)),""))} -> 190 | I18: =IFERROR(C18+-H18,0) -> -45 | J18: =IFERROR(D18+-H18,0) -> 79 | K18: =IFERROR(E18+-H18,0) -> 11 | L18: =SUM(I18:K18) -> 45 | M18: =IFERROR(G18+-H18,0) -> 15 | S18: =MAX(C18:E18)-MIN(C18:E18) -> 124 | T18: =IF($B18="",-999999999+A18,IF($V$2=0,(F18*10000+S18*1000+A18),(M18*10000+S18*10+A18))) -> 151255 | U18: =_xlfn.RANK.EQ(T18,$T$4:$T$28,0) -> 3
A19: 16 | B19: 임 승 기 | C19: 193 | D19: 236 | E19: 222 | F19: =SUM(C19:E19) -> 651 | G19: =F19/3 -> 217 | H19: {=IF(B19="","",IFERROR(INDEX('회원명단 및 기준에버'!D:G,MATCH(B19,'회원명단 및 기준에버'!$C:$C,0),CHOOSE(INT((MONTH($L$2)-1)/3)+1,1,2,3,4)),""))} -> 200 | I19: =IFERROR(C19+-H19,0) -> -7 | J19: =IFERROR(D19+-H19,0) -> 36 | K19: =IFERROR(E19+-H19,0) -> 22 | L19: =SUM(I19:K19) -> 51 | M19: =IFERROR(G19+-H19,0) -> 17 | S19: =MAX(C19:E19)-MIN(C19:E19) -> 43 | T19: =IF($B19="",-999999999+A19,IF($V$2=0,(F19*10000+S19*1000+A19),(M19*10000+S19*10+A19))) -> 170446 | U19: =_xlfn.RANK.EQ(T19,$T$4:$T$28,0) -> 2
A20: 17 | B20: 임 연 진 | C20: 193 | D20: 176 | E20: 175 | F20: =SUM(C20:E20) -> 544 | G20: =F20/3 -> 181.33333 | H20: {=IF(B20="","",IFERROR(INDEX('회원명단 및 기준에버'!D:G,MATCH(B20,'회원명단 및 기준에버'!$C:$C,0),CHOOSE(INT((MONTH($L$2)-1)/3)+1,1,2,3,4)),""))} -> 194 | I20: =IFERROR(C20+-H20,0) -> -1 | J20: =IFERROR(D20+-H20,0) -> -18 | K20: =IFERROR(E20+-H20,0) -> -19 | L20: =SUM(I20:K20) -> -38 | M20: =IFERROR(G20+-H20,0) -> -12.666667 | S20: =MAX(C20:E20)-MIN(C20:E20) -> 18 | T20: =IF($B20="",-999999999+A20,IF($V$2=0,(F20*10000+S20*1000+A20),(M20*10000+S20*10+A20))) -> -126469.67 | U20: =_xlfn.RANK.EQ(T20,$T$4:$T$28,0) -> 20
A21: 18 | B21: 고 경 훈 | C21: 133 | D21: 230 | E21: 194 | F21: =SUM(C21:E21) -> 557 | G21: =F21/3 -> 185.66667 | H21: {=IF(B21="","",IFERROR(INDEX('회원명단 및 기준에버'!D:G,MATCH(B21,'회원명단 및 기준에버'!$C:$C,0),CHOOSE(INT((MONTH($L$2)-1)/3)+1,1,2,3,4)),""))} -> 195 | I21: =IFERROR(C21+-H21,0) -> -62 | J21: =IFERROR(D21+-H21,0) -> 35 | K21: =IFERROR(E21+-H21,0) -> -1 | L21: =SUM(I21:K21) -> -28 | M21: =IFERROR(G21+-H21,0) -> -9.3333333 | S21: =MAX(C21:E21)-MIN(C21:E21) -> 97 | T21: =IF($B21="",-999999999+A21,IF($V$2=0,(F21*10000+S21*1000+A21),(M21*10000+S21*10+A21))) -> -92345.333 | U21: =_xlfn.RANK.EQ(T21,$T$4:$T$28,0) -> 17
A22: 19 | B22: 김 종 훈 | C22: 169 | D22: 159 | E22: 167 | F22: =SUM(C22:E22) -> 495 | G22: =F22/3 -> 165 | H22: {=IF(B22="","",IFERROR(INDEX('회원명단 및 기준에버'!D:G,MATCH(B22,'회원명단 및 기준에버'!$C:$C,0),CHOOSE(INT((MONTH($L$2)-1)/3)+1,1,2,3,4)),""))} -> 198 | I22: =IFERROR(C22+-H22,0) -> -29 | J22: =IFERROR(D22+-H22,0) -> -39 | K22: =IFERROR(E22+-H22,0) -> -31 | L22: =SUM(I22:K22) -> -99 | M22: =IFERROR(G22+-H22,0) -> -33 | S22: =MAX(C22:E22)-MIN(C22:E22) -> 10 | T22: =IF($B22="",-999999999+A22,IF($V$2=0,(F22*10000+S22*1000+A22),(M22*10000+S22*10+A22))) -> -329881 | U22: =_xlfn.RANK.EQ(T22,$T$4:$T$28,0) -> 23
A23: 20 | F23: =SUM(C23:E23) -> 0 | G23: =F23/3 -> 0 | H23: {=IF(B23="","",IFERROR(INDEX('회원명단 및 기준에버'!D:G,MATCH(B23,'회원명단 및 기준에버'!$C:$C,0),CHOOSE(INT((MONTH($L$2)-1)/3)+1,1,2,3,4)),""))} | I23: =IFERROR(C23+-H23,0) -> 0 | J23: =IFERROR(D23+-H23,0) -> 0 | K23: =IFERROR(E23+-H23,0) -> 0 | L23: =SUM(I23:K23) -> 0 | M23: =IFERROR(G23+-H23,0) -> 0 | S23: =MAX(C23:E23)-MIN(C23:E23) -> 0 | T23: =IF($B23="",-999999999+A23,IF($V$2=0,(F23*10000+S23*1000+A23),(M23*10000+S23*10+A23))) -> -999999979 | U23: =_xlfn.RANK.EQ(T23,$T$4:$T$28,0) -> 24
A24: 21 | B24: 변 상 필 | C24: 242 | D24: 161 | E24: 202 | F24: =SUM(C24:E24) -> 605 | G24: =F24/3 -> 201.66667 | H24: {=IF(B24="","",IFERROR(INDEX('회원명단 및 기준에버'!D:G,MATCH(B24,'회원명단 및 기준에버'!$C:$C,0),CHOOSE(INT((MONTH($L$2)-1)/3)+1,1,2,3,4)),""))} -> 200 | I24: =IFERROR(C24+-H24,0) -> 42 | J24: =IFERROR(D24+-H24,0) -> -39 | K24: =IFERROR(E24+-H24,0) -> 2 | L24: =SUM(I24:K24) -> 5 | M24: =IFERROR(G24+-H24,0) -> 1.6666667 | S24: =MAX(C24:E24)-MIN(C24:E24) -> 81 | T24: =IF($B24="",-999999999+A24,IF($V$2=0,(F24*10000+S24*1000+A24),(M24*10000+S24*10+A24))) -> 17497.667 | U24: =_xlfn.RANK.EQ(T24,$T$4:$T$28,0) -> 10
